DEBUG    twister_harness.device.factory:factory.py:37 Get device type "hardware"
DEBUG    httpx:_config.py:82 load_ssl_context verify=True cert=None trust_env=True http2=False
DEBUG    httpx:_config.py:148 load_verify_locations cafile='/usr/local/lib/python3.11/dist-packages/certifi/cacert.pem'
DEBUG    httpcore.connection:_trace.py:85 connect_tcp.started host='api.golioth.io' port=443 local_address=None timeout=5.0 socket_options=None
DEBUG    httpcore.connection:_trace.py:85 connect_tcp.complete return_value=<httpcore._backends.trio.TrioStream object at 0xffffb8c62910>
DEBUG    httpcore.connection:_trace.py:85 start_tls.started ssl_context=<ssl.SSLContext object at 0xffffb8d979b0> server_hostname='api.golioth.io' timeout=5.0
DEBUG    httpcore.connection:_trace.py:85 start_tls.complete return_value=<httpcore._backends.trio.TrioStream object at 0xffffb8aefed0>
DEBUG    httpcore.http11:_trace.py:85 send_request_headers.started request=<Request [b'GET']>
DEBUG    httpcore.http11:_trace.py:85 send_request_headers.complete
DEBUG    httpcore.http11:_trace.py:85 send_request_body.started request=<Request [b'GET']>
DEBUG    httpcore.http11:_trace.py:85 send_request_body.complete
DEBUG    httpcore.http11:_trace.py:85 receive_response_headers.started request=<Request [b'GET']>
DEBUG    httpcore.http11:_trace.py:85 receive_response_headers.complete return_value=(b'HTTP/1.1', 200, b'OK', [(b'Access-Control-Expose-Headers', b'Content-Range'), (b'Content-Length', b'188'), (b'Content-Range', b'projects 0-1/1'), (b'Content-Type', b'application/json'), (b'Date', b'Tue, 26 Nov 2024 16:29:40 GMT'), (b'Grpc-Metadata-Access-Control-Expose-Headers', b'Content-Range'), (b'Grpc-Metadata-Content-Type', b'application/grpc'), (b'Via', b'kong/2.5.2'), (b'X-Kong-Proxy-Latency', b'1'), (b'X-Kong-Upstream-Latency', b'17')])
INFO     httpx:_client.py:1786 HTTP Request: GET https://api.golioth.io/v1/projects "HTTP/1.1 200 OK"
DEBUG    httpcore.http11:_trace.py:85 receive_response_body.started request=<Request [b'GET']>
DEBUG    httpcore.http11:_trace.py:85 receive_response_body.complete
DEBUG    httpcore.http11:_trace.py:85 response_closed.started
DEBUG    httpcore.http11:_trace.py:85 response_closed.complete
DEBUG    httpcore.connection:_trace.py:85 close.started
DEBUG    httpcore.connection:_trace.py:85 close.complete
DEBUG    httpx:_config.py:82 load_ssl_context verify=True cert=None trust_env=True http2=False
DEBUG    httpx:_config.py:148 load_verify_locations cafile='/usr/local/lib/python3.11/dist-packages/certifi/cacert.pem'
DEBUG    httpcore.connection:_trace.py:85 connect_tcp.started host='api.golioth.io' port=443 local_address=None timeout=5.0 socket_options=None
DEBUG    httpcore.connection:_trace.py:85 connect_tcp.complete return_value=<httpcore._backends.trio.TrioStream object at 0xffffb8c4e650>
DEBUG    httpcore.connection:_trace.py:85 start_tls.started ssl_context=<ssl.SSLContext object at 0xffffb8c889e0> server_hostname='api.golioth.io' timeout=5.0
DEBUG    httpcore.connection:_trace.py:85 start_tls.complete return_value=<httpcore._backends.trio.TrioStream object at 0xffffb8c662d0>
DEBUG    httpcore.http11:_trace.py:85 send_request_headers.started request=<Request [b'POST']>
DEBUG    httpcore.http11:_trace.py:85 send_request_headers.complete
DEBUG    httpcore.http11:_trace.py:85 send_request_body.started request=<Request [b'POST']>
DEBUG    httpcore.http11:_trace.py:85 send_request_body.complete
DEBUG    httpcore.http11:_trace.py:85 receive_response_headers.started request=<Request [b'POST']>
DEBUG    httpcore.http11:_trace.py:85 receive_response_headers.complete return_value=(b'HTTP/1.1', 200, b'OK', [(b'Content-Length', b'287'), (b'Content-Type', b'application/json'), (b'Date', b'Tue, 26 Nov 2024 16:29:41 GMT'), (b'Grpc-Metadata-Content-Type', b'application/grpc'), (b'Via', b'kong/2.5.2'), (b'X-Kong-Proxy-Latency', b'3'), (b'X-Kong-Upstream-Latency', b'52')])
INFO     httpx:_client.py:1786 HTTP Request: POST https://api.golioth.io/v1/projects/firmware_ci/devices "HTTP/1.1 200 OK"
DEBUG    httpcore.http11:_trace.py:85 receive_response_body.started request=<Request [b'POST']>
DEBUG    httpcore.http11:_trace.py:85 receive_response_body.complete
DEBUG    httpcore.http11:_trace.py:85 response_closed.started
DEBUG    httpcore.http11:_trace.py:85 response_closed.complete
DEBUG    httpcore.connection:_trace.py:85 close.started
DEBUG    httpcore.connection:_trace.py:85 close.complete
DEBUG    httpx:_config.py:82 load_ssl_context verify=True cert=None trust_env=True http2=False
DEBUG    httpx:_config.py:148 load_verify_locations cafile='/usr/local/lib/python3.11/dist-packages/certifi/cacert.pem'
DEBUG    httpcore.connection:_trace.py:85 connect_tcp.started host='api.golioth.io' port=443 local_address=None timeout=5.0 socket_options=None
DEBUG    httpcore.connection:_trace.py:85 connect_tcp.complete return_value=<httpcore._backends.trio.TrioStream object at 0xffffb8c61b50>
DEBUG    httpcore.connection:_trace.py:85 start_tls.started ssl_context=<ssl.SSLContext object at 0xffffb8c89130> server_hostname='api.golioth.io' timeout=5.0
DEBUG    httpcore.connection:_trace.py:85 start_tls.complete return_value=<httpcore._backends.trio.TrioStream object at 0xffffb8b121d0>
DEBUG    httpcore.http11:_trace.py:85 send_request_headers.started request=<Request [b'POST']>
DEBUG    httpcore.http11:_trace.py:85 send_request_headers.complete
DEBUG    httpcore.http11:_trace.py:85 send_request_body.started request=<Request [b'POST']>
DEBUG    httpcore.http11:_trace.py:85 send_request_body.complete
DEBUG    httpcore.http11:_trace.py:85 receive_response_headers.started request=<Request [b'POST']>
DEBUG    httpcore.http11:_trace.py:85 receive_response_headers.complete return_value=(b'HTTP/1.1', 200, b'OK', [(b'Content-Length', b'201'), (b'Content-Type', b'application/json'), (b'Date', b'Tue, 26 Nov 2024 16:29:41 GMT'), (b'Grpc-Metadata-Content-Type', b'application/grpc'), (b'Via', b'kong/2.5.2'), (b'X-Kong-Proxy-Latency', b'3'), (b'X-Kong-Upstream-Latency', b'27')])
INFO     httpx:_client.py:1786 HTTP Request: POST https://api.golioth.io/v1/projects/firmware_ci/devices/6745f775bb6157cf6cdfabe0/credentials "HTTP/1.1 200 OK"
DEBUG    httpcore.http11:_trace.py:85 receive_response_body.started request=<Request [b'POST']>
DEBUG    httpcore.http11:_trace.py:85 receive_response_body.complete
DEBUG    httpcore.http11:_trace.py:85 response_closed.started
DEBUG    httpcore.http11:_trace.py:85 response_closed.complete
DEBUG    httpcore.connection:_trace.py:85 close.started
DEBUG    httpcore.connection:_trace.py:85 close.complete
DEBUG    twister_harness.device.hardware_adapter:utils.py:37 Flashing command: /usr/local/bin/west flash --skip-rebuild --build-dir /__w/golioth-firmware-sdk/golioth-firmware-sdk/twister-out/rak5010_nrf52840/lightdb/set/sample.golioth.lightdb_set --runner blackmagicprobe -- --gdb=/usr/bin/gdb
DEBUG    twister_harness.device.hardware_adapter:hardware_adapter.py:132 Flashing finished
DEBUG    twister_harness.device.hardware_adapter:hardware_adapter.py:140 Opening serial connection for /dev/serial/by-id/usb-ZEPHYR_RAK5010_Zephyr_B1E5A88410C9C828-if00
ERROR    twister_harness.device.hardware_adapter:hardware_adapter.py:151 Cannot open connection: [Errno 2] could not open port /dev/serial/by-id/usb-ZEPHYR_RAK5010_Zephyr_B1E5A88410C9C828-if00: [Errno 2] No such file or directory: '/dev/serial/by-id/usb-ZEPHYR_RAK5010_Zephyr_B1E5A88410C9C828-if00'
Traceback (most recent call last):
  File "/usr/local/lib/python3.11/dist-packages/serial/serialposix.py", line 322, in open
    self.fd = os.open(self.portstr, os.O_RDWR | os.O_NOCTTY | os.O_NONBLOCK)
              ^^^^^^^^^^^^^^^^^^^^^^^^^^^^^^^^^^^^^^^^^^^^^^^^^^^^^^^^^^^^^^
FileNotFoundError: [Errno 2] No such file or directory: '/dev/serial/by-id/usb-ZEPHYR_RAK5010_Zephyr_B1E5A88410C9C828-if00'

During handling of the above exception, another exception occurred:

Traceback (most recent call last):
  File "/__w/golioth-firmware-sdk/golioth-firmware-sdk/zephyr/scripts/pylib/pytest-twister-harness/src/twister_harness/device/hardware_adapter.py", line 142, in _connect_device
    self._serial_connection = serial.Serial(
                              ^^^^^^^^^^^^^^
  File "/usr/local/lib/python3.11/dist-packages/serial/serialutil.py", line 244, in __init__
    self.open()
  File "/usr/local/lib/python3.11/dist-packages/serial/serialposix.py", line 325, in open
    raise SerialException(msg.errno, "could not open port {}: {}".format(self._port, msg))
serial.serialutil.SerialException: [Errno 2] could not open port /dev/serial/by-id/usb-ZEPHYR_RAK5010_Zephyr_B1E5A88410C9C828-if00: [Errno 2] No such file or directory: '/dev/serial/by-id/usb-ZEPHYR_RAK5010_Zephyr_B1E5A88410C9C828-if00'
DEBUG    twister_harness.device.hardware_adapter:hardware_adapter.py:140 Opening serial connection for /dev/serial/by-id/usb-ZEPHYR_RAK5010_Zephyr_B1E5A88410C9C828-if00
ERROR    twister_harness.device.hardware_adapter:hardware_adapter.py:151 Cannot open connection: [Errno 2] could not open port /dev/serial/by-id/usb-ZEPHYR_RAK5010_Zephyr_B1E5A88410C9C828-if00: [Errno 2] No such file or directory: '/dev/serial/by-id/usb-ZEPHYR_RAK5010_Zephyr_B1E5A88410C9C828-if00'
Traceback (most recent call last):
  File "/usr/local/lib/python3.11/dist-packages/serial/serialposix.py", line 322, in open
    self.fd = os.open(self.portstr, os.O_RDWR | os.O_NOCTTY | os.O_NONBLOCK)
              ^^^^^^^^^^^^^^^^^^^^^^^^^^^^^^^^^^^^^^^^^^^^^^^^^^^^^^^^^^^^^^
FileNotFoundError: [Errno 2] No such file or directory: '/dev/serial/by-id/usb-ZEPHYR_RAK5010_Zephyr_B1E5A88410C9C828-if00'

During handling of the above exception, another exception occurred:

Traceback (most recent call last):
  File "/__w/golioth-firmware-sdk/golioth-firmware-sdk/zephyr/scripts/pylib/pytest-twister-harness/src/twister_harness/device/hardware_adapter.py", line 142, in _connect_device
    self._serial_connection = serial.Serial(
                              ^^^^^^^^^^^^^^
  File "/usr/local/lib/python3.11/dist-packages/serial/serialutil.py", line 244, in __init__
    self.open()
  File "/usr/local/lib/python3.11/dist-packages/serial/serialposix.py", line 325, in open
    raise SerialException(msg.errno, "could not open port {}: {}".format(self._port, msg))
serial.serialutil.SerialException: [Errno 2] could not open port /dev/serial/by-id/usb-ZEPHYR_RAK5010_Zephyr_B1E5A88410C9C828-if00: [Errno 2] No such file or directory: '/dev/serial/by-id/usb-ZEPHYR_RAK5010_Zephyr_B1E5A88410C9C828-if00'
DEBUG    twister_harness.device.hardware_adapter:hardware_adapter.py:140 Opening serial connection for /dev/serial/by-id/usb-ZEPHYR_RAK5010_Zephyr_B1E5A88410C9C828-if00
ERROR    twister_harness.device.hardware_adapter:hardware_adapter.py:151 Cannot open connection: [Errno 2] could not open port /dev/serial/by-id/usb-ZEPHYR_RAK5010_Zephyr_B1E5A88410C9C828-if00: [Errno 2] No such file or directory: '/dev/serial/by-id/usb-ZEPHYR_RAK5010_Zephyr_B1E5A88410C9C828-if00'
Traceback (most recent call last):
  File "/usr/local/lib/python3.11/dist-packages/serial/serialposix.py", line 322, in open
    self.fd = os.open(self.portstr, os.O_RDWR | os.O_NOCTTY | os.O_NONBLOCK)
              ^^^^^^^^^^^^^^^^^^^^^^^^^^^^^^^^^^^^^^^^^^^^^^^^^^^^^^^^^^^^^^
FileNotFoundError: [Errno 2] No such file or directory: '/dev/serial/by-id/usb-ZEPHYR_RAK5010_Zephyr_B1E5A88410C9C828-if00'

During handling of the above exception, another exception occurred:

Traceback (most recent call last):
  File "/__w/golioth-firmware-sdk/golioth-firmware-sdk/zephyr/scripts/pylib/pytest-twister-harness/src/twister_harness/device/hardware_adapter.py", line 142, in _connect_device
    self._serial_connection = serial.Serial(
                              ^^^^^^^^^^^^^^
  File "/usr/local/lib/python3.11/dist-packages/serial/serialutil.py", line 244, in __init__
    self.open()
  File "/usr/local/lib/python3.11/dist-packages/serial/serialposix.py", line 325, in open
    raise SerialException(msg.errno, "could not open port {}: {}".format(self._port, msg))
serial.serialutil.SerialException: [Errno 2] could not open port /dev/serial/by-id/usb-ZEPHYR_RAK5010_Zephyr_B1E5A88410C9C828-if00: [Errno 2] No such file or directory: '/dev/serial/by-id/usb-ZEPHYR_RAK5010_Zephyr_B1E5A88410C9C828-if00'
DEBUG    twister_harness.device.hardware_adapter:hardware_adapter.py:140 Opening serial connection for /dev/serial/by-id/usb-ZEPHYR_RAK5010_Zephyr_B1E5A88410C9C828-if00
ERROR    twister_harness.device.hardware_adapter:hardware_adapter.py:151 Cannot open connection: [Errno 2] could not open port /dev/serial/by-id/usb-ZEPHYR_RAK5010_Zephyr_B1E5A88410C9C828-if00: [Errno 2] No such file or directory: '/dev/serial/by-id/usb-ZEPHYR_RAK5010_Zephyr_B1E5A88410C9C828-if00'
Traceback (most recent call last):
  File "/usr/local/lib/python3.11/dist-packages/serial/serialposix.py", line 322, in open
    self.fd = os.open(self.portstr, os.O_RDWR | os.O_NOCTTY | os.O_NONBLOCK)
              ^^^^^^^^^^^^^^^^^^^^^^^^^^^^^^^^^^^^^^^^^^^^^^^^^^^^^^^^^^^^^^
FileNotFoundError: [Errno 2] No such file or directory: '/dev/serial/by-id/usb-ZEPHYR_RAK5010_Zephyr_B1E5A88410C9C828-if00'

During handling of the above exception, another exception occurred:

Traceback (most recent call last):
  File "/__w/golioth-firmware-sdk/golioth-firmware-sdk/zephyr/scripts/pylib/pytest-twister-harness/src/twister_harness/device/hardware_adapter.py", line 142, in _connect_device
    self._serial_connection = serial.Serial(
                              ^^^^^^^^^^^^^^
  File "/usr/local/lib/python3.11/dist-packages/serial/serialutil.py", line 244, in __init__
    self.open()
  File "/usr/local/lib/python3.11/dist-packages/serial/serialposix.py", line 325, in open
    raise SerialException(msg.errno, "could not open port {}: {}".format(self._port, msg))
serial.serialutil.SerialException: [Errno 2] could not open port /dev/serial/by-id/usb-ZEPHYR_RAK5010_Zephyr_B1E5A88410C9C828-if00: [Errno 2] No such file or directory: '/dev/serial/by-id/usb-ZEPHYR_RAK5010_Zephyr_B1E5A88410C9C828-if00'
DEBUG    twister_harness.device.hardware_adapter:hardware_adapter.py:140 Opening serial connection for /dev/serial/by-id/usb-ZEPHYR_RAK5010_Zephyr_B1E5A88410C9C828-if00
DEBUG    twister_harness.helpers.utils:utils.py:22 Found matching key: CONFIG_SHELL_PROMPT_UART="uart:~$ "
INFO     twister_harness.fixtures:fixtures.py:75 Wait for prompt
DEBUG    twister_harness.helpers.shell:shell.py:47 Got prompt
DEBUG    httpx:_config.py:82 load_ssl_context verify=True cert=None trust_env=True http2=False
DEBUG    httpx:_config.py:148 load_verify_locations cafile='/usr/local/lib/python3.11/dist-packages/certifi/cacert.pem'
DEBUG    httpcore.connection:_trace.py:85 connect_tcp.started host='api.golioth.io' port=443 local_address=None timeout=5.0 socket_options=None
DEBUG    httpcore.connection:_trace.py:85 connect_tcp.complete return_value=<httpcore._backends.trio.TrioStream object at 0xffffb8aef350>
DEBUG    httpcore.connection:_trace.py:85 start_tls.started ssl_context=<ssl.SSLContext object at 0xffffb8d96d50> server_hostname='api.golioth.io' timeout=5.0
DEBUG    httpcore.connection:_trace.py:85 start_tls.complete return_value=<httpcore._backends.trio.TrioStream object at 0xffffb8b535d0>
DEBUG    httpcore.http11:_trace.py:85 send_request_headers.started request=<Request [b'DELETE']>
DEBUG    httpcore.http11:_trace.py:85 send_request_headers.complete
DEBUG    httpcore.http11:_trace.py:85 send_request_body.started request=<Request [b'DELETE']>
DEBUG    httpcore.http11:_trace.py:85 send_request_body.complete
DEBUG    httpcore.http11:_trace.py:85 receive_response_headers.started request=<Request [b'DELETE']>
DEBUG    httpcore.http11:_trace.py:85 receive_response_headers.complete return_value=(b'HTTP/1.1', 200, b'OK', [(b'Content-Length', b'2'), (b'Content-Type', b'application/json'), (b'Date', b'Tue, 26 Nov 2024 16:29:55 GMT'), (b'Grpc-Metadata-Content-Type', b'application/grpc'), (b'Via', b'kong/2.5.2'), (b'X-Kong-Proxy-Latency', b'0'), (b'X-Kong-Upstream-Latency', b'7')])
INFO     httpx:_client.py:1786 HTTP Request: DELETE https://api.golioth.io/v1/projects/firmware_ci/devices/6745f775bb6157cf6cdfabe0/data/counter "HTTP/1.1 200 OK"
DEBUG    httpcore.http11:_trace.py:85 receive_response_body.started request=<Request [b'DELETE']>
DEBUG    httpcore.http11:_trace.py:85 receive_response_body.complete
DEBUG    httpcore.http11:_trace.py:85 response_closed.started
DEBUG    httpcore.http11:_trace.py:85 response_closed.complete
DEBUG    httpcore.connection:_trace.py:85 close.started
DEBUG    httpcore.connection:_trace.py:85 close.complete
DEBUG    httpx:_config.py:82 load_ssl_context verify=True cert=None trust_env=True http2=False
DEBUG    httpx:_config.py:148 load_verify_locations cafile='/usr/local/lib/python3.11/dist-packages/certifi/cacert.pem'
DEBUG    httpcore.connection:_trace.py:85 connect_tcp.started host='api.golioth.io' port=443 local_address=None timeout=5.0 socket_options=None
DEBUG    httpcore.connection:_trace.py:85 connect_tcp.complete return_value=<httpcore._backends.trio.TrioStream object at 0xffffb8b25010>
DEBUG    httpcore.connection:_trace.py:85 start_tls.started ssl_context=<ssl.SSLContext object at 0xffffb8c892e0> server_hostname='api.golioth.io' timeout=5.0
DEBUG    httpcore.connection:_trace.py:85 start_tls.complete return_value=<httpcore._backends.trio.TrioStream object at 0xffffb8b53010>
DEBUG    httpcore.http11:_trace.py:85 send_request_headers.started request=<Request [b'GET']>
DEBUG    httpcore.http11:_trace.py:85 send_request_headers.complete
DEBUG    httpcore.http11:_trace.py:85 send_request_body.started request=<Request [b'GET']>
DEBUG    httpcore.http11:_trace.py:85 send_request_body.complete
DEBUG    httpcore.http11:_trace.py:85 receive_response_headers.started request=<Request [b'GET']>
DEBUG    httpcore.http11:_trace.py:85 receive_response_headers.complete return_value=(b'HTTP/1.1', 200, b'OK', [(b'Access-Control-Expose-Headers', b'Content-Range'), (b'Content-Length', b'203'), (b'Content-Range', b'credentials 0-1/1'), (b'Content-Type', b'application/json'), (b'Date', b'Tue, 26 Nov 2024 16:29:57 GMT'), (b'Grpc-Metadata-Access-Control-Expose-Headers', b'Content-Range'), (b'Grpc-Metadata-Content-Type', b'application/grpc'), (b'Via', b'kong/2.5.2'), (b'X-Kong-Proxy-Latency', b'1'), (b'X-Kong-Upstream-Latency', b'12')])
INFO     httpx:_client.py:1786 HTTP Request: GET https://api.golioth.io/v1/projects/firmware_ci/devices/6745f775bb6157cf6cdfabe0/credentials "HTTP/1.1 200 OK"
DEBUG    httpcore.http11:_trace.py:85 receive_response_body.started request=<Request [b'GET']>
DEBUG    httpcore.http11:_trace.py:85 receive_response_body.complete
DEBUG    httpcore.http11:_trace.py:85 response_closed.started
DEBUG    httpcore.http11:_trace.py:85 response_closed.complete
DEBUG    httpcore.connection:_trace.py:85 close.started
DEBUG    httpcore.connection:_trace.py:85 close.complete
DEBUG    twister_harness.device.device_adapter:device_adapter.py:148 #: [1;32muart:~$ [msettings set golioth/psk-id generated-QfuTttNOyNWVpYYb@firmware_ci
DEBUG    twister_harness.device.device_adapter:device_adapter.py:148 #: Setting golioth/psk-id to generated-QfuTttNOyNWVpYYb@firmware_ci
DEBUG    twister_harness.device.device_adapter:device_adapter.py:148 #: Setting golioth/psk-id saved as generated-QfuTttNOyNWVpYYb@firmware_ci
DEBUG    twister_harness.device.device_adapter:device_adapter.py:148 #: [1;32muart:~$ [m
DEBUG    twister_harness.device.device_adapter:device_adapter.py:148 #: [1;32muart:~$ [msettings set golioth/psk generated-QfuTttNOyNWVpYYb
DEBUG    twister_harness.device.device_adapter:device_adapter.py:148 #: Setting golioth/psk to generated-QfuTttNOyNWVpYYb
DEBUG    twister_harness.device.device_adapter:device_adapter.py:148 #: Setting golioth/psk saved as generated-QfuTttNOyNWVpYYb
DEBUG    twister_harness.device.device_adapter:device_adapter.py:148 #: [1;32muart:~$ [m
DEBUG    twister_harness.device.device_adapter:device_adapter.py:148 #: [1;32muart:~$ [msettings set wifi/ssid "***MIKES_ORANGE_PI_WIFI_SSID***"
DEBUG    twister_harness.device.device_adapter:device_adapter.py:148 #: Setting wifi/ssid to ***MIKES_ORANGE_PI_WIFI_SSID***
DEBUG    twister_harness.device.device_adapter:device_adapter.py:148 #: [1;31mFailed to set runtime setting: wifi/ssid:***MIKES_ORANGE_PI_WIFI_SSID***
DEBUG    twister_harness.device.device_adapter:device_adapter.py:148 #: [m[1;32muart:~$ [m
DEBUG    twister_harness.device.device_adapter:device_adapter.py:148 #: [1;32muart:~$ [msettings set wifi/psk "***MIKES_ORANGE_PI_WIFI_PSK***"
DEBUG    twister_harness.device.device_adapter:device_adapter.py:148 #: Setting wifi/psk to ***MIKES_ORANGE_PI_WIFI_PSK***
DEBUG    twister_harness.device.device_adapter:device_adapter.py:148 #: [1;31mFailed to set runtime setting: wifi/psk:***MIKES_ORANGE_PI_WIFI_PSK***
DEBUG    twister_harness.device.device_adapter:device_adapter.py:148 #: [m[1;32muart:~$ [m
DEBUG    twister_harness.device.device_adapter:device_adapter.py:148 #: [1;32muart:~$ [m[8D[J[00:00:00.291,564] [0m<inf> fs_nvs: alloc wra: 0, f98[0m
DEBUG    twister_harness.device.device_adapter:device_adapter.py:148 #: [1;32muart:~$ [m[8D[J[00:00:00.291,564] [0m<inf> fs_nvs: data wra: 0, f0[0m
DEBUG    twister_harness.device.device_adapter:device_adapter.py:148 #: [1;32muart:~$ [m[8D[J[00:00:00.291,625] [0m<inf> golioth_settings_autoload: Loading settings[0m
DEBUG    twister_harness.device.device_adapter:device_adapter.py:148 #: [1;32muart:~$ [m[8D[J[00:00:00.291,992] [0m<dbg> lightdb_set: main: Start LightDB set sample[0m
DEBUG    twister_harness.device.device_adapter:device_adapter.py:148 #: [1;32muart:~$ [m[8D[J[00:00:00.292,022] [0m<inf> golioth_samples: Bringing up network interface[0m
DEBUG    twister_harness.device.device_adapter:device_adapter.py:148 #: [1;32muart:~$ [m[8D[J[00:00:00.292,053] [0m<inf> golioth_samples: Waiting to obtain IP address[0m
DEBUG    twister_harness.device.device_adapter:device_adapter.py:148 #: [1;32muart:~$ [m[8D[J[00:00:21.785,339] [1;33m<wrn> modem_chat: quectel_bg95_init_chat_script: timed out[0m
DEBUG    twister_harness.device.device_adapter:device_adapter.py:148 #: [1;32muart:~$ [m[8D[J[1;32muart:~$ [m[8D[J[00:00:36.845,794] [0m<inf> golioth_mbox: Mbox created, bufsize: 1320, num_items: 10, item_size: 120[0m
DEBUG    twister_harness.device.device_adapter:device_adapter.py:148 #: [1;32muart:~$ [m[8D[J[1;32muart:~$ [m[8D[J[00:00:38.263,610] [0m<inf> golioth_coap_client_zephyr: Golioth CoAP client connected[0m
DEBUG    twister_harness.device.device_adapter:device_adapter.py:148 #: [1;32muart:~$ [m[8D[J[00:00:38.263,671] [0m<dbg> lightdb_set: main: Setting counter to 0[0m
DEBUG    twister_harness.device.device_adapter:device_adapter.py:148 #: [1;32muart:~$ [m[8D[J[00:00:38.263,671] [0m<dbg> lightdb_set: main: Before request (async)[0m
DEBUG    twister_harness.device.device_adapter:device_adapter.py:148 #: [1;32muart:~$ [m[8D[J[00:00:38.263,793] [0m<dbg> lightdb_set: main: After request (async)[0m
DEBUG    twister_harness.device.device_adapter:device_adapter.py:148 #: [1;32muart:~$ [m[8D[J[00:00:38.263,854] [0m<inf> lightdb_set: Golioth client connected[0m
DEBUG    twister_harness.device.device_adapter:device_adapter.py:148 #: [1;32muart:~$ [m[8D[J[00:00:38.263,854] [0m<inf> golioth_coap_client_zephyr: Entering CoAP I/O loop[0m
DEBUG    twister_harness.device.device_adapter:device_adapter.py:148 #: [1;32muart:~$ [m[8D[J[00:00:38.625,366] [0m<dbg> lightdb_set: counter_set_handler: Counter successfully set[0m
DEBUG    httpx:_config.py:82 load_ssl_context verify=True cert=None trust_env=True http2=False
DEBUG    httpx:_config.py:148 load_verify_locations cafile='/usr/local/lib/python3.11/dist-packages/certifi/cacert.pem'
DEBUG    httpcore.connection:_trace.py:85 connect_tcp.started host='api.golioth.io' port=443 local_address=None timeout=5.0 socket_options=None
DEBUG    httpcore.connection:_trace.py:85 connect_tcp.complete return_value=<httpcore._backends.trio.TrioStream object at 0xffffb8b26cd0>
DEBUG    httpcore.connection:_trace.py:85 start_tls.started ssl_context=<ssl.SSLContext object at 0xffffb8b489e0> server_hostname='api.golioth.io' timeout=5.0
DEBUG    httpcore.connection:_trace.py:85 start_tls.complete return_value=<httpcore._backends.trio.TrioStream object at 0xffffb8b77910>
DEBUG    httpcore.http11:_trace.py:85 send_request_headers.started request=<Request [b'GET']>
DEBUG    httpcore.http11:_trace.py:85 send_request_headers.complete
DEBUG    httpcore.http11:_trace.py:85 send_request_body.started request=<Request [b'GET']>
DEBUG    httpcore.http11:_trace.py:85 send_request_body.complete
DEBUG    httpcore.http11:_trace.py:85 receive_response_headers.started request=<Request [b'GET']>
DEBUG    httpcore.http11:_trace.py:85 receive_response_headers.complete return_value=(b'HTTP/1.1', 200, b'OK', [(b'Content-Length', b'10'), (b'Content-Type', b'application/json'), (b'Date', b'Tue, 26 Nov 2024 16:30:33 GMT'), (b'Grpc-Metadata-Content-Type', b'application/grpc'), (b'Via', b'kong/2.5.2'), (b'X-Kong-Proxy-Latency', b'0'), (b'X-Kong-Upstream-Latency', b'22')])
INFO     httpx:_client.py:1786 HTTP Request: GET https://api.golioth.io/v1/projects/firmware_ci/devices/6745f775bb6157cf6cdfabe0/data/counter "HTTP/1.1 200 OK"
DEBUG    httpcore.http11:_trace.py:85 receive_response_body.started request=<Request [b'GET']>
DEBUG    httpcore.http11:_trace.py:85 receive_response_body.complete
DEBUG    httpcore.http11:_trace.py:85 response_closed.started
DEBUG    httpcore.http11:_trace.py:85 response_closed.complete
DEBUG    httpcore.connection:_trace.py:85 close.started
DEBUG    httpcore.connection:_trace.py:85 close.complete
DEBUG    twister_harness.device.device_adapter:device_adapter.py:148 #: [1;32muart:~$ [m[8D[J[1;32muart:~$ [m[8D[J[00:00:43.263,885] [0m<dbg> lightdb_set: main: Setting counter to 1[0m
DEBUG    twister_harness.device.device_adapter:device_adapter.py:148 #: [1;32muart:~$ [m[8D[J[00:00:43.263,916] [0m<dbg> lightdb_set: main: Before request (sync)[0m
DEBUG    twister_harness.device.device_adapter:device_adapter.py:148 #: [1;32muart:~$ [m[8D[J[00:00:43.772,094] [0m<dbg> lightdb_set: counter_set_sync: Counter successfully set[0m
DEBUG    httpx:_config.py:82 load_ssl_context verify=True cert=None trust_env=True http2=False
DEBUG    httpx:_config.py:148 load_verify_locations cafile='/usr/local/lib/python3.11/dist-packages/certifi/cacert.pem'
DEBUG    httpcore.connection:_trace.py:85 connect_tcp.started host='api.golioth.io' port=443 local_address=None timeout=5.0 socket_options=None
DEBUG    httpcore.connection:_trace.py:85 connect_tcp.complete return_value=<httpcore._backends.trio.TrioStream object at 0xffffb8b76650>
DEBUG    httpcore.connection:_trace.py:85 start_tls.started ssl_context=<ssl.SSLContext object at 0xffffb8b48d40> server_hostname='api.golioth.io' timeout=5.0
DEBUG    httpcore.connection:_trace.py:85 start_tls.complete return_value=<httpcore._backends.trio.TrioStream object at 0xffffb8b5f790>
DEBUG    httpcore.http11:_trace.py:85 send_request_headers.started request=<Request [b'GET']>
DEBUG    httpcore.http11:_trace.py:85 send_request_headers.complete
DEBUG    httpcore.http11:_trace.py:85 send_request_body.started request=<Request [b'GET']>
DEBUG    httpcore.http11:_trace.py:85 send_request_body.complete
DEBUG    httpcore.http11:_trace.py:85 receive_response_headers.started request=<Request [b'GET']>
DEBUG    httpcore.http11:_trace.py:85 receive_response_headers.complete return_value=(b'HTTP/1.1', 200, b'OK', [(b'Content-Length', b'10'), (b'Content-Type', b'application/json'), (b'Date', b'Tue, 26 Nov 2024 16:30:38 GMT'), (b'Grpc-Metadata-Content-Type', b'application/grpc'), (b'Via', b'kong/2.5.2'), (b'X-Kong-Proxy-Latency', b'1'), (b'X-Kong-Upstream-Latency', b'7')])
INFO     httpx:_client.py:1786 HTTP Request: GET https://api.golioth.io/v1/projects/firmware_ci/devices/6745f775bb6157cf6cdfabe0/data/counter "HTTP/1.1 200 OK"
DEBUG    httpcore.http11:_trace.py:85 receive_response_body.started request=<Request [b'GET']>
DEBUG    httpcore.http11:_trace.py:85 receive_response_body.complete
DEBUG    httpcore.http11:_trace.py:85 response_closed.started
DEBUG    httpcore.http11:_trace.py:85 response_closed.complete
DEBUG    httpcore.connection:_trace.py:85 close.started
DEBUG    httpcore.connection:_trace.py:85 close.complete
DEBUG    twister_harness.device.device_adapter:device_adapter.py:148 #: [1;32muart:~$ [m[8D[J[00:00:43.772,094] [0m<dbg> lightdb_set: main: After request (sync)[0m
DEBUG    twister_harness.device.device_adapter:device_adapter.py:148 #: [1;32muart:~$ [m[8D[J[1;32muart:~$ [m[8D[J[00:00:48.772,155] [0m<dbg> lightdb_set: main: Setting counter to 2[0m
DEBUG    twister_harness.device.device_adapter:device_adapter.py:148 #: [1;32muart:~$ [m[8D[J[00:00:48.772,186] [0m<dbg> lightdb_set: main: Before request (json async)[0m
DEBUG    twister_harness.device.device_adapter:device_adapter.py:148 #: [1;32muart:~$ [m[8D[J[00:00:48.772,338] [0m<dbg> lightdb_set: main: After request (json async)[0m
DEBUG    twister_harness.device.device_adapter:device_adapter.py:148 #: [1;32muart:~$ [m[8D[J[00:00:49.413,970] [0m<dbg> lightdb_set: counter_set_handler: Counter successfully set[0m
DEBUG    httpx:_config.py:82 load_ssl_context verify=True cert=None trust_env=True http2=False
DEBUG    httpx:_config.py:148 load_verify_locations cafile='/usr/local/lib/python3.11/dist-packages/certifi/cacert.pem'
DEBUG    httpcore.connection:_trace.py:85 connect_tcp.started host='api.golioth.io' port=443 local_address=None timeout=5.0 socket_options=None
DEBUG    httpcore.connection:_trace.py:85 connect_tcp.complete return_value=<httpcore._backends.trio.TrioStream object at 0xffffb8b5c490>
DEBUG    httpcore.connection:_trace.py:85 start_tls.started ssl_context=<ssl.SSLContext object at 0xffffb8b49490> server_hostname='api.golioth.io' timeout=5.0
DEBUG    httpcore.connection:_trace.py:85 start_tls.complete return_value=<httpcore._backends.trio.TrioStream object at 0xffffb8b6ae90>
DEBUG    httpcore.http11:_trace.py:85 send_request_headers.started request=<Request [b'GET']>
DEBUG    httpcore.http11:_trace.py:85 send_request_headers.complete
DEBUG    httpcore.http11:_trace.py:85 send_request_body.started request=<Request [b'GET']>
DEBUG    httpcore.http11:_trace.py:85 send_request_body.complete
DEBUG    httpcore.http11:_trace.py:85 receive_response_headers.started request=<Request [b'GET']>
DEBUG    httpcore.http11:_trace.py:85 receive_response_headers.complete return_value=(b'HTTP/1.1', 200, b'OK', [(b'Content-Length', b'10'), (b'Content-Type', b'application/json'), (b'Date', b'Tue, 26 Nov 2024 16:30:43 GMT'), (b'Grpc-Metadata-Content-Type', b'application/grpc'), (b'Via', b'kong/2.5.2'), (b'X-Kong-Proxy-Latency', b'1'), (b'X-Kong-Upstream-Latency', b'9')])
INFO     httpx:_client.py:1786 HTTP Request: GET https://api.golioth.io/v1/projects/firmware_ci/devices/6745f775bb6157cf6cdfabe0/data/counter "HTTP/1.1 200 OK"
DEBUG    httpcore.http11:_trace.py:85 receive_response_body.started request=<Request [b'GET']>
DEBUG    httpcore.http11:_trace.py:85 receive_response_body.complete
DEBUG    httpcore.http11:_trace.py:85 response_closed.started
DEBUG    httpcore.http11:_trace.py:85 response_closed.complete
DEBUG    httpcore.connection:_trace.py:85 close.started
DEBUG    httpcore.connection:_trace.py:85 close.complete
DEBUG    twister_harness.device.device_adapter:device_adapter.py:148 #: [1;32muart:~$ [m[8D[J[1;32muart:~$ [m[8D[J[00:00:53.772,399] [0m<dbg> lightdb_set: main: Setting counter to 3[0m
DEBUG    twister_harness.device.device_adapter:device_adapter.py:148 #: [1;32muart:~$ [m[8D[J[00:00:53.772,430] [0m<dbg> lightdb_set: main: Before request (cbor sync)[0m
DEBUG    twister_harness.device.device_adapter:device_adapter.py:148 #: [1;32muart:~$ [m[8D[J[00:00:54.282,836] [0m<dbg> lightdb_set: counter_set_cbor_sync: Counter successfully set[0m
DEBUG    httpx:_config.py:82 load_ssl_context verify=True cert=None trust_env=True http2=False
DEBUG    httpx:_config.py:148 load_verify_locations cafile='/usr/local/lib/python3.11/dist-packages/certifi/cacert.pem'
DEBUG    httpcore.connection:_trace.py:85 connect_tcp.started host='api.golioth.io' port=443 local_address=None timeout=5.0 socket_options=None
DEBUG    httpcore.connection:_trace.py:85 connect_tcp.complete return_value=<httpcore._backends.trio.TrioStream object at 0xffffb8b69c90>
DEBUG    httpcore.connection:_trace.py:85 start_tls.started ssl_context=<ssl.SSLContext object at 0xffffb8b49be0> server_hostname='api.golioth.io' timeout=5.0
DEBUG    httpcore.connection:_trace.py:85 start_tls.complete return_value=<httpcore._backends.trio.TrioStream object at 0xffffb8b6ac10>
DEBUG    httpcore.http11:_trace.py:85 send_request_headers.started request=<Request [b'GET']>
DEBUG    httpcore.http11:_trace.py:85 send_request_headers.complete
DEBUG    httpcore.http11:_trace.py:85 send_request_body.started request=<Request [b'GET']>
DEBUG    httpcore.http11:_trace.py:85 send_request_body.complete
DEBUG    httpcore.http11:_trace.py:85 receive_response_headers.started request=<Request [b'GET']>
DEBUG    httpcore.http11:_trace.py:85 receive_response_headers.complete return_value=(b'HTTP/1.1', 200, b'OK', [(b'Content-Length', b'10'), (b'Content-Type', b'application/json'), (b'Date', b'Tue, 26 Nov 2024 16:30:48 GMT'), (b'Grpc-Metadata-Content-Type', b'application/grpc'), (b'Via', b'kong/2.5.2'), (b'X-Kong-Proxy-Latency', b'1'), (b'X-Kong-Upstream-Latency', b'7')])
INFO     httpx:_client.py:1786 HTTP Request: GET https://api.golioth.io/v1/projects/firmware_ci/devices/6745f775bb6157cf6cdfabe0/data/counter "HTTP/1.1 200 OK"
DEBUG    httpcore.http11:_trace.py:85 receive_response_body.started request=<Request [b'GET']>
DEBUG    httpcore.http11:_trace.py:85 receive_response_body.complete
DEBUG    httpcore.http11:_trace.py:85 response_closed.started
DEBUG    httpcore.http11:_trace.py:85 response_closed.complete
DEBUG    httpcore.connection:_trace.py:85 close.started
DEBUG    httpcore.connection:_trace.py:85 close.complete
DEBUG    twister_harness.device.hardware_adapter:hardware_adapter.py:187 Closed serial connection for /dev/serial/by-id/usb-ZEPHYR_RAK5010_Zephyr_B1E5A88410C9C828-if00
DEBUG    httpx:_config.py:82 load_ssl_context verify=True cert=None trust_env=True http2=False
DEBUG    httpx:_config.py:148 load_verify_locations cafile='/usr/local/lib/python3.11/dist-packages/certifi/cacert.pem'
DEBUG    httpcore.connection:_trace.py:85 connect_tcp.started host='api.golioth.io' port=443 local_address=None timeout=5.0 socket_options=None
DEBUG    httpcore.connection:_trace.py:85 connect_tcp.complete return_value=<httpcore._backends.trio.TrioStream object at 0xffffb8b69410>
DEBUG    httpcore.connection:_trace.py:85 start_tls.started ssl_context=<ssl.SSLContext object at 0xffffb8d97890> server_hostname='api.golioth.io' timeout=5.0
DEBUG    httpcore.connection:_trace.py:85 start_tls.complete return_value=<httpcore._backends.trio.TrioStream object at 0xffffb8b27b50>
DEBUG    httpcore.http11:_trace.py:85 send_request_headers.started request=<Request [b'DELETE']>
DEBUG    httpcore.http11:_trace.py:85 send_request_headers.complete
DEBUG    httpcore.http11:_trace.py:85 send_request_body.started request=<Request [b'DELETE']>
DEBUG    httpcore.http11:_trace.py:85 send_request_body.complete
DEBUG    httpcore.http11:_trace.py:85 receive_response_headers.started request=<Request [b'DELETE']>
DEBUG    httpcore.http11:_trace.py:85 receive_response_headers.complete return_value=(b'HTTP/1.1', 200, b'OK', [(b'Content-Length', b'2'), (b'Content-Type', b'application/json'), (b'Date', b'Tue, 26 Nov 2024 16:30:49 GMT'), (b'Grpc-Metadata-Content-Type', b'application/grpc'), (b'Via', b'kong/2.5.2'), (b'X-Kong-Proxy-Latency', b'1'), (b'X-Kong-Upstream-Latency', b'58')])
INFO     httpx:_client.py:1786 HTTP Request: DELETE https://api.golioth.io/v1/projects/firmware_ci/devices/6745f775bb6157cf6cdfabe0 "HTTP/1.1 200 OK"
DEBUG    httpcore.http11:_trace.py:85 receive_response_body.started request=<Request [b'DELETE']>
DEBUG    httpcore.http11:_trace.py:85 receive_response_body.complete
DEBUG    httpcore.http11:_trace.py:85 response_closed.started
DEBUG    httpcore.http11:_trace.py:85 response_closed.complete
DEBUG    httpcore.connection:_trace.py:85 close.started
DEBUG    httpcore.connection:_trace.py:85 close.complete