{"uid":"b72b3e4d3b50c758","name":"test_lightdb_get","fullName":"examples.esp_idf.lightdb.get.pytest.test_sample#test_lightdb_get","historyId":"f1665023a29e368653101cf8b6a81eaa","time":{"start":1760718132310,"stop":1760718155026,"duration":22716},"status":"broken","statusMessage":"trio.TooSlowError","statusTrace":"seconds = 10.0\n\n    @contextmanager\n    def fail_after(\n        seconds: float,\n        *,\n        shield: bool = False,\n    ) -> Generator[trio.CancelScope, None, None]:\n        \"\"\"Creates a cancel scope with the given timeout, and raises an error if\n        it is actually cancelled.\n    \n        This function and :func:`move_on_after` are similar in that both create a\n        cancel scope with a given timeout, and if the timeout expires then both\n        will cause :exc:`Cancelled` to be raised within the scope. The difference\n        is that when the :exc:`Cancelled` exception reaches :func:`move_on_after`,\n        it's caught and discarded. When it reaches :func:`fail_after`, then it's\n        caught and :exc:`TooSlowError` is raised in its place.\n    \n        The deadline of the cancel scope is calculated upon entering.\n    \n        Args:\n          seconds (float): The timeout.\n          shield (bool): Initial value for the `~trio.CancelScope.shield` attribute\n              of the newly created cancel scope.\n    \n        Raises:\n          TooSlowError: if a :exc:`Cancelled` exception is raised in this scope\n            and caught by the context manager.\n          ValueError: if *seconds* is less than zero or NaN.\n    \n        \"\"\"\n        with move_on_after(seconds, shield=shield) as scope:\n>           yield scope\n\n/root/venv/lib/python3.13/site-packages/trio/_timeouts.py:185: \n_ _ _ _ _ _ _ _ _ _ _ _ _ _ _ _ _ _ _ _ _ _ _ _ _ _ _ _ _ _ _ _ _ _ _ _ _ _ _ _ \n/root/venv/lib/python3.13/site-packages/pytest_hil/board.py:72: in wait_for_regex_in_line\n    chunk = await self.receive_some()\n            ^^^^^^^^^^^^^^^^^^^^^^^^^\n/root/venv/lib/python3.13/site-packages/pytest_hil/board.py:46: in receive_some\n    return await self.serial.receive_some()\n           ^^^^^^^^^^^^^^^^^^^^^^^^^^^^^^^^\n/root/venv/lib/python3.13/site-packages/trio_serial/abstract.py:215: in receive_some\n    return bytes(await self._recv(max_bytes))\n                 ^^^^^^^^^^^^^^^^^^^^^^^^^^^\n/root/venv/lib/python3.13/site-packages/trio_serial/posix.py:159: in _recv\n    await trio.lowlevel.wait_readable(self.fd)\n/root/venv/lib/python3.13/site-packages/trio/_core/_generated_io_epoll.py:45: in wait_readable\n    return await GLOBAL_RUN_CONTEXT.runner.io_manager.wait_readable(fd)\n           ^^^^^^^^^^^^^^^^^^^^^^^^^^^^^^^^^^^^^^^^^^^^^^^^^^^^^^^^^^^^\n/root/venv/lib/python3.13/site-packages/trio/_core/_io_epoll.py:336: in wait_readable\n    await self._epoll_wait(fd, \"read_task\")\n/root/venv/lib/python3.13/site-packages/trio/_core/_io_epoll.py:311: in _epoll_wait\n    await _core.wait_task_rescheduled(abort)\n/root/venv/lib/python3.13/site-packages/trio/_core/_traps.py:208: in wait_task_rescheduled\n    return (await _async_yield(WaitTaskRescheduled(abort_func))).unwrap()\n           ^^^^^^^^^^^^^^^^^^^^^^^^^^^^^^^^^^^^^^^^^^^^^^^^^^^^^^^^^^^^^^\n/root/venv/lib/python3.13/site-packages/outcome/_impl.py:213: in unwrap\n    raise captured_error\n_ _ _ _ _ _ _ _ _ _ _ _ _ _ _ _ _ _ _ _ _ _ _ _ _ _ _ _ _ _ _ _ _ _ _ _ _ _ _ _ \n\n    def raise_cancel() -> NoReturn:\n        if reason is None:\n            raise Cancelled._create(source=\"unknown\", reason=\"misnesting\")\n        else:\n>           raise Cancelled._create(\n                source=reason.source,\n                reason=reason.reason,\n                source_task=reason.source_task,\n            )\nE           trio.Cancelled: cancelled due to deadline\n\n/root/venv/lib/python3.13/site-packages/trio/_core/_run.py:1663: Cancelled\n\nDuring handling of the above exception, another exception occurred:\n\nboard = <pytest_hil.espidfboard.ESPIDFBoard object at 0xffffa3dc3770>\ndevice = <golioth.golioth.Device object at 0xffffa3ccc2f0>\n\n    async def test_lightdb_get(board, device):\n        # Delete counter in lightdb state\n    \n        await device.lightdb.delete(\"counter\")\n    \n        await trio.sleep(2)\n    \n        # Set Golioth credential\n        golioth_cred = (await device.credentials.list())[0]\n        await board.set_golioth_psk_credentials(golioth_cred.identity, golioth_cred.key)\n    \n        # Wait for device to connect\n        await board.wait_for_regex_in_line(r'.*Golioth client connected', timeout_s=30.0)\n    \n        # Verify lightdb reads\n    \n        await board.wait_for_regex_in_line(r'.*Failed to get counter \\(async\\): 0', timeout_s=10.0)\n    \n        await device.lightdb.set(\"counter\", 13)\n    \n>       await board.wait_for_regex_in_line(r'.*Counter \\(sync\\): 13', timeout_s=10.0)\n\nexamples/esp_idf/lightdb/get/pytest/test_sample.py:34: \n_ _ _ _ _ _ _ _ _ _ _ _ _ _ _ _ _ _ _ _ _ _ _ _ _ _ _ _ _ _ _ _ _ _ _ _ _ _ _ _ \n/root/venv/lib/python3.13/site-packages/pytest_hil/board.py:54: in wait_for_regex_in_line\n    with trio.fail_after(timeout_s):\n         ^^^^^^^^^^^^^^^^^^^^^^^^^^\n/usr/cpython-3.13.9-linux-aarch64-gnu/lib/python3.13/contextlib.py:162: in __exit__\n    self.gen.throw(value)\n_ _ _ _ _ _ _ _ _ _ _ _ _ _ _ _ _ _ _ _ _ _ _ _ _ _ _ _ _ _ _ _ _ _ _ _ _ _ _ _ \n\nseconds = 10.0\n\n    @contextmanager\n    def fail_after(\n        seconds: float,\n        *,\n        shield: bool = False,\n    ) -> Generator[trio.CancelScope, None, None]:\n        \"\"\"Creates a cancel scope with the given timeout, and raises an error if\n        it is actually cancelled.\n    \n        This function and :func:`move_on_after` are similar in that both create a\n        cancel scope with a given timeout, and if the timeout expires then both\n        will cause :exc:`Cancelled` to be raised within the scope. The difference\n        is that when the :exc:`Cancelled` exception reaches :func:`move_on_after`,\n        it's caught and discarded. When it reaches :func:`fail_after`, then it's\n        caught and :exc:`TooSlowError` is raised in its place.\n    \n        The deadline of the cancel scope is calculated upon entering.\n    \n        Args:\n          seconds (float): The timeout.\n          shield (bool): Initial value for the `~trio.CancelScope.shield` attribute\n              of the newly created cancel scope.\n    \n        Raises:\n          TooSlowError: if a :exc:`Cancelled` exception is raised in this scope\n            and caught by the context manager.\n          ValueError: if *seconds* is less than zero or NaN.\n    \n        \"\"\"\n        with move_on_after(seconds, shield=shield) as scope:\n            yield scope\n        if scope.cancelled_caught:\n>           raise TooSlowError\nE           trio.TooSlowError\n\n/root/venv/lib/python3.13/site-packages/trio/_timeouts.py:187: TooSlowError","flaky":false,"newFailed":false,"newBroken":false,"newPassed":false,"retriesCount":0,"retriesStatusChange":false,"beforeStages":[{"name":"anyio_backend","time":{"start":1760718088113,"stop":1760718088114,"duration":1},"status":"passed","steps":[],"attachments":[],"parameters":[],"shouldDisplayMessage":false,"stepsCount":0,"attachmentsCount":0,"hasContent":false,"attachmentStep":false},{"name":"baud","time":{"start":1760718088114,"stop":1760718088115,"duration":1},"status":"passed","steps":[],"attachments":[],"parameters":[],"shouldDisplayMessage":false,"stepsCount":0,"attachmentsCount":0,"hasContent":false,"attachmentStep":false},{"name":"wifi_ssid","time":{"start":1760718088115,"stop":1760718088115,"duration":0},"status":"passed","steps":[],"attachments":[],"parameters":[],"shouldDisplayMessage":false,"stepsCount":0,"attachmentsCount":0,"hasContent":false,"attachmentStep":false},{"name":"wifi_psk","time":{"start":1760718088116,"stop":1760718088116,"duration":0},"status":"passed","steps":[],"attachments":[],"parameters":[],"shouldDisplayMessage":false,"stepsCount":0,"attachmentsCount":0,"hasContent":false,"attachmentStep":false},{"name":"device_name","time":{"start":1760718088116,"stop":1760718088117,"duration":1},"status":"passed","steps":[],"attachments":[],"parameters":[],"shouldDisplayMessage":false,"stepsCount":0,"attachmentsCount":0,"hasContent":false,"attachmentStep":false},{"name":"api_key","time":{"start":1760718088117,"stop":1760718088117,"duration":0},"status":"passed","steps":[],"attachments":[],"parameters":[],"shouldDisplayMessage":false,"stepsCount":0,"attachmentsCount":0,"hasContent":false,"attachmentStep":false},{"name":"api_url","time":{"start":1760718088118,"stop":1760718088118,"duration":0},"status":"passed","steps":[],"attachments":[],"parameters":[],"shouldDisplayMessage":false,"stepsCount":0,"attachmentsCount":0,"hasContent":false,"attachmentStep":false},{"name":"board","time":{"start":1760718088118,"stop":1760718131563,"duration":43445},"status":"passed","steps":[],"attachments":[],"parameters":[],"shouldDisplayMessage":false,"stepsCount":0,"attachmentsCount":0,"hasContent":false,"attachmentStep":false},{"name":"board_name","time":{"start":1760718088150,"stop":1760718088150,"duration":0},"status":"passed","steps":[],"attachments":[],"parameters":[],"shouldDisplayMessage":false,"stepsCount":0,"attachmentsCount":0,"hasContent":false,"attachmentStep":false},{"name":"port","time":{"start":1760718088150,"stop":1760718088150,"duration":0},"status":"passed","steps":[],"attachments":[],"parameters":[],"shouldDisplayMessage":false,"stepsCount":0,"attachmentsCount":0,"hasContent":false,"attachmentStep":false},{"name":"fw_image","time":{"start":1760718088151,"stop":1760718088151,"duration":0},"status":"passed","steps":[],"attachments":[],"parameters":[],"shouldDisplayMessage":false,"stepsCount":0,"attachmentsCount":0,"hasContent":false,"attachmentStep":false},{"name":"serial_number","time":{"start":1760718088151,"stop":1760718088151,"duration":0},"status":"passed","steps":[],"attachments":[],"parameters":[],"shouldDisplayMessage":false,"stepsCount":0,"attachmentsCount":0,"hasContent":false,"attachmentStep":false},{"name":"bmp_port","time":{"start":1760718088152,"stop":1760718088152,"duration":0},"status":"passed","steps":[],"attachments":[],"parameters":[],"shouldDisplayMessage":false,"stepsCount":0,"attachmentsCount":0,"hasContent":false,"attachmentStep":false},{"name":"project","time":{"start":1760718131565,"stop":1760718131910,"duration":345},"status":"passed","steps":[],"attachments":[],"parameters":[],"shouldDisplayMessage":false,"stepsCount":0,"attachmentsCount":0,"hasContent":false,"attachmentStep":false},{"name":"device","time":{"start":1760718131911,"stop":1760718132306,"duration":395},"status":"passed","steps":[],"attachments":[],"parameters":[],"shouldDisplayMessage":false,"stepsCount":0,"attachmentsCount":0,"hasContent":false,"attachmentStep":false}],"testStage":{"status":"broken","statusMessage":"trio.TooSlowError","statusTrace":"seconds = 10.0\n\n    @contextmanager\n    def fail_after(\n        seconds: float,\n        *,\n        shield: bool = False,\n    ) -> Generator[trio.CancelScope, None, None]:\n        \"\"\"Creates a cancel scope with the given timeout, and raises an error if\n        it is actually cancelled.\n    \n        This function and :func:`move_on_after` are similar in that both create a\n        cancel scope with a given timeout, and if the timeout expires then both\n        will cause :exc:`Cancelled` to be raised within the scope. The difference\n        is that when the :exc:`Cancelled` exception reaches :func:`move_on_after`,\n        it's caught and discarded. When it reaches :func:`fail_after`, then it's\n        caught and :exc:`TooSlowError` is raised in its place.\n    \n        The deadline of the cancel scope is calculated upon entering.\n    \n        Args:\n          seconds (float): The timeout.\n          shield (bool): Initial value for the `~trio.CancelScope.shield` attribute\n              of the newly created cancel scope.\n    \n        Raises:\n          TooSlowError: if a :exc:`Cancelled` exception is raised in this scope\n            and caught by the context manager.\n          ValueError: if *seconds* is less than zero or NaN.\n    \n        \"\"\"\n        with move_on_after(seconds, shield=shield) as scope:\n>           yield scope\n\n/root/venv/lib/python3.13/site-packages/trio/_timeouts.py:185: \n_ _ _ _ _ _ _ _ _ _ _ _ _ _ _ _ _ _ _ _ _ _ _ _ _ _ _ _ _ _ _ _ _ _ _ _ _ _ _ _ \n/root/venv/lib/python3.13/site-packages/pytest_hil/board.py:72: in wait_for_regex_in_line\n    chunk = await self.receive_some()\n            ^^^^^^^^^^^^^^^^^^^^^^^^^\n/root/venv/lib/python3.13/site-packages/pytest_hil/board.py:46: in receive_some\n    return await self.serial.receive_some()\n           ^^^^^^^^^^^^^^^^^^^^^^^^^^^^^^^^\n/root/venv/lib/python3.13/site-packages/trio_serial/abstract.py:215: in receive_some\n    return bytes(await self._recv(max_bytes))\n                 ^^^^^^^^^^^^^^^^^^^^^^^^^^^\n/root/venv/lib/python3.13/site-packages/trio_serial/posix.py:159: in _recv\n    await trio.lowlevel.wait_readable(self.fd)\n/root/venv/lib/python3.13/site-packages/trio/_core/_generated_io_epoll.py:45: in wait_readable\n    return await GLOBAL_RUN_CONTEXT.runner.io_manager.wait_readable(fd)\n           ^^^^^^^^^^^^^^^^^^^^^^^^^^^^^^^^^^^^^^^^^^^^^^^^^^^^^^^^^^^^\n/root/venv/lib/python3.13/site-packages/trio/_core/_io_epoll.py:336: in wait_readable\n    await self._epoll_wait(fd, \"read_task\")\n/root/venv/lib/python3.13/site-packages/trio/_core/_io_epoll.py:311: in _epoll_wait\n    await _core.wait_task_rescheduled(abort)\n/root/venv/lib/python3.13/site-packages/trio/_core/_traps.py:208: in wait_task_rescheduled\n    return (await _async_yield(WaitTaskRescheduled(abort_func))).unwrap()\n           ^^^^^^^^^^^^^^^^^^^^^^^^^^^^^^^^^^^^^^^^^^^^^^^^^^^^^^^^^^^^^^\n/root/venv/lib/python3.13/site-packages/outcome/_impl.py:213: in unwrap\n    raise captured_error\n_ _ _ _ _ _ _ _ _ _ _ _ _ _ _ _ _ _ _ _ _ _ _ _ _ _ _ _ _ _ _ _ _ _ _ _ _ _ _ _ \n\n    def raise_cancel() -> NoReturn:\n        if reason is None:\n            raise Cancelled._create(source=\"unknown\", reason=\"misnesting\")\n        else:\n>           raise Cancelled._create(\n                source=reason.source,\n                reason=reason.reason,\n                source_task=reason.source_task,\n            )\nE           trio.Cancelled: cancelled due to deadline\n\n/root/venv/lib/python3.13/site-packages/trio/_core/_run.py:1663: Cancelled\n\nDuring handling of the above exception, another exception occurred:\n\nboard = <pytest_hil.espidfboard.ESPIDFBoard object at 0xffffa3dc3770>\ndevice = <golioth.golioth.Device object at 0xffffa3ccc2f0>\n\n    async def test_lightdb_get(board, device):\n        # Delete counter in lightdb state\n    \n        await device.lightdb.delete(\"counter\")\n    \n        await trio.sleep(2)\n    \n        # Set Golioth credential\n        golioth_cred = (await device.credentials.list())[0]\n        await board.set_golioth_psk_credentials(golioth_cred.identity, golioth_cred.key)\n    \n        # Wait for device to connect\n        await board.wait_for_regex_in_line(r'.*Golioth client connected', timeout_s=30.0)\n    \n        # Verify lightdb reads\n    \n        await board.wait_for_regex_in_line(r'.*Failed to get counter \\(async\\): 0', timeout_s=10.0)\n    \n        await device.lightdb.set(\"counter\", 13)\n    \n>       await board.wait_for_regex_in_line(r'.*Counter \\(sync\\): 13', timeout_s=10.0)\n\nexamples/esp_idf/lightdb/get/pytest/test_sample.py:34: \n_ _ _ _ _ _ _ _ _ _ _ _ _ _ _ _ _ _ _ _ _ _ _ _ _ _ _ _ _ _ _ _ _ _ _ _ _ _ _ _ \n/root/venv/lib/python3.13/site-packages/pytest_hil/board.py:54: in wait_for_regex_in_line\n    with trio.fail_after(timeout_s):\n         ^^^^^^^^^^^^^^^^^^^^^^^^^^\n/usr/cpython-3.13.9-linux-aarch64-gnu/lib/python3.13/contextlib.py:162: in __exit__\n    self.gen.throw(value)\n_ _ _ _ _ _ _ _ _ _ _ _ _ _ _ _ _ _ _ _ _ _ _ _ _ _ _ _ _ _ _ _ _ _ _ _ _ _ _ _ \n\nseconds = 10.0\n\n    @contextmanager\n    def fail_after(\n        seconds: float,\n        *,\n        shield: bool = False,\n    ) -> Generator[trio.CancelScope, None, None]:\n        \"\"\"Creates a cancel scope with the given timeout, and raises an error if\n        it is actually cancelled.\n    \n        This function and :func:`move_on_after` are similar in that both create a\n        cancel scope with a given timeout, and if the timeout expires then both\n        will cause :exc:`Cancelled` to be raised within the scope. The difference\n        is that when the :exc:`Cancelled` exception reaches :func:`move_on_after`,\n        it's caught and discarded. When it reaches :func:`fail_after`, then it's\n        caught and :exc:`TooSlowError` is raised in its place.\n    \n        The deadline of the cancel scope is calculated upon entering.\n    \n        Args:\n          seconds (float): The timeout.\n          shield (bool): Initial value for the `~trio.CancelScope.shield` attribute\n              of the newly created cancel scope.\n    \n        Raises:\n          TooSlowError: if a :exc:`Cancelled` exception is raised in this scope\n            and caught by the context manager.\n          ValueError: if *seconds* is less than zero or NaN.\n    \n        \"\"\"\n        with move_on_after(seconds, shield=shield) as scope:\n            yield scope\n        if scope.cancelled_caught:\n>           raise TooSlowError\nE           trio.TooSlowError\n\n/root/venv/lib/python3.13/site-packages/trio/_timeouts.py:187: TooSlowError","steps":[],"attachments":[{"uid":"ae748aa7bc39439f","name":"stdout","source":"ae748aa7bc39439f.txt","type":"text/plain","size":10350}],"parameters":[],"shouldDisplayMessage":true,"stepsCount":0,"attachmentsCount":1,"hasContent":true,"attachmentStep":false},"afterStages":[{"name":"device::0","time":{"start":1760718155647,"stop":1760718155852,"duration":205},"status":"passed","steps":[],"attachments":[],"parameters":[],"shouldDisplayMessage":false,"stepsCount":0,"attachmentsCount":0,"hasContent":false,"attachmentStep":false},{"name":"project::0","time":{"start":1760718155855,"stop":1760718155855,"duration":0},"status":"passed","steps":[],"attachments":[],"parameters":[],"shouldDisplayMessage":false,"stepsCount":0,"attachmentsCount":0,"hasContent":false,"attachmentStep":false},{"name":"board::0","time":{"start":1760718155857,"stop":1760718155867,"duration":10},"status":"passed","steps":[],"attachments":[],"parameters":[],"shouldDisplayMessage":false,"stepsCount":0,"attachmentsCount":0,"hasContent":false,"attachmentStep":false}],"labels":[{"name":"tag","value":"esp32s3_devkitc_espidf"},{"name":"tag","value":"esp-idf"},{"name":"parentSuite","value":"sample.esp-idf.esp32s3_devkitc_espidf"},{"name":"tag","value":"sams_orange_pi"},{"name":"tag","value":"anyio"},{"name":"suite","value":"test_sample"},{"name":"host","value":"9be2bb0d01a7"},{"name":"thread","value":"277-MainThread"},{"name":"framework","value":"pytest"},{"name":"language","value":"cpython3"},{"name":"package","value":"examples.esp_idf.lightdb.get.pytest.test_sample"},{"name":"resultFormat","value":"allure2"}],"parameters":[{"name":"board_name","value":"'esp32s3_devkitc_espidf'"},{"name":"platform_name","value":"'esp-idf'"}],"links":[],"hidden":true,"retry":true,"extra":{"categories":[],"tags":["esp32s3_devkitc_espidf","esp-idf","anyio","sams_orange_pi"]},"source":"b72b3e4d3b50c758.json","parameterValues":["'esp32s3_devkitc_espidf'","'esp-idf'"]}