DEBUG    twister_harness.device.factory:factory.py:37 Get device type "hardware"
DEBUG    httpx:_config.py:82 load_ssl_context verify=True cert=None trust_env=True http2=False
DEBUG    httpx:_config.py:148 load_verify_locations cafile='/usr/local/lib/python3.11/dist-packages/certifi/cacert.pem'
DEBUG    httpcore.connection:_trace.py:85 connect_tcp.started host='api.golioth.io' port=443 local_address=None timeout=5.0 socket_options=None
DEBUG    httpcore.connection:_trace.py:85 connect_tcp.complete return_value=<httpcore._backends.trio.TrioStream object at 0xffffae27d7d0>
DEBUG    httpcore.connection:_trace.py:85 start_tls.started ssl_context=<ssl.SSLContext object at 0xffffae397530> server_hostname='api.golioth.io' timeout=5.0
DEBUG    httpcore.connection:_trace.py:85 start_tls.complete return_value=<httpcore._backends.trio.TrioStream object at 0xffffae266510>
DEBUG    httpcore.http11:_trace.py:85 send_request_headers.started request=<Request [b'GET']>
DEBUG    httpcore.http11:_trace.py:85 send_request_headers.complete
DEBUG    httpcore.http11:_trace.py:85 send_request_body.started request=<Request [b'GET']>
DEBUG    httpcore.http11:_trace.py:85 send_request_body.complete
DEBUG    httpcore.http11:_trace.py:85 receive_response_headers.started request=<Request [b'GET']>
DEBUG    httpcore.http11:_trace.py:85 receive_response_headers.complete return_value=(b'HTTP/1.1', 200, b'OK', [(b'Access-Control-Expose-Headers', b'Content-Range'), (b'Content-Length', b'193'), (b'Content-Range', b'projects 0-1/1'), (b'Content-Type', b'application/json'), (b'Date', b'Tue, 01 Oct 2024 19:03:40 GMT'), (b'Grpc-Metadata-Access-Control-Expose-Headers', b'Content-Range'), (b'Grpc-Metadata-Content-Type', b'application/grpc'), (b'Via', b'kong/2.5.2'), (b'X-Kong-Proxy-Latency', b'0'), (b'X-Kong-Upstream-Latency', b'27')])
INFO     httpx:_client.py:1786 HTTP Request: GET https://api.golioth.io/v1/projects "HTTP/1.1 200 OK"
DEBUG    httpcore.http11:_trace.py:85 receive_response_body.started request=<Request [b'GET']>
DEBUG    httpcore.http11:_trace.py:85 receive_response_body.complete
DEBUG    httpcore.http11:_trace.py:85 response_closed.started
DEBUG    httpcore.http11:_trace.py:85 response_closed.complete
DEBUG    httpcore.connection:_trace.py:85 close.started
DEBUG    httpcore.connection:_trace.py:85 close.complete
DEBUG    httpx:_config.py:82 load_ssl_context verify=True cert=None trust_env=True http2=False
DEBUG    httpx:_config.py:148 load_verify_locations cafile='/usr/local/lib/python3.11/dist-packages/certifi/cacert.pem'
DEBUG    httpcore.connection:_trace.py:85 connect_tcp.started host='api.golioth.io' port=443 local_address=None timeout=5.0 socket_options=None
DEBUG    httpcore.connection:_trace.py:85 connect_tcp.complete return_value=<httpcore._backends.trio.TrioStream object at 0xffffae2ac250>
DEBUG    httpcore.connection:_trace.py:85 start_tls.started ssl_context=<ssl.SSLContext object at 0xffffae290b90> server_hostname='api.golioth.io' timeout=5.0
DEBUG    httpcore.connection:_trace.py:85 start_tls.complete return_value=<httpcore._backends.trio.TrioStream object at 0xffffae10b310>
DEBUG    httpcore.http11:_trace.py:85 send_request_headers.started request=<Request [b'POST']>
DEBUG    httpcore.http11:_trace.py:85 send_request_headers.complete
DEBUG    httpcore.http11:_trace.py:85 send_request_body.started request=<Request [b'POST']>
DEBUG    httpcore.http11:_trace.py:85 send_request_body.complete
DEBUG    httpcore.http11:_trace.py:85 receive_response_headers.started request=<Request [b'POST']>
DEBUG    httpcore.http11:_trace.py:85 receive_response_headers.complete return_value=(b'HTTP/1.1', 200, b'OK', [(b'Content-Length', b'297'), (b'Content-Type', b'application/json'), (b'Date', b'Tue, 01 Oct 2024 19:03:40 GMT'), (b'Grpc-Metadata-Content-Type', b'application/grpc'), (b'Via', b'kong/2.5.2'), (b'X-Kong-Proxy-Latency', b'3'), (b'X-Kong-Upstream-Latency', b'80')])
INFO     httpx:_client.py:1786 HTTP Request: POST https://api.golioth.io/v1/projects/firmware_ci/devices "HTTP/1.1 200 OK"
DEBUG    httpcore.http11:_trace.py:85 receive_response_body.started request=<Request [b'POST']>
DEBUG    httpcore.http11:_trace.py:85 receive_response_body.complete
DEBUG    httpcore.http11:_trace.py:85 response_closed.started
DEBUG    httpcore.http11:_trace.py:85 response_closed.complete
DEBUG    httpcore.connection:_trace.py:85 close.started
DEBUG    httpcore.connection:_trace.py:85 close.complete
DEBUG    httpx:_config.py:82 load_ssl_context verify=True cert=None trust_env=True http2=False
DEBUG    httpx:_config.py:148 load_verify_locations cafile='/usr/local/lib/python3.11/dist-packages/certifi/cacert.pem'
DEBUG    httpcore.connection:_trace.py:85 connect_tcp.started host='api.golioth.io' port=443 local_address=None timeout=5.0 socket_options=None
DEBUG    httpcore.connection:_trace.py:85 connect_tcp.complete return_value=<httpcore._backends.trio.TrioStream object at 0xffffae10b150>
DEBUG    httpcore.connection:_trace.py:85 start_tls.started ssl_context=<ssl.SSLContext object at 0xffffae291370> server_hostname='api.golioth.io' timeout=5.0
DEBUG    httpcore.connection:_trace.py:85 start_tls.complete return_value=<httpcore._backends.trio.TrioStream object at 0xffffae10afd0>
DEBUG    httpcore.http11:_trace.py:85 send_request_headers.started request=<Request [b'POST']>
DEBUG    httpcore.http11:_trace.py:85 send_request_headers.complete
DEBUG    httpcore.http11:_trace.py:85 send_request_body.started request=<Request [b'POST']>
DEBUG    httpcore.http11:_trace.py:85 send_request_body.complete
DEBUG    httpcore.http11:_trace.py:85 receive_response_headers.started request=<Request [b'POST']>
DEBUG    httpcore.http11:_trace.py:85 receive_response_headers.complete return_value=(b'HTTP/1.1', 200, b'OK', [(b'Content-Length', b'205'), (b'Content-Type', b'application/json'), (b'Date', b'Tue, 01 Oct 2024 19:03:41 GMT'), (b'Grpc-Metadata-Content-Type', b'application/grpc'), (b'Via', b'kong/2.5.2'), (b'X-Kong-Proxy-Latency', b'1'), (b'X-Kong-Upstream-Latency', b'41')])
INFO     httpx:_client.py:1786 HTTP Request: POST https://api.golioth.io/v1/projects/firmware_ci/devices/66fc478c9816a3c02f19b3b2/credentials "HTTP/1.1 200 OK"
DEBUG    httpcore.http11:_trace.py:85 receive_response_body.started request=<Request [b'POST']>
DEBUG    httpcore.http11:_trace.py:85 receive_response_body.complete
DEBUG    httpcore.http11:_trace.py:85 response_closed.started
DEBUG    httpcore.http11:_trace.py:85 response_closed.complete
DEBUG    httpcore.connection:_trace.py:85 close.started
DEBUG    httpcore.connection:_trace.py:85 close.complete
DEBUG    twister_harness.device.hardware_adapter:utils.py:37 Flashing command: /usr/local/bin/west flash --skip-rebuild --build-dir /__w/golioth-firmware-sdk/golioth-firmware-sdk/twister-out/rak5010_nrf52840/lightdb/get/sample.golioth.lightdb_get --runner blackmagicprobe -- --gdb=/usr/bin/gdb
DEBUG    twister_harness.device.hardware_adapter:hardware_adapter.py:131 Flashing finished
DEBUG    twister_harness.device.hardware_adapter:hardware_adapter.py:139 Opening serial connection for /dev/serial/by-id/usb-ZEPHYR_RAK5010_Zephyr_A79B173FF273CE6E-if00
ERROR    twister_harness.device.hardware_adapter:hardware_adapter.py:150 Cannot open connection: [Errno 2] could not open port /dev/serial/by-id/usb-ZEPHYR_RAK5010_Zephyr_A79B173FF273CE6E-if00: [Errno 2] No such file or directory: '/dev/serial/by-id/usb-ZEPHYR_RAK5010_Zephyr_A79B173FF273CE6E-if00'
Traceback (most recent call last):
  File "/usr/local/lib/python3.11/dist-packages/serial/serialposix.py", line 322, in open
    self.fd = os.open(self.portstr, os.O_RDWR | os.O_NOCTTY | os.O_NONBLOCK)
              ^^^^^^^^^^^^^^^^^^^^^^^^^^^^^^^^^^^^^^^^^^^^^^^^^^^^^^^^^^^^^^
FileNotFoundError: [Errno 2] No such file or directory: '/dev/serial/by-id/usb-ZEPHYR_RAK5010_Zephyr_A79B173FF273CE6E-if00'

During handling of the above exception, another exception occurred:

Traceback (most recent call last):
  File "/__w/golioth-firmware-sdk/golioth-firmware-sdk/zephyr/scripts/pylib/pytest-twister-harness/src/twister_harness/device/hardware_adapter.py", line 141, in _connect_device
    self._serial_connection = serial.Serial(
                              ^^^^^^^^^^^^^^
  File "/usr/local/lib/python3.11/dist-packages/serial/serialutil.py", line 244, in __init__
    self.open()
  File "/usr/local/lib/python3.11/dist-packages/serial/serialposix.py", line 325, in open
    raise SerialException(msg.errno, "could not open port {}: {}".format(self._port, msg))
serial.serialutil.SerialException: [Errno 2] could not open port /dev/serial/by-id/usb-ZEPHYR_RAK5010_Zephyr_A79B173FF273CE6E-if00: [Errno 2] No such file or directory: '/dev/serial/by-id/usb-ZEPHYR_RAK5010_Zephyr_A79B173FF273CE6E-if00'
DEBUG    twister_harness.device.hardware_adapter:hardware_adapter.py:139 Opening serial connection for /dev/serial/by-id/usb-ZEPHYR_RAK5010_Zephyr_A79B173FF273CE6E-if00
ERROR    twister_harness.device.hardware_adapter:hardware_adapter.py:150 Cannot open connection: [Errno 2] could not open port /dev/serial/by-id/usb-ZEPHYR_RAK5010_Zephyr_A79B173FF273CE6E-if00: [Errno 2] No such file or directory: '/dev/serial/by-id/usb-ZEPHYR_RAK5010_Zephyr_A79B173FF273CE6E-if00'
Traceback (most recent call last):
  File "/usr/local/lib/python3.11/dist-packages/serial/serialposix.py", line 322, in open
    self.fd = os.open(self.portstr, os.O_RDWR | os.O_NOCTTY | os.O_NONBLOCK)
              ^^^^^^^^^^^^^^^^^^^^^^^^^^^^^^^^^^^^^^^^^^^^^^^^^^^^^^^^^^^^^^
FileNotFoundError: [Errno 2] No such file or directory: '/dev/serial/by-id/usb-ZEPHYR_RAK5010_Zephyr_A79B173FF273CE6E-if00'

During handling of the above exception, another exception occurred:

Traceback (most recent call last):
  File "/__w/golioth-firmware-sdk/golioth-firmware-sdk/zephyr/scripts/pylib/pytest-twister-harness/src/twister_harness/device/hardware_adapter.py", line 141, in _connect_device
    self._serial_connection = serial.Serial(
                              ^^^^^^^^^^^^^^
  File "/usr/local/lib/python3.11/dist-packages/serial/serialutil.py", line 244, in __init__
    self.open()
  File "/usr/local/lib/python3.11/dist-packages/serial/serialposix.py", line 325, in open
    raise SerialException(msg.errno, "could not open port {}: {}".format(self._port, msg))
serial.serialutil.SerialException: [Errno 2] could not open port /dev/serial/by-id/usb-ZEPHYR_RAK5010_Zephyr_A79B173FF273CE6E-if00: [Errno 2] No such file or directory: '/dev/serial/by-id/usb-ZEPHYR_RAK5010_Zephyr_A79B173FF273CE6E-if00'
DEBUG    twister_harness.device.hardware_adapter:hardware_adapter.py:139 Opening serial connection for /dev/serial/by-id/usb-ZEPHYR_RAK5010_Zephyr_A79B173FF273CE6E-if00
ERROR    twister_harness.device.hardware_adapter:hardware_adapter.py:150 Cannot open connection: [Errno 2] could not open port /dev/serial/by-id/usb-ZEPHYR_RAK5010_Zephyr_A79B173FF273CE6E-if00: [Errno 2] No such file or directory: '/dev/serial/by-id/usb-ZEPHYR_RAK5010_Zephyr_A79B173FF273CE6E-if00'
Traceback (most recent call last):
  File "/usr/local/lib/python3.11/dist-packages/serial/serialposix.py", line 322, in open
    self.fd = os.open(self.portstr, os.O_RDWR | os.O_NOCTTY | os.O_NONBLOCK)
              ^^^^^^^^^^^^^^^^^^^^^^^^^^^^^^^^^^^^^^^^^^^^^^^^^^^^^^^^^^^^^^
FileNotFoundError: [Errno 2] No such file or directory: '/dev/serial/by-id/usb-ZEPHYR_RAK5010_Zephyr_A79B173FF273CE6E-if00'

During handling of the above exception, another exception occurred:

Traceback (most recent call last):
  File "/__w/golioth-firmware-sdk/golioth-firmware-sdk/zephyr/scripts/pylib/pytest-twister-harness/src/twister_harness/device/hardware_adapter.py", line 141, in _connect_device
    self._serial_connection = serial.Serial(
                              ^^^^^^^^^^^^^^
  File "/usr/local/lib/python3.11/dist-packages/serial/serialutil.py", line 244, in __init__
    self.open()
  File "/usr/local/lib/python3.11/dist-packages/serial/serialposix.py", line 325, in open
    raise SerialException(msg.errno, "could not open port {}: {}".format(self._port, msg))
serial.serialutil.SerialException: [Errno 2] could not open port /dev/serial/by-id/usb-ZEPHYR_RAK5010_Zephyr_A79B173FF273CE6E-if00: [Errno 2] No such file or directory: '/dev/serial/by-id/usb-ZEPHYR_RAK5010_Zephyr_A79B173FF273CE6E-if00'
DEBUG    twister_harness.device.hardware_adapter:hardware_adapter.py:139 Opening serial connection for /dev/serial/by-id/usb-ZEPHYR_RAK5010_Zephyr_A79B173FF273CE6E-if00
ERROR    twister_harness.device.hardware_adapter:hardware_adapter.py:150 Cannot open connection: [Errno 2] could not open port /dev/serial/by-id/usb-ZEPHYR_RAK5010_Zephyr_A79B173FF273CE6E-if00: [Errno 2] No such file or directory: '/dev/serial/by-id/usb-ZEPHYR_RAK5010_Zephyr_A79B173FF273CE6E-if00'
Traceback (most recent call last):
  File "/usr/local/lib/python3.11/dist-packages/serial/serialposix.py", line 322, in open
    self.fd = os.open(self.portstr, os.O_RDWR | os.O_NOCTTY | os.O_NONBLOCK)
              ^^^^^^^^^^^^^^^^^^^^^^^^^^^^^^^^^^^^^^^^^^^^^^^^^^^^^^^^^^^^^^
FileNotFoundError: [Errno 2] No such file or directory: '/dev/serial/by-id/usb-ZEPHYR_RAK5010_Zephyr_A79B173FF273CE6E-if00'

During handling of the above exception, another exception occurred:

Traceback (most recent call last):
  File "/__w/golioth-firmware-sdk/golioth-firmware-sdk/zephyr/scripts/pylib/pytest-twister-harness/src/twister_harness/device/hardware_adapter.py", line 141, in _connect_device
    self._serial_connection = serial.Serial(
                              ^^^^^^^^^^^^^^
  File "/usr/local/lib/python3.11/dist-packages/serial/serialutil.py", line 244, in __init__
    self.open()
  File "/usr/local/lib/python3.11/dist-packages/serial/serialposix.py", line 325, in open
    raise SerialException(msg.errno, "could not open port {}: {}".format(self._port, msg))
serial.serialutil.SerialException: [Errno 2] could not open port /dev/serial/by-id/usb-ZEPHYR_RAK5010_Zephyr_A79B173FF273CE6E-if00: [Errno 2] No such file or directory: '/dev/serial/by-id/usb-ZEPHYR_RAK5010_Zephyr_A79B173FF273CE6E-if00'
DEBUG    twister_harness.device.hardware_adapter:hardware_adapter.py:139 Opening serial connection for /dev/serial/by-id/usb-ZEPHYR_RAK5010_Zephyr_A79B173FF273CE6E-if00
ERROR    twister_harness.device.hardware_adapter:hardware_adapter.py:150 Cannot open connection: [Errno 2] could not open port /dev/serial/by-id/usb-ZEPHYR_RAK5010_Zephyr_A79B173FF273CE6E-if00: [Errno 2] No such file or directory: '/dev/serial/by-id/usb-ZEPHYR_RAK5010_Zephyr_A79B173FF273CE6E-if00'
Traceback (most recent call last):
  File "/usr/local/lib/python3.11/dist-packages/serial/serialposix.py", line 322, in open
    self.fd = os.open(self.portstr, os.O_RDWR | os.O_NOCTTY | os.O_NONBLOCK)
              ^^^^^^^^^^^^^^^^^^^^^^^^^^^^^^^^^^^^^^^^^^^^^^^^^^^^^^^^^^^^^^
FileNotFoundError: [Errno 2] No such file or directory: '/dev/serial/by-id/usb-ZEPHYR_RAK5010_Zephyr_A79B173FF273CE6E-if00'

During handling of the above exception, another exception occurred:

Traceback (most recent call last):
  File "/__w/golioth-firmware-sdk/golioth-firmware-sdk/zephyr/scripts/pylib/pytest-twister-harness/src/twister_harness/device/hardware_adapter.py", line 141, in _connect_device
    self._serial_connection = serial.Serial(
                              ^^^^^^^^^^^^^^
  File "/usr/local/lib/python3.11/dist-packages/serial/serialutil.py", line 244, in __init__
    self.open()
  File "/usr/local/lib/python3.11/dist-packages/serial/serialposix.py", line 325, in open
    raise SerialException(msg.errno, "could not open port {}: {}".format(self._port, msg))
serial.serialutil.SerialException: [Errno 2] could not open port /dev/serial/by-id/usb-ZEPHYR_RAK5010_Zephyr_A79B173FF273CE6E-if00: [Errno 2] No such file or directory: '/dev/serial/by-id/usb-ZEPHYR_RAK5010_Zephyr_A79B173FF273CE6E-if00'
DEBUG    twister_harness.device.hardware_adapter:hardware_adapter.py:139 Opening serial connection for /dev/serial/by-id/usb-ZEPHYR_RAK5010_Zephyr_A79B173FF273CE6E-if00
ERROR    twister_harness.device.hardware_adapter:hardware_adapter.py:150 Cannot open connection: [Errno 2] could not open port /dev/serial/by-id/usb-ZEPHYR_RAK5010_Zephyr_A79B173FF273CE6E-if00: [Errno 2] No such file or directory: '/dev/serial/by-id/usb-ZEPHYR_RAK5010_Zephyr_A79B173FF273CE6E-if00'
Traceback (most recent call last):
  File "/usr/local/lib/python3.11/dist-packages/serial/serialposix.py", line 322, in open
    self.fd = os.open(self.portstr, os.O_RDWR | os.O_NOCTTY | os.O_NONBLOCK)
              ^^^^^^^^^^^^^^^^^^^^^^^^^^^^^^^^^^^^^^^^^^^^^^^^^^^^^^^^^^^^^^
FileNotFoundError: [Errno 2] No such file or directory: '/dev/serial/by-id/usb-ZEPHYR_RAK5010_Zephyr_A79B173FF273CE6E-if00'

During handling of the above exception, another exception occurred:

Traceback (most recent call last):
  File "/__w/golioth-firmware-sdk/golioth-firmware-sdk/zephyr/scripts/pylib/pytest-twister-harness/src/twister_harness/device/hardware_adapter.py", line 141, in _connect_device
    self._serial_connection = serial.Serial(
                              ^^^^^^^^^^^^^^
  File "/usr/local/lib/python3.11/dist-packages/serial/serialutil.py", line 244, in __init__
    self.open()
  File "/usr/local/lib/python3.11/dist-packages/serial/serialposix.py", line 325, in open
    raise SerialException(msg.errno, "could not open port {}: {}".format(self._port, msg))
serial.serialutil.SerialException: [Errno 2] could not open port /dev/serial/by-id/usb-ZEPHYR_RAK5010_Zephyr_A79B173FF273CE6E-if00: [Errno 2] No such file or directory: '/dev/serial/by-id/usb-ZEPHYR_RAK5010_Zephyr_A79B173FF273CE6E-if00'
DEBUG    twister_harness.device.hardware_adapter:hardware_adapter.py:139 Opening serial connection for /dev/serial/by-id/usb-ZEPHYR_RAK5010_Zephyr_A79B173FF273CE6E-if00
ERROR    twister_harness.device.hardware_adapter:hardware_adapter.py:150 Cannot open connection: [Errno 2] could not open port /dev/serial/by-id/usb-ZEPHYR_RAK5010_Zephyr_A79B173FF273CE6E-if00: [Errno 2] No such file or directory: '/dev/serial/by-id/usb-ZEPHYR_RAK5010_Zephyr_A79B173FF273CE6E-if00'
Traceback (most recent call last):
  File "/usr/local/lib/python3.11/dist-packages/serial/serialposix.py", line 322, in open
    self.fd = os.open(self.portstr, os.O_RDWR | os.O_NOCTTY | os.O_NONBLOCK)
              ^^^^^^^^^^^^^^^^^^^^^^^^^^^^^^^^^^^^^^^^^^^^^^^^^^^^^^^^^^^^^^
FileNotFoundError: [Errno 2] No such file or directory: '/dev/serial/by-id/usb-ZEPHYR_RAK5010_Zephyr_A79B173FF273CE6E-if00'

During handling of the above exception, another exception occurred:

Traceback (most recent call last):
  File "/__w/golioth-firmware-sdk/golioth-firmware-sdk/zephyr/scripts/pylib/pytest-twister-harness/src/twister_harness/device/hardware_adapter.py", line 141, in _connect_device
    self._serial_connection = serial.Serial(
                              ^^^^^^^^^^^^^^
  File "/usr/local/lib/python3.11/dist-packages/serial/serialutil.py", line 244, in __init__
    self.open()
  File "/usr/local/lib/python3.11/dist-packages/serial/serialposix.py", line 325, in open
    raise SerialException(msg.errno, "could not open port {}: {}".format(self._port, msg))
serial.serialutil.SerialException: [Errno 2] could not open port /dev/serial/by-id/usb-ZEPHYR_RAK5010_Zephyr_A79B173FF273CE6E-if00: [Errno 2] No such file or directory: '/dev/serial/by-id/usb-ZEPHYR_RAK5010_Zephyr_A79B173FF273CE6E-if00'
DEBUG    twister_harness.device.hardware_adapter:hardware_adapter.py:139 Opening serial connection for /dev/serial/by-id/usb-ZEPHYR_RAK5010_Zephyr_A79B173FF273CE6E-if00
INFO     twister_harness.fixtures:fixtures.py:61 Wait for prompt
DEBUG    twister_harness.helpers.shell:shell.py:47 Got prompt
DEBUG    httpx:_config.py:82 load_ssl_context verify=True cert=None trust_env=True http2=False
DEBUG    httpx:_config.py:148 load_verify_locations cafile='/usr/local/lib/python3.11/dist-packages/certifi/cacert.pem'
DEBUG    httpcore.connection:_trace.py:85 connect_tcp.started host='api.golioth.io' port=443 local_address=None timeout=5.0 socket_options=None
DEBUG    httpcore.connection:_trace.py:85 connect_tcp.complete return_value=<httpcore._backends.trio.TrioStream object at 0xffffae150550>
DEBUG    httpcore.connection:_trace.py:85 start_tls.started ssl_context=<ssl.SSLContext object at 0xffffae397920> server_hostname='api.golioth.io' timeout=5.0
DEBUG    httpcore.connection:_trace.py:85 start_tls.complete return_value=<httpcore._backends.trio.TrioStream object at 0xffffae1514d0>
DEBUG    httpcore.http11:_trace.py:85 send_request_headers.started request=<Request [b'DELETE']>
DEBUG    httpcore.http11:_trace.py:85 send_request_headers.complete
DEBUG    httpcore.http11:_trace.py:85 send_request_body.started request=<Request [b'DELETE']>
DEBUG    httpcore.http11:_trace.py:85 send_request_body.complete
DEBUG    httpcore.http11:_trace.py:85 receive_response_headers.started request=<Request [b'DELETE']>
DEBUG    httpcore.http11:_trace.py:85 receive_response_headers.complete return_value=(b'HTTP/1.1', 200, b'OK', [(b'Content-Length', b'2'), (b'Content-Type', b'application/json'), (b'Date', b'Tue, 01 Oct 2024 19:04:17 GMT'), (b'Grpc-Metadata-Content-Type', b'application/grpc'), (b'Via', b'kong/2.5.2'), (b'X-Kong-Proxy-Latency', b'0'), (b'X-Kong-Upstream-Latency', b'8')])
INFO     httpx:_client.py:1786 HTTP Request: DELETE https://api.golioth.io/v1/projects/firmware_ci/devices/66fc478c9816a3c02f19b3b2/data/counter "HTTP/1.1 200 OK"
DEBUG    httpcore.http11:_trace.py:85 receive_response_body.started request=<Request [b'DELETE']>
DEBUG    httpcore.http11:_trace.py:85 receive_response_body.complete
DEBUG    httpcore.http11:_trace.py:85 response_closed.started
DEBUG    httpcore.http11:_trace.py:85 response_closed.complete
DEBUG    httpcore.connection:_trace.py:85 close.started
DEBUG    httpcore.connection:_trace.py:85 close.complete
DEBUG    httpx:_config.py:82 load_ssl_context verify=True cert=None trust_env=True http2=False
DEBUG    httpx:_config.py:148 load_verify_locations cafile='/usr/local/lib/python3.11/dist-packages/certifi/cacert.pem'
DEBUG    httpcore.connection:_trace.py:85 connect_tcp.started host='api.golioth.io' port=443 local_address=None timeout=5.0 socket_options=None
DEBUG    httpcore.connection:_trace.py:85 connect_tcp.complete return_value=<httpcore._backends.trio.TrioStream object at 0xffffae153f50>
DEBUG    httpcore.connection:_trace.py:85 start_tls.started ssl_context=<ssl.SSLContext object at 0xffffae2916d0> server_hostname='api.golioth.io' timeout=5.0
DEBUG    httpcore.connection:_trace.py:85 start_tls.complete return_value=<httpcore._backends.trio.TrioStream object at 0xffffae13acd0>
DEBUG    httpcore.http11:_trace.py:85 send_request_headers.started request=<Request [b'GET']>
DEBUG    httpcore.http11:_trace.py:85 send_request_headers.complete
DEBUG    httpcore.http11:_trace.py:85 send_request_body.started request=<Request [b'GET']>
DEBUG    httpcore.http11:_trace.py:85 send_request_body.complete
DEBUG    httpcore.http11:_trace.py:85 receive_response_headers.started request=<Request [b'GET']>
DEBUG    httpcore.http11:_trace.py:85 receive_response_headers.complete return_value=(b'HTTP/1.1', 200, b'OK', [(b'Access-Control-Expose-Headers', b'Content-Range'), (b'Content-Length', b'207'), (b'Content-Range', b'credentials 0-1/1'), (b'Content-Type', b'application/json'), (b'Date', b'Tue, 01 Oct 2024 19:04:19 GMT'), (b'Grpc-Metadata-Access-Control-Expose-Headers', b'Content-Range'), (b'Grpc-Metadata-Content-Type', b'application/grpc'), (b'Via', b'kong/2.5.2'), (b'X-Kong-Proxy-Latency', b'16'), (b'X-Kong-Upstream-Latency', b'14')])
INFO     httpx:_client.py:1786 HTTP Request: GET https://api.golioth.io/v1/projects/firmware_ci/devices/66fc478c9816a3c02f19b3b2/credentials "HTTP/1.1 200 OK"
DEBUG    httpcore.http11:_trace.py:85 receive_response_body.started request=<Request [b'GET']>
DEBUG    httpcore.http11:_trace.py:85 receive_response_body.complete
DEBUG    httpcore.http11:_trace.py:85 response_closed.started
DEBUG    httpcore.http11:_trace.py:85 response_closed.complete
DEBUG    httpcore.connection:_trace.py:85 close.started
DEBUG    httpcore.connection:_trace.py:85 close.complete
DEBUG    twister_harness.device.device_adapter:device_adapter.py:148 #: [1;32muart:~$ [msettings set golioth/psk-id generated-QeExbOQnkYPqdizG@firmware_ci
DEBUG    twister_harness.device.device_adapter:device_adapter.py:148 #: Setting golioth/psk-id to generated-QeExbOQnkYPqdizG@firmware_ci
DEBUG    twister_harness.device.device_adapter:device_adapter.py:148 #: Setting golioth/psk-id saved as generated-QeExbOQnkYPqdizG@firmware_ci
DEBUG    twister_harness.device.device_adapter:device_adapter.py:148 #: [1;32muart:~$ [m
DEBUG    twister_harness.device.device_adapter:device_adapter.py:148 #: [1;32muart:~$ [msettings set golioth/psk generated-QeExbOQnkYPqdizG
DEBUG    twister_harness.device.device_adapter:device_adapter.py:148 #: Setting golioth/psk to generated-QeExbOQnkYPqdizG
DEBUG    twister_harness.device.device_adapter:device_adapter.py:148 #: Setting golioth/psk saved as generated-QeExbOQnkYPqdizG
DEBUG    twister_harness.device.device_adapter:device_adapter.py:148 #: [1;32muart:~$ [m
DEBUG    twister_harness.device.device_adapter:device_adapter.py:148 #: [1;32muart:~$ [msettings set wifi/ssid "***MIKES_ORANGE_PI_WIFI_SSID***"
DEBUG    twister_harness.device.device_adapter:device_adapter.py:148 #: Setting wifi/ssid to ***MIKES_ORANGE_PI_WIFI_SSID***
DEBUG    twister_harness.device.device_adapter:device_adapter.py:148 #: [1;31mFailed to set runtime setting: wifi/ssid:***MIKES_ORANGE_PI_WIFI_SSID***
DEBUG    twister_harness.device.device_adapter:device_adapter.py:148 #: [m[1;32muart:~$ [m
DEBUG    twister_harness.device.device_adapter:device_adapter.py:148 #: [1;32muart:~$ [msettings set wifi/psk "***MIKES_ORANGE_PI_WIFI_PSK***"
DEBUG    twister_harness.device.device_adapter:device_adapter.py:148 #: Setting wifi/psk to ***MIKES_ORANGE_PI_WIFI_PSK***
DEBUG    twister_harness.device.device_adapter:device_adapter.py:148 #: [1;31mFailed to set runtime setting: wifi/psk:***MIKES_ORANGE_PI_WIFI_PSK***
DEBUG    twister_harness.device.device_adapter:device_adapter.py:148 #: [m[1;32muart:~$ [m
DEBUG    twister_harness.device.device_adapter:device_adapter.py:148 #: [1;32muart:~$ [m[8D[J[00:00:00.457,977] [0m<inf> golioth_settings_autoload: Loading settings[0m
DEBUG    twister_harness.device.device_adapter:device_adapter.py:148 #: [1;32muart:~$ [m[8D[J[00:00:00.458,343] [0m<dbg> lightdb_get: main: Start LightDB get sample[0m
DEBUG    twister_harness.device.device_adapter:device_adapter.py:148 #: [1;32muart:~$ [m[8D[J[00:00:00.458,343] [0m<inf> golioth_samples: Bringing up network interface[0m
DEBUG    twister_harness.device.device_adapter:device_adapter.py:148 #: [1;32muart:~$ [m[8D[J[00:00:00.458,374] [0m<inf> golioth_samples: Waiting to obtain IP address[0m
DEBUG    twister_harness.device.device_adapter:device_adapter.py:148 #: [1;32muart:~$ [m[8D[J[00:00:21.951,843] [1;33m<wrn> modem_chat: quectel_bg95_init_chat_script: timed out[0m
DEBUG    twister_harness.device.device_adapter:device_adapter.py:148 #: [1;32muart:~$ [m[8D[J[1;32muart:~$ [m[8D[J[00:00:37.201,629] [0m<inf> golioth_mbox: Mbox created, bufsize: 1232, num_items: 10, item_size: 112[0m
DEBUG    twister_harness.device.device_adapter:device_adapter.py:148 #: [1;32muart:~$ [m[8D[J[1;32muart:~$ [m[8D[J[00:00:38.638,610] [0m<inf> golioth_coap_client_zephyr: Golioth CoAP client connected[0m
DEBUG    twister_harness.device.device_adapter:device_adapter.py:148 #: [1;32muart:~$ [m[8D[J[00:00:38.638,641] [0m<inf> lightdb_get: Before request (async)[0m
DEBUG    twister_harness.device.device_adapter:device_adapter.py:148 #: [1;32muart:~$ [m[8D[J[00:00:38.638,732] [0m<inf> lightdb_get: After request (async)[0m
DEBUG    twister_harness.device.device_adapter:device_adapter.py:148 #: [1;32muart:~$ [m[8D[J[00:00:38.638,793] [0m<inf> lightdb_get: Golioth client connected[0m
DEBUG    twister_harness.device.device_adapter:device_adapter.py:148 #: [1;32muart:~$ [m[8D[J[00:00:38.638,793] [0m<inf> golioth_coap_client_zephyr: Entering CoAP I/O loop[0m
DEBUG    twister_harness.device.device_adapter:device_adapter.py:148 #: [1;32muart:~$ [m[8D[J[00:00:38.995,513] [1;33m<wrn> lightdb_get: Failed to get counter (async): 0[0m
DEBUG    httpx:_config.py:82 load_ssl_context verify=True cert=None trust_env=True http2=False
DEBUG    httpx:_config.py:148 load_verify_locations cafile='/usr/local/lib/python3.11/dist-packages/certifi/cacert.pem'
DEBUG    httpcore.connection:_trace.py:85 connect_tcp.started host='api.golioth.io' port=443 local_address=None timeout=5.0 socket_options=None
DEBUG    httpcore.connection:_trace.py:85 connect_tcp.complete return_value=<httpcore._backends.trio.TrioStream object at 0xffffae27da50>
DEBUG    httpcore.connection:_trace.py:85 start_tls.started ssl_context=<ssl.SSLContext object at 0xffffae144ef0> server_hostname='api.golioth.io' timeout=5.0
DEBUG    httpcore.connection:_trace.py:85 start_tls.complete return_value=<httpcore._backends.trio.TrioStream object at 0xffffae15b9d0>
DEBUG    httpcore.http11:_trace.py:85 send_request_headers.started request=<Request [b'POST']>
DEBUG    httpcore.http11:_trace.py:85 send_request_headers.complete
DEBUG    httpcore.http11:_trace.py:85 send_request_body.started request=<Request [b'POST']>
DEBUG    httpcore.http11:_trace.py:85 send_request_body.complete
DEBUG    httpcore.http11:_trace.py:85 receive_response_headers.started request=<Request [b'POST']>
DEBUG    httpcore.http11:_trace.py:85 receive_response_headers.complete return_value=(b'HTTP/1.1', 200, b'OK', [(b'Content-Length', b'11'), (b'Content-Type', b'application/json'), (b'Date', b'Tue, 01 Oct 2024 19:04:54 GMT'), (b'Grpc-Metadata-Content-Type', b'application/grpc'), (b'Via', b'kong/2.5.2'), (b'X-Kong-Proxy-Latency', b'0'), (b'X-Kong-Upstream-Latency', b'15')])
INFO     httpx:_client.py:1786 HTTP Request: POST https://api.golioth.io/v1/projects/firmware_ci/devices/66fc478c9816a3c02f19b3b2/data/counter "HTTP/1.1 200 OK"
DEBUG    httpcore.http11:_trace.py:85 receive_response_body.started request=<Request [b'POST']>
DEBUG    httpcore.http11:_trace.py:85 receive_response_body.complete
DEBUG    httpcore.http11:_trace.py:85 response_closed.started
DEBUG    httpcore.http11:_trace.py:85 response_closed.complete
DEBUG    httpcore.connection:_trace.py:85 close.started
DEBUG    httpcore.connection:_trace.py:85 close.complete
DEBUG    twister_harness.device.device_adapter:device_adapter.py:148 #: [1;32muart:~$ [m[8D[J[1;32muart:~$ [m[8D[J[00:00:43.638,793] [0m<inf> lightdb_get: Before request (sync)[0m
DEBUG    twister_harness.device.device_adapter:device_adapter.py:148 #: [1;32muart:~$ [m[8D[J[00:00:44.178,649] [0m<inf> lightdb_get: Counter (sync): 13[0m
DEBUG    httpx:_config.py:82 load_ssl_context verify=True cert=None trust_env=True http2=False
DEBUG    httpx:_config.py:148 load_verify_locations cafile='/usr/local/lib/python3.11/dist-packages/certifi/cacert.pem'
DEBUG    httpcore.connection:_trace.py:85 connect_tcp.started host='api.golioth.io' port=443 local_address=None timeout=5.0 socket_options=None
DEBUG    httpcore.connection:_trace.py:85 connect_tcp.complete return_value=<httpcore._backends.trio.TrioStream object at 0xffffae159a10>
DEBUG    httpcore.connection:_trace.py:85 start_tls.started ssl_context=<ssl.SSLContext object at 0xffffae145250> server_hostname='api.golioth.io' timeout=5.0
DEBUG    httpcore.connection:_trace.py:85 start_tls.complete return_value=<httpcore._backends.trio.TrioStream object at 0xffffae166c90>
DEBUG    httpcore.http11:_trace.py:85 send_request_headers.started request=<Request [b'POST']>
DEBUG    httpcore.http11:_trace.py:85 send_request_headers.complete
DEBUG    httpcore.http11:_trace.py:85 send_request_body.started request=<Request [b'POST']>
DEBUG    httpcore.http11:_trace.py:85 send_request_body.complete
DEBUG    httpcore.http11:_trace.py:85 receive_response_headers.started request=<Request [b'POST']>
DEBUG    httpcore.http11:_trace.py:85 receive_response_headers.complete return_value=(b'HTTP/1.1', 200, b'OK', [(b'Content-Length', b'11'), (b'Content-Type', b'application/json'), (b'Date', b'Tue, 01 Oct 2024 19:04:59 GMT'), (b'Grpc-Metadata-Content-Type', b'application/grpc'), (b'Via', b'kong/2.5.2'), (b'X-Kong-Proxy-Latency', b'1'), (b'X-Kong-Upstream-Latency', b'7')])
INFO     httpx:_client.py:1786 HTTP Request: POST https://api.golioth.io/v1/projects/firmware_ci/devices/66fc478c9816a3c02f19b3b2/data/counter "HTTP/1.1 200 OK"
DEBUG    httpcore.http11:_trace.py:85 receive_response_body.started request=<Request [b'POST']>
DEBUG    httpcore.http11:_trace.py:85 receive_response_body.complete
DEBUG    httpcore.http11:_trace.py:85 response_closed.started
DEBUG    httpcore.http11:_trace.py:85 response_closed.complete
DEBUG    httpcore.connection:_trace.py:85 close.started
DEBUG    httpcore.connection:_trace.py:85 close.complete
DEBUG    twister_harness.device.device_adapter:device_adapter.py:148 #: [1;32muart:~$ [m[8D[J[00:00:44.178,649] [0m<inf> lightdb_get: After request (sync)[0m
DEBUG    twister_harness.device.device_adapter:device_adapter.py:148 #: [1;32muart:~$ [m[8D[J[1;32muart:~$ [m[8D[J[00:00:49.178,710] [0m<inf> lightdb_get: Before JSON request (sync)[0m
DEBUG    twister_harness.device.device_adapter:device_adapter.py:148 #: [1;32muart:~$ [m[8D[J[00:00:49.677,185] [0m<inf> lightdb_get: LightDB JSON (sync)
DEBUG    twister_harness.device.device_adapter:device_adapter.py:148 #: 7b 22 63 6f 75 6e 74 65  72 22 3a 32 37 7d       |{"counte r":27}  [0m
DEBUG    httpx:_config.py:82 load_ssl_context verify=True cert=None trust_env=True http2=False
DEBUG    httpx:_config.py:148 load_verify_locations cafile='/usr/local/lib/python3.11/dist-packages/certifi/cacert.pem'
DEBUG    httpcore.connection:_trace.py:85 connect_tcp.started host='api.golioth.io' port=443 local_address=None timeout=5.0 socket_options=None
DEBUG    httpcore.connection:_trace.py:85 connect_tcp.complete return_value=<httpcore._backends.trio.TrioStream object at 0xffffae158150>
DEBUG    httpcore.connection:_trace.py:85 start_tls.started ssl_context=<ssl.SSLContext object at 0xffffae145910> server_hostname='api.golioth.io' timeout=5.0
DEBUG    httpcore.connection:_trace.py:85 start_tls.complete return_value=<httpcore._backends.trio.TrioStream object at 0xffffae17a8d0>
DEBUG    httpcore.http11:_trace.py:85 send_request_headers.started request=<Request [b'POST']>
DEBUG    httpcore.http11:_trace.py:85 send_request_headers.complete
DEBUG    httpcore.http11:_trace.py:85 send_request_body.started request=<Request [b'POST']>
DEBUG    httpcore.http11:_trace.py:85 send_request_body.complete
DEBUG    httpcore.http11:_trace.py:85 receive_response_headers.started request=<Request [b'POST']>
DEBUG    httpcore.http11:_trace.py:85 receive_response_headers.complete return_value=(b'HTTP/1.1', 200, b'OK', [(b'Content-Length', b'11'), (b'Content-Type', b'application/json'), (b'Date', b'Tue, 01 Oct 2024 19:05:05 GMT'), (b'Grpc-Metadata-Content-Type', b'application/grpc'), (b'Via', b'kong/2.5.2'), (b'X-Kong-Proxy-Latency', b'3'), (b'X-Kong-Upstream-Latency', b'9')])
INFO     httpx:_client.py:1786 HTTP Request: POST https://api.golioth.io/v1/projects/firmware_ci/devices/66fc478c9816a3c02f19b3b2/data/counter "HTTP/1.1 200 OK"
DEBUG    httpcore.http11:_trace.py:85 receive_response_body.started request=<Request [b'POST']>
DEBUG    httpcore.http11:_trace.py:85 receive_response_body.complete
DEBUG    httpcore.http11:_trace.py:85 response_closed.started
DEBUG    httpcore.http11:_trace.py:85 response_closed.complete
DEBUG    httpcore.connection:_trace.py:85 close.started
DEBUG    httpcore.connection:_trace.py:85 close.complete
DEBUG    twister_harness.device.device_adapter:device_adapter.py:148 #: [1;32muart:~$ [m[8D[J[00:00:49.677,185] [0m<inf> lightdb_get: After JSON request (sync)[0m
DEBUG    twister_harness.device.device_adapter:device_adapter.py:148 #: [1;32muart:~$ [m[8D[J[1;32muart:~$ [m[8D[J[00:00:54.677,246] [0m<inf> lightdb_get: Before CBOR request (async)[0m
DEBUG    twister_harness.device.device_adapter:device_adapter.py:148 #: [1;32muart:~$ [m[8D[J[00:00:54.677,368] [0m<inf> lightdb_get: After CBOR request (async)[0m
DEBUG    twister_harness.device.device_adapter:device_adapter.py:148 #: [1;32muart:~$ [m[8D[J[00:00:55.209,838] [0m<inf> lightdb_get: Counter (CBOR async): 99[0m
DEBUG    httpx:_config.py:82 load_ssl_context verify=True cert=None trust_env=True http2=False
DEBUG    httpx:_config.py:148 load_verify_locations cafile='/usr/local/lib/python3.11/dist-packages/certifi/cacert.pem'
DEBUG    httpcore.connection:_trace.py:85 connect_tcp.started host='api.golioth.io' port=443 local_address=None timeout=5.0 socket_options=None
DEBUG    httpcore.connection:_trace.py:85 connect_tcp.complete return_value=<httpcore._backends.trio.TrioStream object at 0xffffae179a90>
DEBUG    httpcore.connection:_trace.py:85 start_tls.started ssl_context=<ssl.SSLContext object at 0xffffae1462a0> server_hostname='api.golioth.io' timeout=5.0
DEBUG    httpcore.connection:_trace.py:85 start_tls.complete return_value=<httpcore._backends.trio.TrioStream object at 0xffffae17a090>
DEBUG    httpcore.http11:_trace.py:85 send_request_headers.started request=<Request [b'POST']>
DEBUG    httpcore.http11:_trace.py:85 send_request_headers.complete
DEBUG    httpcore.http11:_trace.py:85 send_request_body.started request=<Request [b'POST']>
DEBUG    httpcore.http11:_trace.py:85 send_request_body.complete
DEBUG    httpcore.http11:_trace.py:85 receive_response_headers.started request=<Request [b'POST']>
DEBUG    httpcore.http11:_trace.py:85 receive_response_headers.complete return_value=(b'HTTP/1.1', 200, b'OK', [(b'Content-Length', b'11'), (b'Content-Type', b'application/json'), (b'Date', b'Tue, 01 Oct 2024 19:05:10 GMT'), (b'Grpc-Metadata-Content-Type', b'application/grpc'), (b'Via', b'kong/2.5.2'), (b'X-Kong-Proxy-Latency', b'0'), (b'X-Kong-Upstream-Latency', b'7')])
INFO     httpx:_client.py:1786 HTTP Request: POST https://api.golioth.io/v1/projects/firmware_ci/devices/66fc478c9816a3c02f19b3b2/data/counter "HTTP/1.1 200 OK"
DEBUG    httpcore.http11:_trace.py:85 receive_response_body.started request=<Request [b'POST']>
DEBUG    httpcore.http11:_trace.py:85 receive_response_body.complete
DEBUG    httpcore.http11:_trace.py:85 response_closed.started
DEBUG    httpcore.http11:_trace.py:85 response_closed.complete
DEBUG    httpcore.connection:_trace.py:85 close.started
DEBUG    httpcore.connection:_trace.py:85 close.complete
DEBUG    twister_harness.device.device_adapter:device_adapter.py:148 #: [1;32muart:~$ [m[8D[J[1;32muart:~$ [m[8D[J[00:00:59.677,429] [0m<inf> lightdb_get: Before request (async)[0m
DEBUG    twister_harness.device.device_adapter:device_adapter.py:148 #: [1;32muart:~$ [m[8D[J[00:00:59.677,551] [0m<inf> lightdb_get: After request (async)[0m
DEBUG    twister_harness.device.device_adapter:device_adapter.py:148 #: [1;32muart:~$ [m[8D[J[00:01:00.234,039] [0m<inf> lightdb_get: Counter (async): 42[0m
DEBUG    twister_harness.device.hardware_adapter:hardware_adapter.py:186 Closed serial connection for /dev/serial/by-id/usb-ZEPHYR_RAK5010_Zephyr_A79B173FF273CE6E-if00
DEBUG    httpx:_config.py:82 load_ssl_context verify=True cert=None trust_env=True http2=False
DEBUG    httpx:_config.py:148 load_verify_locations cafile='/usr/local/lib/python3.11/dist-packages/certifi/cacert.pem'
DEBUG    httpcore.connection:_trace.py:85 connect_tcp.started host='api.golioth.io' port=443 local_address=None timeout=5.0 socket_options=None
DEBUG    httpcore.connection:_trace.py:85 connect_tcp.complete return_value=<httpcore._backends.trio.TrioStream object at 0xffffae166ed0>
DEBUG    httpcore.connection:_trace.py:85 start_tls.started ssl_context=<ssl.SSLContext object at 0xffffae396a80> server_hostname='api.golioth.io' timeout=5.0
DEBUG    httpcore.connection:_trace.py:85 start_tls.complete return_value=<httpcore._backends.trio.TrioStream object at 0xffffae15a050>
DEBUG    httpcore.http11:_trace.py:85 send_request_headers.started request=<Request [b'DELETE']>
DEBUG    httpcore.http11:_trace.py:85 send_request_headers.complete
DEBUG    httpcore.http11:_trace.py:85 send_request_body.started request=<Request [b'DELETE']>
DEBUG    httpcore.http11:_trace.py:85 send_request_body.complete
DEBUG    httpcore.http11:_trace.py:85 receive_response_headers.started request=<Request [b'DELETE']>
DEBUG    httpcore.http11:_trace.py:85 receive_response_headers.complete return_value=(b'HTTP/1.1', 200, b'OK', [(b'Content-Length', b'2'), (b'Content-Type', b'application/json'), (b'Date', b'Tue, 01 Oct 2024 19:05:16 GMT'), (b'Grpc-Metadata-Content-Type', b'application/grpc'), (b'Via', b'kong/2.5.2'), (b'X-Kong-Proxy-Latency', b'0'), (b'X-Kong-Upstream-Latency', b'27')])
INFO     httpx:_client.py:1786 HTTP Request: DELETE https://api.golioth.io/v1/projects/firmware_ci/devices/66fc478c9816a3c02f19b3b2 "HTTP/1.1 200 OK"
DEBUG    httpcore.http11:_trace.py:85 receive_response_body.started request=<Request [b'DELETE']>
DEBUG    httpcore.http11:_trace.py:85 receive_response_body.complete
DEBUG    httpcore.http11:_trace.py:85 response_closed.started
DEBUG    httpcore.http11:_trace.py:85 response_closed.complete
DEBUG    httpcore.connection:_trace.py:85 close.started
DEBUG    httpcore.connection:_trace.py:85 close.complete