DEBUG    twister_harness.device.factory:factory.py:37 Get device type "hardware"
DEBUG    httpcore.connection:_trace.py:87 connect_tcp.started host='api.golioth.io' port=443 local_address=None timeout=5.0 socket_options=None
DEBUG    httpcore.connection:_trace.py:87 connect_tcp.complete return_value=<httpcore._backends.trio.TrioStream object at 0xffff839a8590>
DEBUG    httpcore.connection:_trace.py:87 start_tls.started ssl_context=<ssl.SSLContext object at 0xffff83b60dd0> server_hostname='api.golioth.io' timeout=5.0
DEBUG    httpcore.connection:_trace.py:87 start_tls.complete return_value=<httpcore._backends.trio.TrioStream object at 0xffff83b51310>
DEBUG    httpcore.http11:_trace.py:87 send_request_headers.started request=<Request [b'GET']>
DEBUG    httpcore.http11:_trace.py:87 send_request_headers.complete
DEBUG    httpcore.http11:_trace.py:87 send_request_body.started request=<Request [b'GET']>
DEBUG    httpcore.http11:_trace.py:87 send_request_body.complete
DEBUG    httpcore.http11:_trace.py:87 receive_response_headers.started request=<Request [b'GET']>
DEBUG    httpcore.http11:_trace.py:87 receive_response_headers.complete return_value=(b'HTTP/1.1', 200, b'OK', [(b'content-type', b'application/json'), (b'content-length', b'188'), (b'access-control-expose-headers', b'Content-Range'), (b'content-range', b'projects 0-1/1'), (b'grpc-metadata-access-control-expose-headers', b'Content-Range'), (b'grpc-metadata-content-type', b'application/grpc'), (b'date', b'Tue, 21 Oct 2025 15:41:04 GMT'), (b'x-kong-upstream-latency', b'16'), (b'x-kong-proxy-latency', b'0'), (b'via', b'kong/2.5.2, 1.1 google')])
INFO     httpx:_client.py:1740 HTTP Request: GET https://api.golioth.io/v1/projects "HTTP/1.1 200 OK"
DEBUG    httpcore.http11:_trace.py:87 receive_response_body.started request=<Request [b'GET']>
DEBUG    httpcore.http11:_trace.py:87 receive_response_body.complete
DEBUG    httpcore.http11:_trace.py:87 response_closed.started
DEBUG    httpcore.http11:_trace.py:87 response_closed.complete
DEBUG    httpcore.connection:_trace.py:87 close.started
DEBUG    httpcore.connection:_trace.py:87 close.complete
DEBUG    httpcore.connection:_trace.py:87 connect_tcp.started host='api.golioth.io' port=443 local_address=None timeout=5.0 socket_options=None
DEBUG    httpcore.connection:_trace.py:87 connect_tcp.complete return_value=<httpcore._backends.trio.TrioStream object at 0xffff83b52d50>
DEBUG    httpcore.connection:_trace.py:87 start_tls.started ssl_context=<ssl.SSLContext object at 0xffff83b612e0> server_hostname='api.golioth.io' timeout=5.0
DEBUG    httpcore.connection:_trace.py:87 start_tls.complete return_value=<httpcore._backends.trio.TrioStream object at 0xffff83b3e060>
DEBUG    httpcore.http11:_trace.py:87 send_request_headers.started request=<Request [b'POST']>
DEBUG    httpcore.http11:_trace.py:87 send_request_headers.complete
DEBUG    httpcore.http11:_trace.py:87 send_request_body.started request=<Request [b'POST']>
DEBUG    httpcore.http11:_trace.py:87 send_request_body.complete
DEBUG    httpcore.http11:_trace.py:87 receive_response_headers.started request=<Request [b'POST']>
DEBUG    httpcore.http11:_trace.py:87 receive_response_headers.complete return_value=(b'HTTP/1.1', 200, b'OK', [(b'content-type', b'application/json'), (b'content-length', b'287'), (b'grpc-metadata-content-type', b'application/grpc'), (b'date', b'Tue, 21 Oct 2025 15:41:04 GMT'), (b'x-kong-upstream-latency', b'16'), (b'x-kong-proxy-latency', b'0'), (b'via', b'kong/2.5.2, 1.1 google')])
INFO     httpx:_client.py:1740 HTTP Request: POST https://api.golioth.io/v1/projects/firmware_ci/devices "HTTP/1.1 200 OK"
DEBUG    httpcore.http11:_trace.py:87 receive_response_body.started request=<Request [b'POST']>
DEBUG    httpcore.http11:_trace.py:87 receive_response_body.complete
DEBUG    httpcore.http11:_trace.py:87 response_closed.started
DEBUG    httpcore.http11:_trace.py:87 response_closed.complete
DEBUG    httpcore.connection:_trace.py:87 close.started
DEBUG    httpcore.connection:_trace.py:87 close.complete
DEBUG    httpcore.connection:_trace.py:87 connect_tcp.started host='api.golioth.io' port=443 local_address=None timeout=5.0 socket_options=None
DEBUG    httpcore.connection:_trace.py:87 connect_tcp.complete return_value=<httpcore._backends.trio.TrioStream object at 0xffff83b3e650>
DEBUG    httpcore.connection:_trace.py:87 start_tls.started ssl_context=<ssl.SSLContext object at 0xffff83b615b0> server_hostname='api.golioth.io' timeout=5.0
DEBUG    httpcore.connection:_trace.py:87 start_tls.complete return_value=<httpcore._backends.trio.TrioStream object at 0xffff83994710>
DEBUG    httpcore.http11:_trace.py:87 send_request_headers.started request=<Request [b'POST']>
DEBUG    httpcore.http11:_trace.py:87 send_request_headers.complete
DEBUG    httpcore.http11:_trace.py:87 send_request_body.started request=<Request [b'POST']>
DEBUG    httpcore.http11:_trace.py:87 send_request_body.complete
DEBUG    httpcore.http11:_trace.py:87 receive_response_headers.started request=<Request [b'POST']>
DEBUG    httpcore.http11:_trace.py:87 receive_response_headers.complete return_value=(b'HTTP/1.1', 200, b'OK', [(b'content-type', b'application/json'), (b'content-length', b'201'), (b'grpc-metadata-content-type', b'application/grpc'), (b'date', b'Tue, 21 Oct 2025 15:41:05 GMT'), (b'x-kong-upstream-latency', b'17'), (b'x-kong-proxy-latency', b'0'), (b'via', b'kong/2.5.2, 1.1 google')])
INFO     httpx:_client.py:1740 HTTP Request: POST https://api.golioth.io/v1/projects/firmware_ci/devices/68f7a990424cece3ad3e3274/credentials "HTTP/1.1 200 OK"
DEBUG    httpcore.http11:_trace.py:87 receive_response_body.started request=<Request [b'POST']>
DEBUG    httpcore.http11:_trace.py:87 receive_response_body.complete
DEBUG    httpcore.http11:_trace.py:87 response_closed.started
DEBUG    httpcore.http11:_trace.py:87 response_closed.complete
DEBUG    httpcore.connection:_trace.py:87 close.started
DEBUG    httpcore.connection:_trace.py:87 close.complete
DEBUG    twister_harness.device.hardware_adapter:utils.py:37 Flashing command: /root/venv/bin/west flash --skip-rebuild --build-dir /__w/golioth-firmware-sdk/golioth-firmware-sdk/twister-out/rak5010_nrf52840/zephyr/lightdb/observe/sample.golioth.lightdb_observe --runner blackmagicprobe -- --gdb=/usr/bin/gdb
DEBUG    twister_harness.device.hardware_adapter:hardware_adapter.py:135 Flashing finished
DEBUG    twister_harness.device.hardware_adapter:hardware_adapter.py:143 Opening serial connection for /dev/serial/by-id/usb-ZEPHYR_RAK5010_Zephyr_A79B173FF273CE6E-if00
ERROR    twister_harness.device.hardware_adapter:hardware_adapter.py:154 Cannot open connection: [Errno 2] could not open port /dev/serial/by-id/usb-ZEPHYR_RAK5010_Zephyr_A79B173FF273CE6E-if00: [Errno 2] No such file or directory: '/dev/serial/by-id/usb-ZEPHYR_RAK5010_Zephyr_A79B173FF273CE6E-if00'
Traceback (most recent call last):
  File "/root/venv/lib/python3.13/site-packages/serial/serialposix.py", line 322, in open
    self.fd = os.open(self.portstr, os.O_RDWR | os.O_NOCTTY | os.O_NONBLOCK)
              ~~~~~~~^^^^^^^^^^^^^^^^^^^^^^^^^^^^^^^^^^^^^^^^^^^^^^^^^^^^^^^
FileNotFoundError: [Errno 2] No such file or directory: '/dev/serial/by-id/usb-ZEPHYR_RAK5010_Zephyr_A79B173FF273CE6E-if00'

During handling of the above exception, another exception occurred:

Traceback (most recent call last):
  File "/__w/golioth-firmware-sdk/golioth-firmware-sdk/zephyr/scripts/pylib/pytest-twister-harness/src/twister_harness/device/hardware_adapter.py", line 145, in _connect_device
    self._serial_connection = serial.Serial(
                              ~~~~~~~~~~~~~^
        serial_name,
        ^^^^^^^^^^^^
    ...<4 lines>...
        timeout=self.base_timeout,
        ^^^^^^^^^^^^^^^^^^^^^^^^^^
    )
    ^
  File "/root/venv/lib/python3.13/site-packages/serial/serialutil.py", line 244, in __init__
    self.open()
    ~~~~~~~~~^^
  File "/root/venv/lib/python3.13/site-packages/serial/serialposix.py", line 325, in open
    raise SerialException(msg.errno, "could not open port {}: {}".format(self._port, msg))
serial.serialutil.SerialException: [Errno 2] could not open port /dev/serial/by-id/usb-ZEPHYR_RAK5010_Zephyr_A79B173FF273CE6E-if00: [Errno 2] No such file or directory: '/dev/serial/by-id/usb-ZEPHYR_RAK5010_Zephyr_A79B173FF273CE6E-if00'
DEBUG    twister_harness.device.hardware_adapter:hardware_adapter.py:143 Opening serial connection for /dev/serial/by-id/usb-ZEPHYR_RAK5010_Zephyr_A79B173FF273CE6E-if00
ERROR    twister_harness.device.hardware_adapter:hardware_adapter.py:154 Cannot open connection: [Errno 2] could not open port /dev/serial/by-id/usb-ZEPHYR_RAK5010_Zephyr_A79B173FF273CE6E-if00: [Errno 2] No such file or directory: '/dev/serial/by-id/usb-ZEPHYR_RAK5010_Zephyr_A79B173FF273CE6E-if00'
Traceback (most recent call last):
  File "/root/venv/lib/python3.13/site-packages/serial/serialposix.py", line 322, in open
    self.fd = os.open(self.portstr, os.O_RDWR | os.O_NOCTTY | os.O_NONBLOCK)
              ~~~~~~~^^^^^^^^^^^^^^^^^^^^^^^^^^^^^^^^^^^^^^^^^^^^^^^^^^^^^^^
FileNotFoundError: [Errno 2] No such file or directory: '/dev/serial/by-id/usb-ZEPHYR_RAK5010_Zephyr_A79B173FF273CE6E-if00'

During handling of the above exception, another exception occurred:

Traceback (most recent call last):
  File "/__w/golioth-firmware-sdk/golioth-firmware-sdk/zephyr/scripts/pylib/pytest-twister-harness/src/twister_harness/device/hardware_adapter.py", line 145, in _connect_device
    self._serial_connection = serial.Serial(
                              ~~~~~~~~~~~~~^
        serial_name,
        ^^^^^^^^^^^^
    ...<4 lines>...
        timeout=self.base_timeout,
        ^^^^^^^^^^^^^^^^^^^^^^^^^^
    )
    ^
  File "/root/venv/lib/python3.13/site-packages/serial/serialutil.py", line 244, in __init__
    self.open()
    ~~~~~~~~~^^
  File "/root/venv/lib/python3.13/site-packages/serial/serialposix.py", line 325, in open
    raise SerialException(msg.errno, "could not open port {}: {}".format(self._port, msg))
serial.serialutil.SerialException: [Errno 2] could not open port /dev/serial/by-id/usb-ZEPHYR_RAK5010_Zephyr_A79B173FF273CE6E-if00: [Errno 2] No such file or directory: '/dev/serial/by-id/usb-ZEPHYR_RAK5010_Zephyr_A79B173FF273CE6E-if00'
DEBUG    twister_harness.device.hardware_adapter:hardware_adapter.py:143 Opening serial connection for /dev/serial/by-id/usb-ZEPHYR_RAK5010_Zephyr_A79B173FF273CE6E-if00
ERROR    twister_harness.device.hardware_adapter:hardware_adapter.py:154 Cannot open connection: [Errno 2] could not open port /dev/serial/by-id/usb-ZEPHYR_RAK5010_Zephyr_A79B173FF273CE6E-if00: [Errno 2] No such file or directory: '/dev/serial/by-id/usb-ZEPHYR_RAK5010_Zephyr_A79B173FF273CE6E-if00'
Traceback (most recent call last):
  File "/root/venv/lib/python3.13/site-packages/serial/serialposix.py", line 322, in open
    self.fd = os.open(self.portstr, os.O_RDWR | os.O_NOCTTY | os.O_NONBLOCK)
              ~~~~~~~^^^^^^^^^^^^^^^^^^^^^^^^^^^^^^^^^^^^^^^^^^^^^^^^^^^^^^^
FileNotFoundError: [Errno 2] No such file or directory: '/dev/serial/by-id/usb-ZEPHYR_RAK5010_Zephyr_A79B173FF273CE6E-if00'

During handling of the above exception, another exception occurred:

Traceback (most recent call last):
  File "/__w/golioth-firmware-sdk/golioth-firmware-sdk/zephyr/scripts/pylib/pytest-twister-harness/src/twister_harness/device/hardware_adapter.py", line 145, in _connect_device
    self._serial_connection = serial.Serial(
                              ~~~~~~~~~~~~~^
        serial_name,
        ^^^^^^^^^^^^
    ...<4 lines>...
        timeout=self.base_timeout,
        ^^^^^^^^^^^^^^^^^^^^^^^^^^
    )
    ^
  File "/root/venv/lib/python3.13/site-packages/serial/serialutil.py", line 244, in __init__
    self.open()
    ~~~~~~~~~^^
  File "/root/venv/lib/python3.13/site-packages/serial/serialposix.py", line 325, in open
    raise SerialException(msg.errno, "could not open port {}: {}".format(self._port, msg))
serial.serialutil.SerialException: [Errno 2] could not open port /dev/serial/by-id/usb-ZEPHYR_RAK5010_Zephyr_A79B173FF273CE6E-if00: [Errno 2] No such file or directory: '/dev/serial/by-id/usb-ZEPHYR_RAK5010_Zephyr_A79B173FF273CE6E-if00'
DEBUG    twister_harness.device.hardware_adapter:hardware_adapter.py:143 Opening serial connection for /dev/serial/by-id/usb-ZEPHYR_RAK5010_Zephyr_A79B173FF273CE6E-if00
ERROR    twister_harness.device.hardware_adapter:hardware_adapter.py:154 Cannot open connection: [Errno 2] could not open port /dev/serial/by-id/usb-ZEPHYR_RAK5010_Zephyr_A79B173FF273CE6E-if00: [Errno 2] No such file or directory: '/dev/serial/by-id/usb-ZEPHYR_RAK5010_Zephyr_A79B173FF273CE6E-if00'
Traceback (most recent call last):
  File "/root/venv/lib/python3.13/site-packages/serial/serialposix.py", line 322, in open
    self.fd = os.open(self.portstr, os.O_RDWR | os.O_NOCTTY | os.O_NONBLOCK)
              ~~~~~~~^^^^^^^^^^^^^^^^^^^^^^^^^^^^^^^^^^^^^^^^^^^^^^^^^^^^^^^
FileNotFoundError: [Errno 2] No such file or directory: '/dev/serial/by-id/usb-ZEPHYR_RAK5010_Zephyr_A79B173FF273CE6E-if00'

During handling of the above exception, another exception occurred:

Traceback (most recent call last):
  File "/__w/golioth-firmware-sdk/golioth-firmware-sdk/zephyr/scripts/pylib/pytest-twister-harness/src/twister_harness/device/hardware_adapter.py", line 145, in _connect_device
    self._serial_connection = serial.Serial(
                              ~~~~~~~~~~~~~^
        serial_name,
        ^^^^^^^^^^^^
    ...<4 lines>...
        timeout=self.base_timeout,
        ^^^^^^^^^^^^^^^^^^^^^^^^^^
    )
    ^
  File "/root/venv/lib/python3.13/site-packages/serial/serialutil.py", line 244, in __init__
    self.open()
    ~~~~~~~~~^^
  File "/root/venv/lib/python3.13/site-packages/serial/serialposix.py", line 325, in open
    raise SerialException(msg.errno, "could not open port {}: {}".format(self._port, msg))
serial.serialutil.SerialException: [Errno 2] could not open port /dev/serial/by-id/usb-ZEPHYR_RAK5010_Zephyr_A79B173FF273CE6E-if00: [Errno 2] No such file or directory: '/dev/serial/by-id/usb-ZEPHYR_RAK5010_Zephyr_A79B173FF273CE6E-if00'
DEBUG    twister_harness.device.hardware_adapter:hardware_adapter.py:143 Opening serial connection for /dev/serial/by-id/usb-ZEPHYR_RAK5010_Zephyr_A79B173FF273CE6E-if00
ERROR    twister_harness.device.hardware_adapter:hardware_adapter.py:154 Cannot open connection: [Errno 2] could not open port /dev/serial/by-id/usb-ZEPHYR_RAK5010_Zephyr_A79B173FF273CE6E-if00: [Errno 2] No such file or directory: '/dev/serial/by-id/usb-ZEPHYR_RAK5010_Zephyr_A79B173FF273CE6E-if00'
Traceback (most recent call last):
  File "/root/venv/lib/python3.13/site-packages/serial/serialposix.py", line 322, in open
    self.fd = os.open(self.portstr, os.O_RDWR | os.O_NOCTTY | os.O_NONBLOCK)
              ~~~~~~~^^^^^^^^^^^^^^^^^^^^^^^^^^^^^^^^^^^^^^^^^^^^^^^^^^^^^^^
FileNotFoundError: [Errno 2] No such file or directory: '/dev/serial/by-id/usb-ZEPHYR_RAK5010_Zephyr_A79B173FF273CE6E-if00'

During handling of the above exception, another exception occurred:

Traceback (most recent call last):
  File "/__w/golioth-firmware-sdk/golioth-firmware-sdk/zephyr/scripts/pylib/pytest-twister-harness/src/twister_harness/device/hardware_adapter.py", line 145, in _connect_device
    self._serial_connection = serial.Serial(
                              ~~~~~~~~~~~~~^
        serial_name,
        ^^^^^^^^^^^^
    ...<4 lines>...
        timeout=self.base_timeout,
        ^^^^^^^^^^^^^^^^^^^^^^^^^^
    )
    ^
  File "/root/venv/lib/python3.13/site-packages/serial/serialutil.py", line 244, in __init__
    self.open()
    ~~~~~~~~~^^
  File "/root/venv/lib/python3.13/site-packages/serial/serialposix.py", line 325, in open
    raise SerialException(msg.errno, "could not open port {}: {}".format(self._port, msg))
serial.serialutil.SerialException: [Errno 2] could not open port /dev/serial/by-id/usb-ZEPHYR_RAK5010_Zephyr_A79B173FF273CE6E-if00: [Errno 2] No such file or directory: '/dev/serial/by-id/usb-ZEPHYR_RAK5010_Zephyr_A79B173FF273CE6E-if00'
DEBUG    twister_harness.device.hardware_adapter:hardware_adapter.py:143 Opening serial connection for /dev/serial/by-id/usb-ZEPHYR_RAK5010_Zephyr_A79B173FF273CE6E-if00
ERROR    twister_harness.device.hardware_adapter:hardware_adapter.py:154 Cannot open connection: [Errno 2] could not open port /dev/serial/by-id/usb-ZEPHYR_RAK5010_Zephyr_A79B173FF273CE6E-if00: [Errno 2] No such file or directory: '/dev/serial/by-id/usb-ZEPHYR_RAK5010_Zephyr_A79B173FF273CE6E-if00'
Traceback (most recent call last):
  File "/root/venv/lib/python3.13/site-packages/serial/serialposix.py", line 322, in open
    self.fd = os.open(self.portstr, os.O_RDWR | os.O_NOCTTY | os.O_NONBLOCK)
              ~~~~~~~^^^^^^^^^^^^^^^^^^^^^^^^^^^^^^^^^^^^^^^^^^^^^^^^^^^^^^^
FileNotFoundError: [Errno 2] No such file or directory: '/dev/serial/by-id/usb-ZEPHYR_RAK5010_Zephyr_A79B173FF273CE6E-if00'

During handling of the above exception, another exception occurred:

Traceback (most recent call last):
  File "/__w/golioth-firmware-sdk/golioth-firmware-sdk/zephyr/scripts/pylib/pytest-twister-harness/src/twister_harness/device/hardware_adapter.py", line 145, in _connect_device
    self._serial_connection = serial.Serial(
                              ~~~~~~~~~~~~~^
        serial_name,
        ^^^^^^^^^^^^
    ...<4 lines>...
        timeout=self.base_timeout,
        ^^^^^^^^^^^^^^^^^^^^^^^^^^
    )
    ^
  File "/root/venv/lib/python3.13/site-packages/serial/serialutil.py", line 244, in __init__
    self.open()
    ~~~~~~~~~^^
  File "/root/venv/lib/python3.13/site-packages/serial/serialposix.py", line 325, in open
    raise SerialException(msg.errno, "could not open port {}: {}".format(self._port, msg))
serial.serialutil.SerialException: [Errno 2] could not open port /dev/serial/by-id/usb-ZEPHYR_RAK5010_Zephyr_A79B173FF273CE6E-if00: [Errno 2] No such file or directory: '/dev/serial/by-id/usb-ZEPHYR_RAK5010_Zephyr_A79B173FF273CE6E-if00'
DEBUG    twister_harness.device.hardware_adapter:hardware_adapter.py:143 Opening serial connection for /dev/serial/by-id/usb-ZEPHYR_RAK5010_Zephyr_A79B173FF273CE6E-if00
DEBUG    twister_harness.helpers.utils:utils.py:22 Found matching key: CONFIG_SHELL_PROMPT_UART="uart:~$ "
INFO     twister_harness.fixtures:fixtures.py:78 Wait for prompt
DEBUG    twister_harness.helpers.shell:shell.py:49 Got prompt
DEBUG    httpcore.connection:_trace.py:87 connect_tcp.started host='api.golioth.io' port=443 local_address=None timeout=5.0 socket_options=None
DEBUG    httpcore.connection:_trace.py:87 connect_tcp.complete return_value=<httpcore._backends.trio.TrioStream object at 0xffff839c2470>
DEBUG    httpcore.connection:_trace.py:87 start_tls.started ssl_context=<ssl.SSLContext object at 0xffff83b62c30> server_hostname='api.golioth.io' timeout=5.0
DEBUG    httpcore.connection:_trace.py:87 start_tls.complete return_value=<httpcore._backends.trio.TrioStream object at 0xffff839c2580>
DEBUG    httpcore.http11:_trace.py:87 send_request_headers.started request=<Request [b'DELETE']>
DEBUG    httpcore.http11:_trace.py:87 send_request_headers.complete
DEBUG    httpcore.http11:_trace.py:87 send_request_body.started request=<Request [b'DELETE']>
DEBUG    httpcore.http11:_trace.py:87 send_request_body.complete
DEBUG    httpcore.http11:_trace.py:87 receive_response_headers.started request=<Request [b'DELETE']>
DEBUG    httpcore.http11:_trace.py:87 receive_response_headers.complete return_value=(b'HTTP/1.1', 200, b'OK', [(b'content-type', b'application/json'), (b'content-length', b'2'), (b'grpc-metadata-content-type', b'application/grpc'), (b'date', b'Tue, 21 Oct 2025 15:41:42 GMT'), (b'x-kong-upstream-latency', b'40'), (b'x-kong-proxy-latency', b'1'), (b'via', b'kong/2.5.2, 1.1 google')])
INFO     httpx:_client.py:1740 HTTP Request: DELETE https://api.golioth.io/v1/projects/firmware_ci/devices/68f7a990424cece3ad3e3274/data/counter "HTTP/1.1 200 OK"
DEBUG    httpcore.http11:_trace.py:87 receive_response_body.started request=<Request [b'DELETE']>
DEBUG    httpcore.http11:_trace.py:87 receive_response_body.complete
DEBUG    httpcore.http11:_trace.py:87 response_closed.started
DEBUG    httpcore.http11:_trace.py:87 response_closed.complete
DEBUG    httpcore.connection:_trace.py:87 close.started
DEBUG    httpcore.connection:_trace.py:87 close.complete
DEBUG    httpcore.connection:_trace.py:87 connect_tcp.started host='api.golioth.io' port=443 local_address=None timeout=5.0 socket_options=None
DEBUG    httpcore.connection:_trace.py:87 connect_tcp.complete return_value=<httpcore._backends.trio.TrioStream object at 0xffff83b76550>
DEBUG    httpcore.connection:_trace.py:87 start_tls.started ssl_context=<ssl.SSLContext object at 0xffff83b630b0> server_hostname='api.golioth.io' timeout=5.0
DEBUG    httpcore.connection:_trace.py:87 start_tls.complete return_value=<httpcore._backends.trio.TrioStream object at 0xffff83b76650>
DEBUG    httpcore.http11:_trace.py:87 send_request_headers.started request=<Request [b'GET']>
DEBUG    httpcore.http11:_trace.py:87 send_request_headers.complete
DEBUG    httpcore.http11:_trace.py:87 send_request_body.started request=<Request [b'GET']>
DEBUG    httpcore.http11:_trace.py:87 send_request_body.complete
DEBUG    httpcore.http11:_trace.py:87 receive_response_headers.started request=<Request [b'GET']>
DEBUG    httpcore.http11:_trace.py:87 receive_response_headers.complete return_value=(b'HTTP/1.1', 200, b'OK', [(b'content-type', b'application/json'), (b'content-length', b'203'), (b'access-control-expose-headers', b'Content-Range'), (b'content-range', b'credentials 0-1/1'), (b'grpc-metadata-access-control-expose-headers', b'Content-Range'), (b'grpc-metadata-content-type', b'application/grpc'), (b'date', b'Tue, 21 Oct 2025 15:41:45 GMT'), (b'x-kong-upstream-latency', b'13'), (b'x-kong-proxy-latency', b'1'), (b'via', b'kong/2.5.2, 1.1 google')])
INFO     httpx:_client.py:1740 HTTP Request: GET https://api.golioth.io/v1/projects/firmware_ci/devices/68f7a990424cece3ad3e3274/credentials "HTTP/1.1 200 OK"
DEBUG    httpcore.http11:_trace.py:87 receive_response_body.started request=<Request [b'GET']>
DEBUG    httpcore.http11:_trace.py:87 receive_response_body.complete
DEBUG    httpcore.http11:_trace.py:87 response_closed.started
DEBUG    httpcore.http11:_trace.py:87 response_closed.complete
DEBUG    httpcore.connection:_trace.py:87 close.started
DEBUG    httpcore.connection:_trace.py:87 close.complete
DEBUG    twister_harness.device.device_adapter:device_adapter.py:150 #: [1;32muart:~$ [msettings set golioth/psk-id generated-MazGwqhVGvvwgUqW@firmware_ci
DEBUG    twister_harness.device.device_adapter:device_adapter.py:150 #: Setting golioth/psk-id to generated-MazGwqhVGvvwgUqW@firmware_ci
DEBUG    twister_harness.device.device_adapter:device_adapter.py:150 #: Setting golioth/psk-id saved as generated-MazGwqhVGvvwgUqW@firmware_ci
DEBUG    twister_harness.device.device_adapter:device_adapter.py:150 #: [1;32muart:~$ [m
DEBUG    twister_harness.device.device_adapter:device_adapter.py:150 #: [1;32muart:~$ [msettings set golioth/psk generated-MazGwqhVGvvwgUqW
DEBUG    twister_harness.device.device_adapter:device_adapter.py:150 #: Setting golioth/psk to generated-MazGwqhVGvvwgUqW
DEBUG    twister_harness.device.device_adapter:device_adapter.py:150 #: Setting golioth/psk saved as generated-MazGwqhVGvvwgUqW
DEBUG    twister_harness.device.device_adapter:device_adapter.py:150 #: [1;32muart:~$ [m
DEBUG    twister_harness.device.device_adapter:device_adapter.py:150 #: [1;32muart:~$ [mwifi cred add -k 1 -s "***MIKES_ORANGE_PI_WIFI_SSID***" -p "***MIKES_ORANGE_PI_WIFI_PSK***"
DEBUG    twister_harness.device.device_adapter:device_adapter.py:150 #: [1;31mwifi: command not found
DEBUG    twister_harness.device.device_adapter:device_adapter.py:150 #: [m[1;32muart:~$ [m
DEBUG    twister_harness.device.device_adapter:device_adapter.py:150 #: [1;32muart:~$ [mwifi cred auto_connect
DEBUG    twister_harness.device.device_adapter:device_adapter.py:150 #: [1;31mwifi: command not found
DEBUG    twister_harness.device.device_adapter:device_adapter.py:150 #: [m[1;32muart:~$ [m
DEBUG    twister_harness.device.device_adapter:device_adapter.py:150 #: [1;32muart:~$ [m[8D[J[00:00:00.424,713] [0m<inf> golioth_samples: Bringing up network interface[0m
DEBUG    twister_harness.device.device_adapter:device_adapter.py:150 #: [1;32muart:~$ [m[8D[J[00:00:00.424,865] [0m<inf> golioth_samples: Waiting to obtain IP address[0m
DEBUG    twister_harness.device.device_adapter:device_adapter.py:150 #: [1;32muart:~$ [m[8D[J[00:00:21.918,060] [1;33m<wrn> modem_chat: quectel_bg95_init_chat_script: timed out[0m
DEBUG    twister_harness.device.device_adapter:device_adapter.py:150 #: [1;32muart:~$ [m[8D[J[1;32muart:~$ [m[8D[J[00:00:36.656,677] [0m<inf> golioth_mbox: Mbox created, bufsize: 1320, num_items: 10, item_size: 120[0m
DEBUG    twister_harness.device.device_adapter:device_adapter.py:150 #: [1;32muart:~$ [m[8D[J[1;32muart:~$ [m[8D[J[00:00:38.084,197] [0m<inf> golioth_coap_client_zephyr: Golioth CoAP client connected[0m
DEBUG    twister_harness.device.device_adapter:device_adapter.py:150 #: [1;32muart:~$ [m[8D[J[00:00:38.084,320] [0m<inf> lightdb_observe: Golioth client connected[0m
DEBUG    twister_harness.device.device_adapter:device_adapter.py:150 #: [1;32muart:~$ [m[8D[J[00:00:38.084,747] [0m<inf> golioth_coap_client_zephyr: Entering CoAP I/O loop[0m
DEBUG    twister_harness.device.device_adapter:device_adapter.py:150 #: [1;32muart:~$ [m[8D[J[1;32muart:~$ [m[8D[J[00:00:39.317,871] [0m<inf> lightdb_observe: Counter (async)
DEBUG    twister_harness.device.device_adapter:device_adapter.py:150 #:                                           6e 75 6c 6c                                      |null             [0m
DEBUG    httpcore.connection:_trace.py:87 connect_tcp.started host='api.golioth.io' port=443 local_address=None timeout=5.0 socket_options=None
DEBUG    httpcore.connection:_trace.py:87 connect_tcp.complete return_value=<httpcore._backends.trio.TrioStream object at 0xffff83b2f110>
DEBUG    httpcore.connection:_trace.py:87 start_tls.started ssl_context=<ssl.SSLContext object at 0xffff83b63380> server_hostname='api.golioth.io' timeout=5.0
DEBUG    httpcore.connection:_trace.py:87 start_tls.complete return_value=<httpcore._backends.trio.TrioStream object at 0xffff83b2f200>
DEBUG    httpcore.http11:_trace.py:87 send_request_headers.started request=<Request [b'POST']>
DEBUG    httpcore.http11:_trace.py:87 send_request_headers.complete
DEBUG    httpcore.http11:_trace.py:87 send_request_body.started request=<Request [b'POST']>
DEBUG    httpcore.http11:_trace.py:87 send_request_body.complete
DEBUG    httpcore.http11:_trace.py:87 receive_response_headers.started request=<Request [b'POST']>
DEBUG    httpcore.http11:_trace.py:87 receive_response_headers.complete return_value=(b'HTTP/1.1', 200, b'OK', [(b'content-type', b'application/json'), (b'content-length', b'11'), (b'grpc-metadata-content-type', b'application/grpc'), (b'date', b'Tue, 21 Oct 2025 15:42:21 GMT'), (b'x-kong-upstream-latency', b'13'), (b'x-kong-proxy-latency', b'0'), (b'via', b'kong/2.5.2, 1.1 google')])
INFO     httpx:_client.py:1740 HTTP Request: POST https://api.golioth.io/v1/projects/firmware_ci/devices/68f7a990424cece3ad3e3274/data/counter "HTTP/1.1 200 OK"
DEBUG    httpcore.http11:_trace.py:87 receive_response_body.started request=<Request [b'POST']>
DEBUG    httpcore.http11:_trace.py:87 receive_response_body.complete
DEBUG    httpcore.http11:_trace.py:87 response_closed.started
DEBUG    httpcore.http11:_trace.py:87 response_closed.complete
DEBUG    httpcore.connection:_trace.py:87 close.started
DEBUG    httpcore.connection:_trace.py:87 close.complete
DEBUG    twister_harness.device.device_adapter:device_adapter.py:150 #: [1;32muart:~$ [m[8D[J[1;32muart:~$ [m[8D[J[00:00:40.996,795] [0m<inf> lightdb_observe: Counter (async)
DEBUG    twister_harness.device.device_adapter:device_adapter.py:150 #:                                           38 37                                            |87               [0m
DEBUG    twister_harness.device.hardware_adapter:hardware_adapter.py:190 Closed serial connection for /dev/serial/by-id/usb-ZEPHYR_RAK5010_Zephyr_A79B173FF273CE6E-if00
DEBUG    httpcore.connection:_trace.py:87 connect_tcp.started host='api.golioth.io' port=443 local_address=None timeout=5.0 socket_options=None
DEBUG    httpcore.connection:_trace.py:87 connect_tcp.complete return_value=<httpcore._backends.trio.TrioStream object at 0xffff8399b230>
DEBUG    httpcore.connection:_trace.py:87 start_tls.started ssl_context=<ssl.SSLContext object at 0xffff83b63650> server_hostname='api.golioth.io' timeout=5.0
DEBUG    httpcore.connection:_trace.py:87 start_tls.complete return_value=<httpcore._backends.trio.TrioStream object at 0xffff8399b690>
DEBUG    httpcore.http11:_trace.py:87 send_request_headers.started request=<Request [b'DELETE']>
DEBUG    httpcore.http11:_trace.py:87 send_request_headers.complete
DEBUG    httpcore.http11:_trace.py:87 send_request_body.started request=<Request [b'DELETE']>
DEBUG    httpcore.http11:_trace.py:87 send_request_body.complete
DEBUG    httpcore.http11:_trace.py:87 receive_response_headers.started request=<Request [b'DELETE']>
DEBUG    httpcore.http11:_trace.py:87 receive_response_headers.complete return_value=(b'HTTP/1.1', 200, b'OK', [(b'content-type', b'application/json'), (b'content-length', b'2'), (b'grpc-metadata-content-type', b'application/grpc'), (b'date', b'Tue, 21 Oct 2025 15:42:23 GMT'), (b'x-kong-upstream-latency', b'19'), (b'x-kong-proxy-latency', b'1'), (b'via', b'kong/2.5.2, 1.1 google')])
INFO     httpx:_client.py:1740 HTTP Request: DELETE https://api.golioth.io/v1/projects/firmware_ci/devices/68f7a990424cece3ad3e3274 "HTTP/1.1 200 OK"
DEBUG    httpcore.http11:_trace.py:87 receive_response_body.started request=<Request [b'DELETE']>
DEBUG    httpcore.http11:_trace.py:87 receive_response_body.complete
DEBUG    httpcore.http11:_trace.py:87 response_closed.started
DEBUG    httpcore.http11:_trace.py:87 response_closed.complete
DEBUG    httpcore.connection:_trace.py:87 close.started
DEBUG    httpcore.connection:_trace.py:87 close.complete