DEBUG    twister_harness.device.factory:factory.py:37 Get device type "hardware"
DEBUG    httpx:_config.py:82 load_ssl_context verify=True cert=None trust_env=True http2=False
DEBUG    httpx:_config.py:148 load_verify_locations cafile='/usr/local/lib/python3.11/dist-packages/certifi/cacert.pem'
DEBUG    httpcore.connection:_trace.py:85 connect_tcp.started host='api.golioth.io' port=443 local_address=None timeout=5.0 socket_options=None
DEBUG    httpcore.connection:_trace.py:85 connect_tcp.complete return_value=<httpcore._backends.trio.TrioStream object at 0xffffb2370110>
DEBUG    httpcore.connection:_trace.py:85 start_tls.started ssl_context=<ssl.SSLContext object at 0xffffb2463e30> server_hostname='api.golioth.io' timeout=5.0
DEBUG    httpcore.connection:_trace.py:85 start_tls.complete return_value=<httpcore._backends.trio.TrioStream object at 0xffffb21cf050>
DEBUG    httpcore.http11:_trace.py:85 send_request_headers.started request=<Request [b'GET']>
DEBUG    httpcore.http11:_trace.py:85 send_request_headers.complete
DEBUG    httpcore.http11:_trace.py:85 send_request_body.started request=<Request [b'GET']>
DEBUG    httpcore.http11:_trace.py:85 send_request_body.complete
DEBUG    httpcore.http11:_trace.py:85 receive_response_headers.started request=<Request [b'GET']>
DEBUG    httpcore.http11:_trace.py:85 receive_response_headers.complete return_value=(b'HTTP/1.1', 200, b'OK', [(b'Access-Control-Expose-Headers', b'Content-Range'), (b'Content-Length', b'193'), (b'Content-Range', b'projects 0-1/1'), (b'Content-Type', b'application/json'), (b'Date', b'Fri, 04 Oct 2024 07:30:27 GMT'), (b'Grpc-Metadata-Access-Control-Expose-Headers', b'Content-Range'), (b'Grpc-Metadata-Content-Type', b'application/grpc'), (b'Via', b'kong/2.5.2'), (b'X-Kong-Proxy-Latency', b'0'), (b'X-Kong-Upstream-Latency', b'15')])
INFO     httpx:_client.py:1786 HTTP Request: GET https://api.golioth.io/v1/projects "HTTP/1.1 200 OK"
DEBUG    httpcore.http11:_trace.py:85 receive_response_body.started request=<Request [b'GET']>
DEBUG    httpcore.http11:_trace.py:85 receive_response_body.complete
DEBUG    httpcore.http11:_trace.py:85 response_closed.started
DEBUG    httpcore.http11:_trace.py:85 response_closed.complete
DEBUG    httpcore.connection:_trace.py:85 close.started
DEBUG    httpcore.connection:_trace.py:85 close.complete
DEBUG    httpx:_config.py:82 load_ssl_context verify=True cert=None trust_env=True http2=False
DEBUG    httpx:_config.py:148 load_verify_locations cafile='/usr/local/lib/python3.11/dist-packages/certifi/cacert.pem'
DEBUG    httpcore.connection:_trace.py:85 connect_tcp.started host='api.golioth.io' port=443 local_address=None timeout=5.0 socket_options=None
DEBUG    httpcore.connection:_trace.py:85 connect_tcp.complete return_value=<httpcore._backends.trio.TrioStream object at 0xffffb2370110>
DEBUG    httpcore.connection:_trace.py:85 start_tls.started ssl_context=<ssl.SSLContext object at 0xffffb236d130> server_hostname='api.golioth.io' timeout=5.0
DEBUG    httpcore.connection:_trace.py:85 start_tls.complete return_value=<httpcore._backends.trio.TrioStream object at 0xffffb41032d0>
DEBUG    httpcore.http11:_trace.py:85 send_request_headers.started request=<Request [b'POST']>
DEBUG    httpcore.http11:_trace.py:85 send_request_headers.complete
DEBUG    httpcore.http11:_trace.py:85 send_request_body.started request=<Request [b'POST']>
DEBUG    httpcore.http11:_trace.py:85 send_request_body.complete
DEBUG    httpcore.http11:_trace.py:85 receive_response_headers.started request=<Request [b'POST']>
DEBUG    httpcore.http11:_trace.py:85 receive_response_headers.complete return_value=(b'HTTP/1.1', 200, b'OK', [(b'Content-Length', b'849'), (b'Content-Type', b'application/json'), (b'Date', b'Fri, 04 Oct 2024 07:30:28 GMT'), (b'Grpc-Metadata-Content-Type', b'application/grpc'), (b'Via', b'kong/2.5.2'), (b'X-Kong-Proxy-Latency', b'1'), (b'X-Kong-Upstream-Latency', b'16')])
INFO     httpx:_client.py:1786 HTTP Request: POST https://api.golioth.io/v1/projects/firmware_ci/certificates "HTTP/1.1 200 OK"
DEBUG    httpcore.http11:_trace.py:85 receive_response_body.started request=<Request [b'POST']>
DEBUG    httpcore.http11:_trace.py:85 receive_response_body.complete
DEBUG    httpcore.http11:_trace.py:85 response_closed.started
DEBUG    httpcore.http11:_trace.py:85 response_closed.complete
DEBUG    httpcore.connection:_trace.py:85 close.started
DEBUG    httpcore.connection:_trace.py:85 close.complete
DEBUG    twister_harness.device.hardware_adapter:utils.py:37 Flashing command: /usr/local/bin/west flash --skip-rebuild --build-dir /__w/golioth-firmware-sdk/golioth-firmware-sdk/twister-out/rak5010_nrf52840/certificate_provisioning/sample.golioth.certificate_provisioning --runner blackmagicprobe -- --gdb=/usr/bin/gdb
DEBUG    twister_harness.device.hardware_adapter:hardware_adapter.py:131 Flashing finished
DEBUG    twister_harness.device.hardware_adapter:hardware_adapter.py:139 Opening serial connection for /dev/serial/by-id/usb-ZEPHYR_RAK5010_Zephyr_A79B173FF273CE6E-if00
ERROR    twister_harness.device.hardware_adapter:hardware_adapter.py:150 Cannot open connection: [Errno 2] could not open port /dev/serial/by-id/usb-ZEPHYR_RAK5010_Zephyr_A79B173FF273CE6E-if00: [Errno 2] No such file or directory: '/dev/serial/by-id/usb-ZEPHYR_RAK5010_Zephyr_A79B173FF273CE6E-if00'
Traceback (most recent call last):
  File "/usr/local/lib/python3.11/dist-packages/serial/serialposix.py", line 322, in open
    self.fd = os.open(self.portstr, os.O_RDWR | os.O_NOCTTY | os.O_NONBLOCK)
              ^^^^^^^^^^^^^^^^^^^^^^^^^^^^^^^^^^^^^^^^^^^^^^^^^^^^^^^^^^^^^^
FileNotFoundError: [Errno 2] No such file or directory: '/dev/serial/by-id/usb-ZEPHYR_RAK5010_Zephyr_A79B173FF273CE6E-if00'

During handling of the above exception, another exception occurred:

Traceback (most recent call last):
  File "/__w/golioth-firmware-sdk/golioth-firmware-sdk/zephyr/scripts/pylib/pytest-twister-harness/src/twister_harness/device/hardware_adapter.py", line 141, in _connect_device
    self._serial_connection = serial.Serial(
                              ^^^^^^^^^^^^^^
  File "/usr/local/lib/python3.11/dist-packages/serial/serialutil.py", line 244, in __init__
    self.open()
  File "/usr/local/lib/python3.11/dist-packages/serial/serialposix.py", line 325, in open
    raise SerialException(msg.errno, "could not open port {}: {}".format(self._port, msg))
serial.serialutil.SerialException: [Errno 2] could not open port /dev/serial/by-id/usb-ZEPHYR_RAK5010_Zephyr_A79B173FF273CE6E-if00: [Errno 2] No such file or directory: '/dev/serial/by-id/usb-ZEPHYR_RAK5010_Zephyr_A79B173FF273CE6E-if00'
DEBUG    twister_harness.device.hardware_adapter:hardware_adapter.py:139 Opening serial connection for /dev/serial/by-id/usb-ZEPHYR_RAK5010_Zephyr_A79B173FF273CE6E-if00
ERROR    twister_harness.device.hardware_adapter:hardware_adapter.py:150 Cannot open connection: [Errno 2] could not open port /dev/serial/by-id/usb-ZEPHYR_RAK5010_Zephyr_A79B173FF273CE6E-if00: [Errno 2] No such file or directory: '/dev/serial/by-id/usb-ZEPHYR_RAK5010_Zephyr_A79B173FF273CE6E-if00'
Traceback (most recent call last):
  File "/usr/local/lib/python3.11/dist-packages/serial/serialposix.py", line 322, in open
    self.fd = os.open(self.portstr, os.O_RDWR | os.O_NOCTTY | os.O_NONBLOCK)
              ^^^^^^^^^^^^^^^^^^^^^^^^^^^^^^^^^^^^^^^^^^^^^^^^^^^^^^^^^^^^^^
FileNotFoundError: [Errno 2] No such file or directory: '/dev/serial/by-id/usb-ZEPHYR_RAK5010_Zephyr_A79B173FF273CE6E-if00'

During handling of the above exception, another exception occurred:

Traceback (most recent call last):
  File "/__w/golioth-firmware-sdk/golioth-firmware-sdk/zephyr/scripts/pylib/pytest-twister-harness/src/twister_harness/device/hardware_adapter.py", line 141, in _connect_device
    self._serial_connection = serial.Serial(
                              ^^^^^^^^^^^^^^
  File "/usr/local/lib/python3.11/dist-packages/serial/serialutil.py", line 244, in __init__
    self.open()
  File "/usr/local/lib/python3.11/dist-packages/serial/serialposix.py", line 325, in open
    raise SerialException(msg.errno, "could not open port {}: {}".format(self._port, msg))
serial.serialutil.SerialException: [Errno 2] could not open port /dev/serial/by-id/usb-ZEPHYR_RAK5010_Zephyr_A79B173FF273CE6E-if00: [Errno 2] No such file or directory: '/dev/serial/by-id/usb-ZEPHYR_RAK5010_Zephyr_A79B173FF273CE6E-if00'
DEBUG    twister_harness.device.hardware_adapter:hardware_adapter.py:139 Opening serial connection for /dev/serial/by-id/usb-ZEPHYR_RAK5010_Zephyr_A79B173FF273CE6E-if00
ERROR    twister_harness.device.hardware_adapter:hardware_adapter.py:150 Cannot open connection: [Errno 2] could not open port /dev/serial/by-id/usb-ZEPHYR_RAK5010_Zephyr_A79B173FF273CE6E-if00: [Errno 2] No such file or directory: '/dev/serial/by-id/usb-ZEPHYR_RAK5010_Zephyr_A79B173FF273CE6E-if00'
Traceback (most recent call last):
  File "/usr/local/lib/python3.11/dist-packages/serial/serialposix.py", line 322, in open
    self.fd = os.open(self.portstr, os.O_RDWR | os.O_NOCTTY | os.O_NONBLOCK)
              ^^^^^^^^^^^^^^^^^^^^^^^^^^^^^^^^^^^^^^^^^^^^^^^^^^^^^^^^^^^^^^
FileNotFoundError: [Errno 2] No such file or directory: '/dev/serial/by-id/usb-ZEPHYR_RAK5010_Zephyr_A79B173FF273CE6E-if00'

During handling of the above exception, another exception occurred:

Traceback (most recent call last):
  File "/__w/golioth-firmware-sdk/golioth-firmware-sdk/zephyr/scripts/pylib/pytest-twister-harness/src/twister_harness/device/hardware_adapter.py", line 141, in _connect_device
    self._serial_connection = serial.Serial(
                              ^^^^^^^^^^^^^^
  File "/usr/local/lib/python3.11/dist-packages/serial/serialutil.py", line 244, in __init__
    self.open()
  File "/usr/local/lib/python3.11/dist-packages/serial/serialposix.py", line 325, in open
    raise SerialException(msg.errno, "could not open port {}: {}".format(self._port, msg))
serial.serialutil.SerialException: [Errno 2] could not open port /dev/serial/by-id/usb-ZEPHYR_RAK5010_Zephyr_A79B173FF273CE6E-if00: [Errno 2] No such file or directory: '/dev/serial/by-id/usb-ZEPHYR_RAK5010_Zephyr_A79B173FF273CE6E-if00'
DEBUG    twister_harness.device.hardware_adapter:hardware_adapter.py:139 Opening serial connection for /dev/serial/by-id/usb-ZEPHYR_RAK5010_Zephyr_A79B173FF273CE6E-if00
ERROR    twister_harness.device.hardware_adapter:hardware_adapter.py:150 Cannot open connection: [Errno 2] could not open port /dev/serial/by-id/usb-ZEPHYR_RAK5010_Zephyr_A79B173FF273CE6E-if00: [Errno 2] No such file or directory: '/dev/serial/by-id/usb-ZEPHYR_RAK5010_Zephyr_A79B173FF273CE6E-if00'
Traceback (most recent call last):
  File "/usr/local/lib/python3.11/dist-packages/serial/serialposix.py", line 322, in open
    self.fd = os.open(self.portstr, os.O_RDWR | os.O_NOCTTY | os.O_NONBLOCK)
              ^^^^^^^^^^^^^^^^^^^^^^^^^^^^^^^^^^^^^^^^^^^^^^^^^^^^^^^^^^^^^^
FileNotFoundError: [Errno 2] No such file or directory: '/dev/serial/by-id/usb-ZEPHYR_RAK5010_Zephyr_A79B173FF273CE6E-if00'

During handling of the above exception, another exception occurred:

Traceback (most recent call last):
  File "/__w/golioth-firmware-sdk/golioth-firmware-sdk/zephyr/scripts/pylib/pytest-twister-harness/src/twister_harness/device/hardware_adapter.py", line 141, in _connect_device
    self._serial_connection = serial.Serial(
                              ^^^^^^^^^^^^^^
  File "/usr/local/lib/python3.11/dist-packages/serial/serialutil.py", line 244, in __init__
    self.open()
  File "/usr/local/lib/python3.11/dist-packages/serial/serialposix.py", line 325, in open
    raise SerialException(msg.errno, "could not open port {}: {}".format(self._port, msg))
serial.serialutil.SerialException: [Errno 2] could not open port /dev/serial/by-id/usb-ZEPHYR_RAK5010_Zephyr_A79B173FF273CE6E-if00: [Errno 2] No such file or directory: '/dev/serial/by-id/usb-ZEPHYR_RAK5010_Zephyr_A79B173FF273CE6E-if00'
DEBUG    twister_harness.device.hardware_adapter:hardware_adapter.py:139 Opening serial connection for /dev/serial/by-id/usb-ZEPHYR_RAK5010_Zephyr_A79B173FF273CE6E-if00
ERROR    twister_harness.device.hardware_adapter:hardware_adapter.py:150 Cannot open connection: [Errno 2] could not open port /dev/serial/by-id/usb-ZEPHYR_RAK5010_Zephyr_A79B173FF273CE6E-if00: [Errno 2] No such file or directory: '/dev/serial/by-id/usb-ZEPHYR_RAK5010_Zephyr_A79B173FF273CE6E-if00'
Traceback (most recent call last):
  File "/usr/local/lib/python3.11/dist-packages/serial/serialposix.py", line 322, in open
    self.fd = os.open(self.portstr, os.O_RDWR | os.O_NOCTTY | os.O_NONBLOCK)
              ^^^^^^^^^^^^^^^^^^^^^^^^^^^^^^^^^^^^^^^^^^^^^^^^^^^^^^^^^^^^^^
FileNotFoundError: [Errno 2] No such file or directory: '/dev/serial/by-id/usb-ZEPHYR_RAK5010_Zephyr_A79B173FF273CE6E-if00'

During handling of the above exception, another exception occurred:

Traceback (most recent call last):
  File "/__w/golioth-firmware-sdk/golioth-firmware-sdk/zephyr/scripts/pylib/pytest-twister-harness/src/twister_harness/device/hardware_adapter.py", line 141, in _connect_device
    self._serial_connection = serial.Serial(
                              ^^^^^^^^^^^^^^
  File "/usr/local/lib/python3.11/dist-packages/serial/serialutil.py", line 244, in __init__
    self.open()
  File "/usr/local/lib/python3.11/dist-packages/serial/serialposix.py", line 325, in open
    raise SerialException(msg.errno, "could not open port {}: {}".format(self._port, msg))
serial.serialutil.SerialException: [Errno 2] could not open port /dev/serial/by-id/usb-ZEPHYR_RAK5010_Zephyr_A79B173FF273CE6E-if00: [Errno 2] No such file or directory: '/dev/serial/by-id/usb-ZEPHYR_RAK5010_Zephyr_A79B173FF273CE6E-if00'
DEBUG    twister_harness.device.hardware_adapter:hardware_adapter.py:139 Opening serial connection for /dev/serial/by-id/usb-ZEPHYR_RAK5010_Zephyr_A79B173FF273CE6E-if00
ERROR    twister_harness.device.hardware_adapter:hardware_adapter.py:150 Cannot open connection: [Errno 2] could not open port /dev/serial/by-id/usb-ZEPHYR_RAK5010_Zephyr_A79B173FF273CE6E-if00: [Errno 2] No such file or directory: '/dev/serial/by-id/usb-ZEPHYR_RAK5010_Zephyr_A79B173FF273CE6E-if00'
Traceback (most recent call last):
  File "/usr/local/lib/python3.11/dist-packages/serial/serialposix.py", line 322, in open
    self.fd = os.open(self.portstr, os.O_RDWR | os.O_NOCTTY | os.O_NONBLOCK)
              ^^^^^^^^^^^^^^^^^^^^^^^^^^^^^^^^^^^^^^^^^^^^^^^^^^^^^^^^^^^^^^
FileNotFoundError: [Errno 2] No such file or directory: '/dev/serial/by-id/usb-ZEPHYR_RAK5010_Zephyr_A79B173FF273CE6E-if00'

During handling of the above exception, another exception occurred:

Traceback (most recent call last):
  File "/__w/golioth-firmware-sdk/golioth-firmware-sdk/zephyr/scripts/pylib/pytest-twister-harness/src/twister_harness/device/hardware_adapter.py", line 141, in _connect_device
    self._serial_connection = serial.Serial(
                              ^^^^^^^^^^^^^^
  File "/usr/local/lib/python3.11/dist-packages/serial/serialutil.py", line 244, in __init__
    self.open()
  File "/usr/local/lib/python3.11/dist-packages/serial/serialposix.py", line 325, in open
    raise SerialException(msg.errno, "could not open port {}: {}".format(self._port, msg))
serial.serialutil.SerialException: [Errno 2] could not open port /dev/serial/by-id/usb-ZEPHYR_RAK5010_Zephyr_A79B173FF273CE6E-if00: [Errno 2] No such file or directory: '/dev/serial/by-id/usb-ZEPHYR_RAK5010_Zephyr_A79B173FF273CE6E-if00'
DEBUG    twister_harness.device.hardware_adapter:hardware_adapter.py:139 Opening serial connection for /dev/serial/by-id/usb-ZEPHYR_RAK5010_Zephyr_A79B173FF273CE6E-if00
ERROR    twister_harness.device.hardware_adapter:hardware_adapter.py:150 Cannot open connection: [Errno 2] could not open port /dev/serial/by-id/usb-ZEPHYR_RAK5010_Zephyr_A79B173FF273CE6E-if00: [Errno 2] No such file or directory: '/dev/serial/by-id/usb-ZEPHYR_RAK5010_Zephyr_A79B173FF273CE6E-if00'
Traceback (most recent call last):
  File "/usr/local/lib/python3.11/dist-packages/serial/serialposix.py", line 322, in open
    self.fd = os.open(self.portstr, os.O_RDWR | os.O_NOCTTY | os.O_NONBLOCK)
              ^^^^^^^^^^^^^^^^^^^^^^^^^^^^^^^^^^^^^^^^^^^^^^^^^^^^^^^^^^^^^^
FileNotFoundError: [Errno 2] No such file or directory: '/dev/serial/by-id/usb-ZEPHYR_RAK5010_Zephyr_A79B173FF273CE6E-if00'

During handling of the above exception, another exception occurred:

Traceback (most recent call last):
  File "/__w/golioth-firmware-sdk/golioth-firmware-sdk/zephyr/scripts/pylib/pytest-twister-harness/src/twister_harness/device/hardware_adapter.py", line 141, in _connect_device
    self._serial_connection = serial.Serial(
                              ^^^^^^^^^^^^^^
  File "/usr/local/lib/python3.11/dist-packages/serial/serialutil.py", line 244, in __init__
    self.open()
  File "/usr/local/lib/python3.11/dist-packages/serial/serialposix.py", line 325, in open
    raise SerialException(msg.errno, "could not open port {}: {}".format(self._port, msg))
serial.serialutil.SerialException: [Errno 2] could not open port /dev/serial/by-id/usb-ZEPHYR_RAK5010_Zephyr_A79B173FF273CE6E-if00: [Errno 2] No such file or directory: '/dev/serial/by-id/usb-ZEPHYR_RAK5010_Zephyr_A79B173FF273CE6E-if00'
DEBUG    twister_harness.device.hardware_adapter:hardware_adapter.py:139 Opening serial connection for /dev/serial/by-id/usb-ZEPHYR_RAK5010_Zephyr_A79B173FF273CE6E-if00
INFO     twister_harness.fixtures:fixtures.py:61 Wait for prompt
DEBUG    twister_harness.helpers.shell:shell.py:47 Got prompt
DEBUG    httpx:_config.py:82 load_ssl_context verify=True cert=None trust_env=True http2=False
DEBUG    httpx:_config.py:148 load_verify_locations cafile='/usr/local/lib/python3.11/dist-packages/certifi/cacert.pem'
DEBUG    httpcore.connection:_trace.py:85 connect_tcp.started host='api.golioth.io' port=443 local_address=None timeout=5.0 socket_options=None
DEBUG    httpcore.connection:_trace.py:85 connect_tcp.complete return_value=<httpcore._backends.trio.TrioStream object at 0xffffb234f810>
DEBUG    httpcore.connection:_trace.py:85 start_tls.started ssl_context=<ssl.SSLContext object at 0xffffb2d25ac0> server_hostname='api.golioth.io' timeout=5.0
DEBUG    httpcore.connection:_trace.py:85 start_tls.complete return_value=<httpcore._backends.trio.TrioStream object at 0xffffb222f810>
DEBUG    httpcore.http11:_trace.py:85 send_request_headers.started request=<Request [b'GET']>
DEBUG    httpcore.http11:_trace.py:85 send_request_headers.complete
DEBUG    httpcore.http11:_trace.py:85 send_request_body.started request=<Request [b'GET']>
DEBUG    httpcore.http11:_trace.py:85 send_request_body.complete
DEBUG    httpcore.http11:_trace.py:85 receive_response_headers.started request=<Request [b'GET']>
DEBUG    httpcore.http11:_trace.py:85 receive_response_headers.complete return_value=(b'HTTP/1.1', 200, b'OK', [(b'Access-Control-Expose-Headers', b'Content-Range'), (b'Content-Length', b'47'), (b'Content-Range', b'devices 0-0/0'), (b'Content-Type', b'application/json'), (b'Date', b'Fri, 04 Oct 2024 07:31:10 GMT'), (b'Grpc-Metadata-Access-Control-Expose-Headers', b'Content-Range'), (b'Grpc-Metadata-Content-Type', b'application/grpc'), (b'Via', b'kong/2.5.2'), (b'X-Kong-Proxy-Latency', b'0'), (b'X-Kong-Upstream-Latency', b'23')])
INFO     httpx:_client.py:1786 HTTP Request: GET https://api.golioth.io/v1/projects/firmware_ci/devices?deviceName=certificate-cuIpEFuPjexPJHep "HTTP/1.1 200 OK"
DEBUG    httpcore.http11:_trace.py:85 receive_response_body.started request=<Request [b'GET']>
DEBUG    httpcore.http11:_trace.py:85 receive_response_body.complete
DEBUG    httpcore.http11:_trace.py:85 response_closed.started
DEBUG    httpcore.http11:_trace.py:85 response_closed.complete
DEBUG    httpcore.connection:_trace.py:85 close.started
DEBUG    httpcore.connection:_trace.py:85 close.complete
DEBUG    twister_harness.device.device_adapter:device_adapter.py:148 #: [1;32muart:~$ [msettings set wifi/ssid "***MIKES_ORANGE_PI_WIFI_SSID***"
DEBUG    twister_harness.device.device_adapter:device_adapter.py:148 #: Setting wifi/ssid to ***MIKES_ORANGE_PI_WIFI_SSID***
DEBUG    twister_harness.device.device_adapter:device_adapter.py:148 #: [1;31mFailed to set runtime setting: wifi/ssid:***MIKES_ORANGE_PI_WIFI_SSID***
DEBUG    twister_harness.device.device_adapter:device_adapter.py:148 #: [m[1;32muart:~$ [m
DEBUG    twister_harness.device.device_adapter:device_adapter.py:148 #: [1;32muart:~$ [msettings set wifi/psk "***MIKES_ORANGE_PI_WIFI_PSK***"
DEBUG    twister_harness.device.device_adapter:device_adapter.py:148 #: Setting wifi/psk to ***MIKES_ORANGE_PI_WIFI_PSK***
DEBUG    twister_harness.device.device_adapter:device_adapter.py:148 #: [1;31mFailed to set runtime setting: wifi/psk:***MIKES_ORANGE_PI_WIFI_PSK***
DEBUG    twister_harness.device.device_adapter:device_adapter.py:148 #: [m[1;32muart:~$ [m
DEBUG    twister_harness.device.device_adapter:device_adapter.py:148 #: [1;32muart:~$ [m[8D[J[00:00:00.430,877] [0m<inf> littlefs: LittleFS version 2.8, disk version 2.1[0m
DEBUG    twister_harness.device.device_adapter:device_adapter.py:148 #: [1;32muart:~$ [m[8D[J[00:00:00.431,091] [0m<inf> littlefs: FS at flash-controller@4001e000:0xf8000 is 8 0x1000-byte blocks with 512 cycle[0m
DEBUG    twister_harness.device.device_adapter:device_adapter.py:148 #: [1;32muart:~$ [m[8D[J[00:00:00.431,091] [0m<inf> littlefs: sizes: rd 16 ; pr 16 ; ca 64 ; la 32[0m
DEBUG    twister_harness.device.device_adapter:device_adapter.py:148 #: [1;32muart:~$ [m[8D[J[00:00:00.431,213] [1;31m<err> littlefs: WEST_TOPDIR/modules/fs/littlefs/lfs.c:1351: Corrupted dir pair at {0x1, 0x0}[0m
DEBUG    twister_harness.device.device_adapter:device_adapter.py:148 #: [1;32muart:~$ [m[8D[J[00:00:00.431,213] [1;33m<wrn> littlefs: can't mount (LFS -84); formatting[0m
DEBUG    twister_harness.device.device_adapter:device_adapter.py:148 #: [1;32muart:~$ [m[8D[J[00:00:00.601,684] [0m<inf> littlefs: /lfs1 mounted[0m
DEBUG    twister_harness.device.device_adapter:device_adapter.py:148 #: [1;32muart:~$ [m[8D[J[00:00:00.601,715] [0m<inf> littlefs: Automount /lfs1 succeeded[0m
DEBUG    twister_harness.device.device_adapter:device_adapter.py:148 #: [1;32muart:~$ [m[8D[J*** Booting Zephyr OS build 36940db938a8 ***
DEBUG    twister_harness.device.device_adapter:device_adapter.py:148 #: [1;32muart:~$ [m[8D[J[00:00:00.601,928] [0m<inf> golioth_settings_autoload: Initializing settings subsystem[0m
DEBUG    twister_harness.device.device_adapter:device_adapter.py:148 #: [1;32muart:~$ [m[8D[J[00:00:00.601,989] [0m<inf> golioth_settings_autoload: Loading settings[0m
DEBUG    twister_harness.device.device_adapter:device_adapter.py:148 #: [1;32muart:~$ [m[8D[J[00:00:00.602,172] [1;31m<err> fs: file open error (-2)[0m
DEBUG    twister_harness.device.device_adapter:device_adapter.py:148 #: [1;32muart:~$ [m[8D[J[00:00:00.602,630] [0m<dbg> cert_provisioning: main: Start certificate provisioning sample[0m
DEBUG    twister_harness.device.device_adapter:device_adapter.py:148 #: [1;32muart:~$ [m[8D[J[00:00:00.602,630] [0m<inf> golioth_samples: Bringing up network interface[0m
DEBUG    twister_harness.device.device_adapter:device_adapter.py:148 #: [1;32muart:~$ [m[8D[J[00:00:00.602,691] [0m<inf> golioth_samples: Waiting to obtain IP address[0m
DEBUG    twister_harness.device.device_adapter:device_adapter.py:148 #: [1;32muart:~$ [m[8D[J[00:00:21.931,121] [1;33m<wrn> modem_chat: quectel_bg95_init_chat_script: timed out[0m
DEBUG    twister_harness.device.device_adapter:device_adapter.py:148 #: [1;32muart:~$ [m[8D[J[1;32muart:~$ [m[8D[J[00:00:36.614,257] [1;33m<wrn> cert_provisioning: Could not stat /lfs1/credentials/client_cert.der, err: -2[0m
DEBUG    twister_harness.device.device_adapter:device_adapter.py:148 #: [1;32muart:~$ [m[8D[J[1;32muart:~$ [mfs mkdir /lfs1/credentials
DEBUG    twister_harness.device.device_adapter:device_adapter.py:148 #: [1;32muart:~$ [m
DEBUG    twister_harness.device.device_adapter:device_adapter.py:148 #: [1;32muart:~$ [mlog halt
DEBUG    twister_harness.device.device_adapter:device_adapter.py:148 #: [1;32muart:~$ [m
INFO     test_sample:test_sample.py:23 mcumgr crt stdout: 302
365
Done

INFO     test_sample:test_sample.py:23 mcumgr key stdout: 121
Done

DEBUG    twister_harness.device.device_adapter:device_adapter.py:148 #: [1;32muart:~$ [mlog go
DEBUG    twister_harness.device.device_adapter:device_adapter.py:148 #: [1;32muart:~$ [m
DEBUG    twister_harness.device.device_adapter:device_adapter.py:148 #: [1;32muart:~$ [m[8D[J[00:00:41.616,149] [0m<inf> cert_provisioning: Read 365 bytes from /lfs1/credentials/client_cert.der[0m
DEBUG    twister_harness.device.device_adapter:device_adapter.py:148 #: [1;32muart:~$ [m[8D[J[00:00:41.617,767] [0m<inf> cert_provisioning: Read 121 bytes from /lfs1/credentials/private_key.der[0m
DEBUG    twister_harness.device.device_adapter:device_adapter.py:148 #: [1;32muart:~$ [m[8D[J[00:00:41.618,316] [0m<inf> golioth_mbox: Mbox created, bufsize: 1320, num_items: 10, item_size: 120[0m
DEBUG    twister_harness.device.device_adapter:device_adapter.py:148 #: [1;32muart:~$ [m[8D[J[1;32muart:~$ [m[8D[J[00:00:44.155,181] [1;31m<err> net_pkt: Data buffer (127) allocation failed.[0m
DEBUG    twister_harness.device.device_adapter:device_adapter.py:148 #: [1;32muart:~$ [m[8D[J[00:00:44.155,181] [1;33m<wrn> modem_ppp: Failed to alloc buffer[0m
DEBUG    twister_harness.device.device_adapter:device_adapter.py:148 #: [1;32muart:~$ [m[8D[J[00:00:45.594,177] [1;31m<err> net_pkt: Data buffer (127) allocation failed.[0m
DEBUG    twister_harness.device.device_adapter:device_adapter.py:148 #: [1;32muart:~$ [m[8D[J[00:00:45.594,177] [1;33m<wrn> modem_ppp: Failed to alloc buffer[0m
DEBUG    twister_harness.device.device_adapter:device_adapter.py:148 #: [1;32muart:~$ [m[8D[J[00:00:45.736,175] [1;31m<err> net_pkt: Data buffer (127) allocation failed.[0m
DEBUG    twister_harness.device.device_adapter:device_adapter.py:148 #: [1;32muart:~$ [m[8D[J[1;31m--- 1 messages dropped ---
DEBUG    twister_harness.device.device_adapter:device_adapter.py:148 #: [m[00:00:45.736,175] [1;33m<wrn> modem_ppp: Failed to alloc buffer[0m
DEBUG    twister_harness.device.device_adapter:device_adapter.py:148 #: [1;32muart:~$ [m[8D[J[00:00:45.945,648] [1;33m<wrn> modem_ppp: Dropped frame, no net_pkt available[0m
DEBUG    twister_harness.device.device_adapter:device_adapter.py:148 #: [1;32muart:~$ [m[8D[J[00:00:46.106,689] [1;33m<wrn> modem_ppp: Dropped frame, no net_pkt available[0m
DEBUG    twister_harness.device.device_adapter:device_adapter.py:148 #: [1;32muart:~$ [m[8D[J[00:00:46.841,430] [1;33m<wrn> modem_ppp: Dropped frame, no net_pkt available[0m
DEBUG    twister_harness.device.device_adapter:device_adapter.py:148 #: [1;32muart:~$ [m[8D[J[00:00:46.970,733] [1;33m<wrn> modem_ppp: Dropped frame, no net_pkt available[0m
DEBUG    twister_harness.device.device_adapter:device_adapter.py:148 #: [1;32muart:~$ [m[8D[J[00:00:47.131,713] [1;33m<wrn> modem_ppp: Dropped frame, no net_pkt available[0m
DEBUG    twister_harness.device.device_adapter:device_adapter.py:148 #: [1;32muart:~$ [m[8D[J[00:00:49.237,518] [1;33m<wrn> modem_ppp: Dropped frame, no net_pkt available[0m
DEBUG    twister_harness.device.device_adapter:device_adapter.py:148 #: [1;32muart:~$ [m[8D[J[00:00:49.370,697] [1;33m<wrn> modem_ppp: Dropped frame, no net_pkt available[0m
DEBUG    twister_harness.device.device_adapter:device_adapter.py:148 #: [1;32muart:~$ [m[8D[J[00:00:49.531,738] [1;33m<wrn> modem_ppp: Dropped frame, no net_pkt available[0m
DEBUG    twister_harness.device.device_adapter:device_adapter.py:148 #: [1;32muart:~$ [m[8D[J[00:00:49.652,893] [1;33m<wrn> modem_ppp: Dropped frame, no net_pkt available[0m
DEBUG    twister_harness.device.device_adapter:device_adapter.py:148 #: [1;32muart:~$ [m[8D[J[00:00:49.672,790] [1;33m<wrn> modem_ppp: Dropped frame, no net_pkt available[0m
DEBUG    twister_harness.device.device_adapter:device_adapter.py:148 #: [1;32muart:~$ [m[8D[J[00:00:49.843,566] [1;33m<wrn> modem_ppp: Dropped frame, no net_pkt available[0m
DEBUG    twister_harness.device.device_adapter:device_adapter.py:148 #: [1;32muart:~$ [m[8D[J[00:00:49.945,678] [1;33m<wrn> modem_ppp: Dropped frame, no net_pkt available[0m
DEBUG    twister_harness.device.device_adapter:device_adapter.py:148 #: [1;32muart:~$ [m[8D[J[00:00:50.106,750] [1;33m<wrn> modem_ppp: Dropped frame, no net_pkt available[0m
DEBUG    twister_harness.device.device_adapter:device_adapter.py:148 #: [1;32muart:~$ [m[8D[J[00:00:50.935,729] [1;33m<wrn> modem_ppp: Dropped frame, no net_pkt available[0m
DEBUG    twister_harness.device.device_adapter:device_adapter.py:148 #: [1;32muart:~$ [m[8D[J[00:00:51.077,178] [1;33m<wrn> modem_ppp: Dropped frame, no net_pkt available[0m
DEBUG    twister_harness.device.device_adapter:device_adapter.py:148 #: [1;32muart:~$ [m[8D[J[00:00:53.077,728] [1;33m<wrn> modem_ppp: Dropped frame, no net_pkt available[0m
DEBUG    twister_harness.device.device_adapter:device_adapter.py:148 #: [1;32muart:~$ [m[8D[J[00:00:53.210,906] [1;33m<wrn> modem_ppp: Dropped frame, no net_pkt available[0m
DEBUG    twister_harness.device.device_adapter:device_adapter.py:148 #: [1;32muart:~$ [m[8D[J[00:00:53.371,948] [1;33m<wrn> modem_ppp: Dropped frame, no net_pkt available[0m
DEBUG    twister_harness.device.device_adapter:device_adapter.py:148 #: [1;32muart:~$ [m[8D[J[00:00:53.493,103] [1;33m<wrn> modem_ppp: Dropped frame, no net_pkt available[0m
DEBUG    twister_harness.device.device_adapter:device_adapter.py:148 #: [1;32muart:~$ [m[8D[J[00:00:53.513,000] [1;33m<wrn> modem_ppp: Dropped frame, no net_pkt available[0m
DEBUG    twister_harness.device.device_adapter:device_adapter.py:148 #: [1;32muart:~$ [m[8D[J[00:00:53.953,887] [1;33m<wrn> modem_ppp: Dropped frame, no net_pkt available[0m
DEBUG    twister_harness.device.device_adapter:device_adapter.py:148 #: [1;32muart:~$ [m[8D[J[00:00:54.114,959] [1;33m<wrn> modem_ppp: Dropped frame, no net_pkt available[0m
DEBUG    twister_harness.device.device_adapter:device_adapter.py:148 #: [1;32muart:~$ [m[8D[J[00:00:54.115,417] [1;33m<wrn> modem_ppp: Dropped frame, no net_pkt available[0m
DEBUG    twister_harness.device.device_adapter:device_adapter.py:148 #: [1;32muart:~$ [m[8D[J[00:00:54.844,818] [1;33m<wrn> modem_ppp: Dropped frame, no net_pkt available[0m
DEBUG    twister_harness.device.device_adapter:device_adapter.py:148 #: [1;32muart:~$ [m[8D[J[00:00:54.940,887] [1;33m<wrn> modem_ppp: Dropped frame, no net_pkt available[0m
DEBUG    twister_harness.device.device_adapter:device_adapter.py:148 #: [1;32muart:~$ [m[8D[J[00:00:55.101,928] [1;33m<wrn> modem_ppp: Dropped frame, no net_pkt available[0m
DEBUG    twister_harness.device.device_adapter:device_adapter.py:148 #: [1;32muart:~$ [m[8D[J[00:00:56.917,663] [1;33m<wrn> modem_ppp: Dropped frame, no net_pkt available[0m
DEBUG    twister_harness.device.device_adapter:device_adapter.py:148 #: [1;32muart:~$ [m[8D[J[00:00:57.050,842] [1;33m<wrn> modem_ppp: Dropped frame, no net_pkt available[0m
DEBUG    twister_harness.device.device_adapter:device_adapter.py:148 #: [1;32muart:~$ [m[8D[J[00:00:57.211,914] [1;33m<wrn> modem_ppp: Dropped frame, no net_pkt available[0m
DEBUG    twister_harness.device.device_adapter:device_adapter.py:148 #: [1;32muart:~$ [m[8D[J[00:00:57.333,038] [1;33m<wrn> modem_ppp: Dropped frame, no net_pkt available[0m
DEBUG    twister_harness.device.device_adapter:device_adapter.py:148 #: [1;32muart:~$ [m[8D[J[00:00:57.352,935] [1;33m<wrn> modem_ppp: Dropped frame, no net_pkt available[0m
DEBUG    twister_harness.device.device_adapter:device_adapter.py:148 #: [1;32muart:~$ [m[8D[J[00:00:57.850,677] [1;33m<wrn> modem_ppp: Dropped frame, no net_pkt available[0m
DEBUG    twister_harness.device.device_adapter:device_adapter.py:148 #: [1;32muart:~$ [m[8D[J[00:00:57.932,952] [1;33m<wrn> modem_ppp: Dropped frame, no net_pkt available[0m
DEBUG    twister_harness.device.device_adapter:device_adapter.py:148 #: [1;32muart:~$ [m[8D[J[00:00:58.093,933] [1;33m<wrn> modem_ppp: Dropped frame, no net_pkt available[0m
DEBUG    twister_harness.device.device_adapter:device_adapter.py:148 #: [1;32muart:~$ [m[8D[J[00:00:58.848,663] [1;33m<wrn> modem_ppp: Dropped frame, no net_pkt available[0m
DEBUG    twister_harness.device.device_adapter:device_adapter.py:148 #: [1;32muart:~$ [m[8D[J[00:00:58.940,887] [1;33m<wrn> modem_ppp: Dropped frame, no net_pkt available[0m
DEBUG    twister_harness.device.device_adapter:device_adapter.py:148 #: [1;32muart:~$ [m[8D[J[00:00:59.101,959] [1;33m<wrn> modem_ppp: Dropped frame, no net_pkt available[0m
DEBUG    twister_harness.device.device_adapter:device_adapter.py:148 #: [1;32muart:~$ [m[8D[J[00:01:00.757,751] [1;33m<wrn> modem_ppp: Dropped frame, no net_pkt available[0m
DEBUG    twister_harness.device.device_adapter:device_adapter.py:148 #: [1;32muart:~$ [m[8D[J[00:01:00.890,930] [1;33m<wrn> modem_ppp: Dropped frame, no net_pkt available[0m
DEBUG    twister_harness.device.device_adapter:device_adapter.py:148 #: [1;32muart:~$ [m[8D[J[00:01:01.051,971] [1;33m<wrn> modem_ppp: Dropped frame, no net_pkt available[0m
DEBUG    twister_harness.device.device_adapter:device_adapter.py:148 #: [1;32muart:~$ [m[8D[J[00:01:01.173,126] [1;33m<wrn> modem_ppp: Dropped frame, no net_pkt available[0m
DEBUG    twister_harness.device.device_adapter:device_adapter.py:148 #: [1;32muart:~$ [m[8D[J[00:01:01.193,023] [1;33m<wrn> modem_ppp: Dropped frame, no net_pkt available[0m
DEBUG    twister_harness.device.device_adapter:device_adapter.py:148 #: [1;32muart:~$ [m[8D[J[00:01:01.354,064] [1;33m<wrn> modem_ppp: Dropped frame, no net_pkt available[0m
DEBUG    twister_harness.device.device_adapter:device_adapter.py:148 #: [1;32muart:~$ [m[8D[J[00:01:01.850,860] [1;33m<wrn> modem_ppp: Dropped frame, no net_pkt available[0m
DEBUG    twister_harness.device.device_adapter:device_adapter.py:148 #: [1;32muart:~$ [m[8D[J[00:01:01.965,057] [1;33m<wrn> modem_ppp: Dropped frame, no net_pkt available[0m
DEBUG    twister_harness.device.device_adapter:device_adapter.py:148 #: [1;32muart:~$ [m[8D[J[00:01:02.126,098] [1;33m<wrn> modem_ppp: Dropped frame, no net_pkt available[0m
DEBUG    twister_harness.device.device_adapter:device_adapter.py:148 #: [1;32muart:~$ [m[8D[J[00:01:02.850,738] [1;33m<wrn> modem_ppp: Dropped frame, no net_pkt available[0m
DEBUG    twister_harness.device.device_adapter:device_adapter.py:148 #: [1;32muart:~$ [m[8D[J[00:01:02.970,947] [1;33m<wrn> modem_ppp: Dropped frame, no net_pkt available[0m
DEBUG    twister_harness.device.device_adapter:device_adapter.py:148 #: [1;32muart:~$ [m[8D[J[00:01:03.132,019] [1;33m<wrn> modem_ppp: Dropped frame, no net_pkt available[0m
DEBUG    twister_harness.device.device_adapter:device_adapter.py:148 #: [1;32muart:~$ [m[8D[J[1;32muart:~$ [m[8D[J[1;32muart:~$ [m[8D[J[00:01:04.686,706] [0m<inf> golioth_coap_client_zephyr: Golioth CoAP client connected[0m
DEBUG    twister_harness.device.device_adapter:device_adapter.py:148 #: [1;32muart:~$ [m[8D[J[00:01:04.686,920] [0m<inf> cert_provisioning: Sending hello! 0[0m
DEBUG    twister_harness.device.device_adapter:device_adapter.py:148 #: [1;32muart:~$ [m[8D[J[00:01:04.686,981] [0m<inf> cert_provisioning: Golioth client connected[0m
DEBUG    twister_harness.device.device_adapter:device_adapter.py:148 #: [1;32muart:~$ [m[8D[J[00:01:04.686,981] [0m<inf> golioth_coap_client_zephyr: Entering CoAP I/O loop[0m
DEBUG    twister_harness.device.device_adapter:device_adapter.py:148 #: [1;32muart:~$ [m[8D[J[1;32muart:~$ [m[8D[J[00:01:09.687,011] [0m<inf> cert_provisioning: Sending hello! 1[0m
DEBUG    twister_harness.device.device_adapter:device_adapter.py:148 #: [1;32muart:~$ [m[8D[J[1;32muart:~$ [m[8D[J[00:01:14.687,072] [0m<inf> cert_provisioning: Sending hello! 2[0m
DEBUG    httpx:_config.py:82 load_ssl_context verify=True cert=None trust_env=True http2=False
DEBUG    httpx:_config.py:148 load_verify_locations cafile='/usr/local/lib/python3.11/dist-packages/certifi/cacert.pem'
DEBUG    httpcore.connection:_trace.py:85 connect_tcp.started host='api.golioth.io' port=443 local_address=None timeout=5.0 socket_options=None
DEBUG    httpcore.connection:_trace.py:85 connect_tcp.complete return_value=<httpcore._backends.trio.TrioStream object at 0xffffb22398d0>
DEBUG    httpcore.connection:_trace.py:85 start_tls.started ssl_context=<ssl.SSLContext object at 0xffffb236d250> server_hostname='api.golioth.io' timeout=5.0
DEBUG    httpcore.connection:_trace.py:85 start_tls.complete return_value=<httpcore._backends.trio.TrioStream object at 0xffffb2247bd0>
DEBUG    httpcore.http11:_trace.py:85 send_request_headers.started request=<Request [b'GET']>
DEBUG    httpcore.http11:_trace.py:85 send_request_headers.complete
DEBUG    httpcore.http11:_trace.py:85 send_request_body.started request=<Request [b'GET']>
DEBUG    httpcore.http11:_trace.py:85 send_request_body.complete
DEBUG    httpcore.http11:_trace.py:85 receive_response_headers.started request=<Request [b'GET']>
DEBUG    httpcore.http11:_trace.py:85 receive_response_headers.complete return_value=(b'HTTP/1.1', 200, b'OK', [(b'Access-Control-Expose-Headers', b'Content-Range'), (b'Content-Length', b'584'), (b'Content-Range', b'devices 0-1/1'), (b'Content-Type', b'application/json'), (b'Date', b'Fri, 04 Oct 2024 07:32:24 GMT'), (b'Grpc-Metadata-Access-Control-Expose-Headers', b'Content-Range'), (b'Grpc-Metadata-Content-Type', b'application/grpc'), (b'Via', b'kong/2.5.2'), (b'X-Kong-Proxy-Latency', b'0'), (b'X-Kong-Upstream-Latency', b'50')])
INFO     httpx:_client.py:1786 HTTP Request: GET https://api.golioth.io/v1/projects/firmware_ci/devices?deviceName=certificate-cuIpEFuPjexPJHep "HTTP/1.1 200 OK"
DEBUG    httpcore.http11:_trace.py:85 receive_response_body.started request=<Request [b'GET']>
DEBUG    httpcore.http11:_trace.py:85 receive_response_body.complete
DEBUG    httpcore.http11:_trace.py:85 response_closed.started
DEBUG    httpcore.http11:_trace.py:85 response_closed.complete
DEBUG    httpcore.connection:_trace.py:85 close.started
DEBUG    httpcore.connection:_trace.py:85 close.complete
DEBUG    twister_harness.device.hardware_adapter:hardware_adapter.py:186 Closed serial connection for /dev/serial/by-id/usb-ZEPHYR_RAK5010_Zephyr_A79B173FF273CE6E-if00
DEBUG    httpx:_config.py:82 load_ssl_context verify=True cert=None trust_env=True http2=False
DEBUG    httpx:_config.py:148 load_verify_locations cafile='/usr/local/lib/python3.11/dist-packages/certifi/cacert.pem'
DEBUG    httpcore.connection:_trace.py:85 connect_tcp.started host='api.golioth.io' port=443 local_address=None timeout=5.0 socket_options=None
DEBUG    httpcore.connection:_trace.py:85 connect_tcp.complete return_value=<httpcore._backends.trio.TrioStream object at 0xffffb2244550>
DEBUG    httpcore.connection:_trace.py:85 start_tls.started ssl_context=<ssl.SSLContext object at 0xffffb236d400> server_hostname='api.golioth.io' timeout=5.0
DEBUG    httpcore.connection:_trace.py:85 start_tls.complete return_value=<httpcore._backends.trio.TrioStream object at 0xffffb225f390>
DEBUG    httpcore.http11:_trace.py:85 send_request_headers.started request=<Request [b'DELETE']>
DEBUG    httpcore.http11:_trace.py:85 send_request_headers.complete
DEBUG    httpcore.http11:_trace.py:85 send_request_body.started request=<Request [b'DELETE']>
DEBUG    httpcore.http11:_trace.py:85 send_request_body.complete
DEBUG    httpcore.http11:_trace.py:85 receive_response_headers.started request=<Request [b'DELETE']>
DEBUG    httpcore.http11:_trace.py:85 receive_response_headers.complete return_value=(b'HTTP/1.1', 200, b'OK', [(b'Content-Length', b'2'), (b'Content-Type', b'application/json'), (b'Date', b'Fri, 04 Oct 2024 07:32:25 GMT'), (b'Grpc-Metadata-Content-Type', b'application/grpc'), (b'Via', b'kong/2.5.2'), (b'X-Kong-Proxy-Latency', b'1'), (b'X-Kong-Upstream-Latency', b'10')])
INFO     httpx:_client.py:1786 HTTP Request: DELETE https://api.golioth.io/v1/projects/firmware_ci/certificates/66ff99941b3c084061ccf285 "HTTP/1.1 200 OK"
DEBUG    httpcore.http11:_trace.py:85 receive_response_body.started request=<Request [b'DELETE']>
DEBUG    httpcore.http11:_trace.py:85 receive_response_body.complete
DEBUG    httpcore.http11:_trace.py:85 response_closed.started
DEBUG    httpcore.http11:_trace.py:85 response_closed.complete
DEBUG    httpcore.connection:_trace.py:85 close.started
DEBUG    httpcore.connection:_trace.py:85 close.complete
DEBUG    httpx:_config.py:82 load_ssl_context verify=True cert=None trust_env=True http2=False
DEBUG    httpx:_config.py:148 load_verify_locations cafile='/usr/local/lib/python3.11/dist-packages/certifi/cacert.pem'
DEBUG    httpcore.connection:_trace.py:85 connect_tcp.started host='api.golioth.io' port=443 local_address=None timeout=5.0 socket_options=None
DEBUG    httpcore.connection:_trace.py:85 connect_tcp.complete return_value=<httpcore._backends.trio.TrioStream object at 0xffffb21e9fd0>
DEBUG    httpcore.connection:_trace.py:85 start_tls.started ssl_context=<ssl.SSLContext object at 0xffffb2462f00> server_hostname='api.golioth.io' timeout=5.0
DEBUG    httpcore.connection:_trace.py:85 start_tls.complete return_value=<httpcore._backends.trio.TrioStream object at 0xffffb21f1c10>
DEBUG    httpcore.http11:_trace.py:85 send_request_headers.started request=<Request [b'GET']>
DEBUG    httpcore.http11:_trace.py:85 send_request_headers.complete
DEBUG    httpcore.http11:_trace.py:85 send_request_body.started request=<Request [b'GET']>
DEBUG    httpcore.http11:_trace.py:85 send_request_body.complete
DEBUG    httpcore.http11:_trace.py:85 receive_response_headers.started request=<Request [b'GET']>
DEBUG    httpcore.http11:_trace.py:85 receive_response_headers.complete return_value=(b'HTTP/1.1', 200, b'OK', [(b'Access-Control-Expose-Headers', b'Content-Range'), (b'Content-Length', b'584'), (b'Content-Range', b'devices 0-1/1'), (b'Content-Type', b'application/json'), (b'Date', b'Fri, 04 Oct 2024 07:32:25 GMT'), (b'Grpc-Metadata-Access-Control-Expose-Headers', b'Content-Range'), (b'Grpc-Metadata-Content-Type', b'application/grpc'), (b'Via', b'kong/2.5.2'), (b'X-Kong-Proxy-Latency', b'0'), (b'X-Kong-Upstream-Latency', b'52')])
INFO     httpx:_client.py:1786 HTTP Request: GET https://api.golioth.io/v1/projects/firmware_ci/devices?deviceName=certificate-cuIpEFuPjexPJHep "HTTP/1.1 200 OK"
DEBUG    httpcore.http11:_trace.py:85 receive_response_body.started request=<Request [b'GET']>
DEBUG    httpcore.http11:_trace.py:85 receive_response_body.complete
DEBUG    httpcore.http11:_trace.py:85 response_closed.started
DEBUG    httpcore.http11:_trace.py:85 response_closed.complete
DEBUG    httpcore.connection:_trace.py:85 close.started
DEBUG    httpcore.connection:_trace.py:85 close.complete
DEBUG    httpx:_config.py:82 load_ssl_context verify=True cert=None trust_env=True http2=False
DEBUG    httpx:_config.py:148 load_verify_locations cafile='/usr/local/lib/python3.11/dist-packages/certifi/cacert.pem'
DEBUG    httpcore.connection:_trace.py:85 connect_tcp.started host='api.golioth.io' port=443 local_address=None timeout=5.0 socket_options=None
DEBUG    httpcore.connection:_trace.py:85 connect_tcp.complete return_value=<httpcore._backends.trio.TrioStream object at 0xffffb2247450>
DEBUG    httpcore.connection:_trace.py:85 start_tls.started ssl_context=<ssl.SSLContext object at 0xffffb236d0a0> server_hostname='api.golioth.io' timeout=5.0
DEBUG    httpcore.connection:_trace.py:85 start_tls.complete return_value=<httpcore._backends.trio.TrioStream object at 0xffffb22479d0>
DEBUG    httpcore.http11:_trace.py:85 send_request_headers.started request=<Request [b'DELETE']>
DEBUG    httpcore.http11:_trace.py:85 send_request_headers.complete
DEBUG    httpcore.http11:_trace.py:85 send_request_body.started request=<Request [b'DELETE']>
DEBUG    httpcore.http11:_trace.py:85 send_request_body.complete
DEBUG    httpcore.http11:_trace.py:85 receive_response_headers.started request=<Request [b'DELETE']>
DEBUG    httpcore.http11:_trace.py:85 receive_response_headers.complete return_value=(b'HTTP/1.1', 200, b'OK', [(b'Content-Length', b'2'), (b'Content-Type', b'application/json'), (b'Date', b'Fri, 04 Oct 2024 07:32:26 GMT'), (b'Grpc-Metadata-Content-Type', b'application/grpc'), (b'Via', b'kong/2.5.2'), (b'X-Kong-Proxy-Latency', b'0'), (b'X-Kong-Upstream-Latency', b'47')])
INFO     httpx:_client.py:1786 HTTP Request: DELETE https://api.golioth.io/v1/projects/firmware_ci/devices/66ff99fc1b3c084061ccf2a2 "HTTP/1.1 200 OK"
DEBUG    httpcore.http11:_trace.py:85 receive_response_body.started request=<Request [b'DELETE']>
DEBUG    httpcore.http11:_trace.py:85 receive_response_body.complete
DEBUG    httpcore.http11:_trace.py:85 response_closed.started
DEBUG    httpcore.http11:_trace.py:85 response_closed.complete
DEBUG    httpcore.connection:_trace.py:85 close.started
DEBUG    httpcore.connection:_trace.py:85 close.complete