DEBUG    twister_harness.device.factory:factory.py:37 Get device type "hardware"
DEBUG    httpx:_config.py:82 load_ssl_context verify=True cert=None trust_env=True http2=False
DEBUG    httpx:_config.py:148 load_verify_locations cafile='/usr/local/lib/python3.11/dist-packages/certifi/cacert.pem'
DEBUG    httpcore.connection:_trace.py:85 connect_tcp.started host='api.golioth.io' port=443 local_address=None timeout=5.0 socket_options=None
DEBUG    httpcore.connection:_trace.py:85 connect_tcp.complete return_value=<httpcore._backends.trio.TrioStream object at 0xffffaf4cfad0>
DEBUG    httpcore.connection:_trace.py:85 start_tls.started ssl_context=<ssl.SSLContext object at 0xffffaf5cfbf0> server_hostname='api.golioth.io' timeout=5.0
DEBUG    httpcore.connection:_trace.py:85 start_tls.complete return_value=<httpcore._backends.trio.TrioStream object at 0xffffaf33b390>
DEBUG    httpcore.http11:_trace.py:85 send_request_headers.started request=<Request [b'GET']>
DEBUG    httpcore.http11:_trace.py:85 send_request_headers.complete
DEBUG    httpcore.http11:_trace.py:85 send_request_body.started request=<Request [b'GET']>
DEBUG    httpcore.http11:_trace.py:85 send_request_body.complete
DEBUG    httpcore.http11:_trace.py:85 receive_response_headers.started request=<Request [b'GET']>
DEBUG    httpcore.http11:_trace.py:85 receive_response_headers.complete return_value=(b'HTTP/1.1', 200, b'OK', [(b'Access-Control-Expose-Headers', b'Content-Range'), (b'Content-Length', b'188'), (b'Content-Range', b'projects 0-1/1'), (b'Content-Type', b'application/json'), (b'Date', b'Wed, 13 Nov 2024 23:28:49 GMT'), (b'Grpc-Metadata-Access-Control-Expose-Headers', b'Content-Range'), (b'Grpc-Metadata-Content-Type', b'application/grpc'), (b'Via', b'kong/2.5.2'), (b'X-Kong-Proxy-Latency', b'0'), (b'X-Kong-Upstream-Latency', b'24')])
INFO     httpx:_client.py:1786 HTTP Request: GET https://api.golioth.io/v1/projects "HTTP/1.1 200 OK"
DEBUG    httpcore.http11:_trace.py:85 receive_response_body.started request=<Request [b'GET']>
DEBUG    httpcore.http11:_trace.py:85 receive_response_body.complete
DEBUG    httpcore.http11:_trace.py:85 response_closed.started
DEBUG    httpcore.http11:_trace.py:85 response_closed.complete
DEBUG    httpcore.connection:_trace.py:85 close.started
DEBUG    httpcore.connection:_trace.py:85 close.complete
DEBUG    httpx:_config.py:82 load_ssl_context verify=True cert=None trust_env=True http2=False
DEBUG    httpx:_config.py:148 load_verify_locations cafile='/usr/local/lib/python3.11/dist-packages/certifi/cacert.pem'
DEBUG    httpcore.connection:_trace.py:85 connect_tcp.started host='api.golioth.io' port=443 local_address=None timeout=5.0 socket_options=None
DEBUG    httpcore.connection:_trace.py:85 connect_tcp.complete return_value=<httpcore._backends.trio.TrioStream object at 0xffffaf4dd790>
DEBUG    httpcore.connection:_trace.py:85 start_tls.started ssl_context=<ssl.SSLContext object at 0xffffaf4c4680> server_hostname='api.golioth.io' timeout=5.0
DEBUG    httpcore.connection:_trace.py:85 start_tls.complete return_value=<httpcore._backends.trio.TrioStream object at 0xffffaf32bf50>
DEBUG    httpcore.http11:_trace.py:85 send_request_headers.started request=<Request [b'POST']>
DEBUG    httpcore.http11:_trace.py:85 send_request_headers.complete
DEBUG    httpcore.http11:_trace.py:85 send_request_body.started request=<Request [b'POST']>
DEBUG    httpcore.http11:_trace.py:85 send_request_body.complete
DEBUG    httpcore.http11:_trace.py:85 receive_response_headers.started request=<Request [b'POST']>
DEBUG    httpcore.http11:_trace.py:85 receive_response_headers.complete return_value=(b'HTTP/1.1', 200, b'OK', [(b'Content-Length', b'287'), (b'Content-Type', b'application/json'), (b'Date', b'Wed, 13 Nov 2024 23:28:50 GMT'), (b'Grpc-Metadata-Content-Type', b'application/grpc'), (b'Via', b'kong/2.5.2'), (b'X-Kong-Proxy-Latency', b'0'), (b'X-Kong-Upstream-Latency', b'191')])
INFO     httpx:_client.py:1786 HTTP Request: POST https://api.golioth.io/v1/projects/firmware_ci/devices "HTTP/1.1 200 OK"
DEBUG    httpcore.http11:_trace.py:85 receive_response_body.started request=<Request [b'POST']>
DEBUG    httpcore.http11:_trace.py:85 receive_response_body.complete
DEBUG    httpcore.http11:_trace.py:85 response_closed.started
DEBUG    httpcore.http11:_trace.py:85 response_closed.complete
DEBUG    httpcore.connection:_trace.py:85 close.started
DEBUG    httpcore.connection:_trace.py:85 close.complete
DEBUG    httpx:_config.py:82 load_ssl_context verify=True cert=None trust_env=True http2=False
DEBUG    httpx:_config.py:148 load_verify_locations cafile='/usr/local/lib/python3.11/dist-packages/certifi/cacert.pem'
DEBUG    httpcore.connection:_trace.py:85 connect_tcp.started host='api.golioth.io' port=443 local_address=None timeout=5.0 socket_options=None
DEBUG    httpcore.connection:_trace.py:85 connect_tcp.complete return_value=<httpcore._backends.trio.TrioStream object at 0xffffaf34ed10>
DEBUG    httpcore.connection:_trace.py:85 start_tls.started ssl_context=<ssl.SSLContext object at 0xffffaf4c4dd0> server_hostname='api.golioth.io' timeout=5.0
DEBUG    httpcore.connection:_trace.py:85 start_tls.complete return_value=<httpcore._backends.trio.TrioStream object at 0xffffaf359650>
DEBUG    httpcore.http11:_trace.py:85 send_request_headers.started request=<Request [b'POST']>
DEBUG    httpcore.http11:_trace.py:85 send_request_headers.complete
DEBUG    httpcore.http11:_trace.py:85 send_request_body.started request=<Request [b'POST']>
DEBUG    httpcore.http11:_trace.py:85 send_request_body.complete
DEBUG    httpcore.http11:_trace.py:85 receive_response_headers.started request=<Request [b'POST']>
DEBUG    httpcore.http11:_trace.py:85 receive_response_headers.complete return_value=(b'HTTP/1.1', 200, b'OK', [(b'Content-Length', b'201'), (b'Content-Type', b'application/json'), (b'Date', b'Wed, 13 Nov 2024 23:28:50 GMT'), (b'Grpc-Metadata-Content-Type', b'application/grpc'), (b'Via', b'kong/2.5.2'), (b'X-Kong-Proxy-Latency', b'1'), (b'X-Kong-Upstream-Latency', b'93')])
INFO     httpx:_client.py:1786 HTTP Request: POST https://api.golioth.io/v1/projects/firmware_ci/devices/673536328590529831ce4d55/credentials "HTTP/1.1 200 OK"
DEBUG    httpcore.http11:_trace.py:85 receive_response_body.started request=<Request [b'POST']>
DEBUG    httpcore.http11:_trace.py:85 receive_response_body.complete
DEBUG    httpcore.http11:_trace.py:85 response_closed.started
DEBUG    httpcore.http11:_trace.py:85 response_closed.complete
DEBUG    httpcore.connection:_trace.py:85 close.started
DEBUG    httpcore.connection:_trace.py:85 close.complete
DEBUG    twister_harness.device.hardware_adapter:utils.py:37 Flashing command: /usr/local/bin/west flash --skip-rebuild --build-dir /__w/golioth-firmware-sdk/golioth-firmware-sdk/twister-out/rak5010_nrf52840/lightdb/delete/sample.golioth.lightdb_delete --runner blackmagicprobe -- --gdb=/usr/bin/gdb
DEBUG    twister_harness.device.hardware_adapter:hardware_adapter.py:131 Flashing finished
DEBUG    twister_harness.device.hardware_adapter:hardware_adapter.py:139 Opening serial connection for /dev/serial/by-id/usb-ZEPHYR_RAK5010_Zephyr_A79B173FF273CE6E-if00
ERROR    twister_harness.device.hardware_adapter:hardware_adapter.py:150 Cannot open connection: [Errno 2] could not open port /dev/serial/by-id/usb-ZEPHYR_RAK5010_Zephyr_A79B173FF273CE6E-if00: [Errno 2] No such file or directory: '/dev/serial/by-id/usb-ZEPHYR_RAK5010_Zephyr_A79B173FF273CE6E-if00'
Traceback (most recent call last):
  File "/usr/local/lib/python3.11/dist-packages/serial/serialposix.py", line 322, in open
    self.fd = os.open(self.portstr, os.O_RDWR | os.O_NOCTTY | os.O_NONBLOCK)
              ^^^^^^^^^^^^^^^^^^^^^^^^^^^^^^^^^^^^^^^^^^^^^^^^^^^^^^^^^^^^^^
FileNotFoundError: [Errno 2] No such file or directory: '/dev/serial/by-id/usb-ZEPHYR_RAK5010_Zephyr_A79B173FF273CE6E-if00'

During handling of the above exception, another exception occurred:

Traceback (most recent call last):
  File "/__w/golioth-firmware-sdk/golioth-firmware-sdk/zephyr/scripts/pylib/pytest-twister-harness/src/twister_harness/device/hardware_adapter.py", line 141, in _connect_device
    self._serial_connection = serial.Serial(
                              ^^^^^^^^^^^^^^
  File "/usr/local/lib/python3.11/dist-packages/serial/serialutil.py", line 244, in __init__
    self.open()
  File "/usr/local/lib/python3.11/dist-packages/serial/serialposix.py", line 325, in open
    raise SerialException(msg.errno, "could not open port {}: {}".format(self._port, msg))
serial.serialutil.SerialException: [Errno 2] could not open port /dev/serial/by-id/usb-ZEPHYR_RAK5010_Zephyr_A79B173FF273CE6E-if00: [Errno 2] No such file or directory: '/dev/serial/by-id/usb-ZEPHYR_RAK5010_Zephyr_A79B173FF273CE6E-if00'
DEBUG    twister_harness.device.hardware_adapter:hardware_adapter.py:139 Opening serial connection for /dev/serial/by-id/usb-ZEPHYR_RAK5010_Zephyr_A79B173FF273CE6E-if00
ERROR    twister_harness.device.hardware_adapter:hardware_adapter.py:150 Cannot open connection: [Errno 2] could not open port /dev/serial/by-id/usb-ZEPHYR_RAK5010_Zephyr_A79B173FF273CE6E-if00: [Errno 2] No such file or directory: '/dev/serial/by-id/usb-ZEPHYR_RAK5010_Zephyr_A79B173FF273CE6E-if00'
Traceback (most recent call last):
  File "/usr/local/lib/python3.11/dist-packages/serial/serialposix.py", line 322, in open
    self.fd = os.open(self.portstr, os.O_RDWR | os.O_NOCTTY | os.O_NONBLOCK)
              ^^^^^^^^^^^^^^^^^^^^^^^^^^^^^^^^^^^^^^^^^^^^^^^^^^^^^^^^^^^^^^
FileNotFoundError: [Errno 2] No such file or directory: '/dev/serial/by-id/usb-ZEPHYR_RAK5010_Zephyr_A79B173FF273CE6E-if00'

During handling of the above exception, another exception occurred:

Traceback (most recent call last):
  File "/__w/golioth-firmware-sdk/golioth-firmware-sdk/zephyr/scripts/pylib/pytest-twister-harness/src/twister_harness/device/hardware_adapter.py", line 141, in _connect_device
    self._serial_connection = serial.Serial(
                              ^^^^^^^^^^^^^^
  File "/usr/local/lib/python3.11/dist-packages/serial/serialutil.py", line 244, in __init__
    self.open()
  File "/usr/local/lib/python3.11/dist-packages/serial/serialposix.py", line 325, in open
    raise SerialException(msg.errno, "could not open port {}: {}".format(self._port, msg))
serial.serialutil.SerialException: [Errno 2] could not open port /dev/serial/by-id/usb-ZEPHYR_RAK5010_Zephyr_A79B173FF273CE6E-if00: [Errno 2] No such file or directory: '/dev/serial/by-id/usb-ZEPHYR_RAK5010_Zephyr_A79B173FF273CE6E-if00'
DEBUG    twister_harness.device.hardware_adapter:hardware_adapter.py:139 Opening serial connection for /dev/serial/by-id/usb-ZEPHYR_RAK5010_Zephyr_A79B173FF273CE6E-if00
ERROR    twister_harness.device.hardware_adapter:hardware_adapter.py:150 Cannot open connection: [Errno 2] could not open port /dev/serial/by-id/usb-ZEPHYR_RAK5010_Zephyr_A79B173FF273CE6E-if00: [Errno 2] No such file or directory: '/dev/serial/by-id/usb-ZEPHYR_RAK5010_Zephyr_A79B173FF273CE6E-if00'
Traceback (most recent call last):
  File "/usr/local/lib/python3.11/dist-packages/serial/serialposix.py", line 322, in open
    self.fd = os.open(self.portstr, os.O_RDWR | os.O_NOCTTY | os.O_NONBLOCK)
              ^^^^^^^^^^^^^^^^^^^^^^^^^^^^^^^^^^^^^^^^^^^^^^^^^^^^^^^^^^^^^^
FileNotFoundError: [Errno 2] No such file or directory: '/dev/serial/by-id/usb-ZEPHYR_RAK5010_Zephyr_A79B173FF273CE6E-if00'

During handling of the above exception, another exception occurred:

Traceback (most recent call last):
  File "/__w/golioth-firmware-sdk/golioth-firmware-sdk/zephyr/scripts/pylib/pytest-twister-harness/src/twister_harness/device/hardware_adapter.py", line 141, in _connect_device
    self._serial_connection = serial.Serial(
                              ^^^^^^^^^^^^^^
  File "/usr/local/lib/python3.11/dist-packages/serial/serialutil.py", line 244, in __init__
    self.open()
  File "/usr/local/lib/python3.11/dist-packages/serial/serialposix.py", line 325, in open
    raise SerialException(msg.errno, "could not open port {}: {}".format(self._port, msg))
serial.serialutil.SerialException: [Errno 2] could not open port /dev/serial/by-id/usb-ZEPHYR_RAK5010_Zephyr_A79B173FF273CE6E-if00: [Errno 2] No such file or directory: '/dev/serial/by-id/usb-ZEPHYR_RAK5010_Zephyr_A79B173FF273CE6E-if00'
DEBUG    twister_harness.device.hardware_adapter:hardware_adapter.py:139 Opening serial connection for /dev/serial/by-id/usb-ZEPHYR_RAK5010_Zephyr_A79B173FF273CE6E-if00
ERROR    twister_harness.device.hardware_adapter:hardware_adapter.py:150 Cannot open connection: [Errno 2] could not open port /dev/serial/by-id/usb-ZEPHYR_RAK5010_Zephyr_A79B173FF273CE6E-if00: [Errno 2] No such file or directory: '/dev/serial/by-id/usb-ZEPHYR_RAK5010_Zephyr_A79B173FF273CE6E-if00'
Traceback (most recent call last):
  File "/usr/local/lib/python3.11/dist-packages/serial/serialposix.py", line 322, in open
    self.fd = os.open(self.portstr, os.O_RDWR | os.O_NOCTTY | os.O_NONBLOCK)
              ^^^^^^^^^^^^^^^^^^^^^^^^^^^^^^^^^^^^^^^^^^^^^^^^^^^^^^^^^^^^^^
FileNotFoundError: [Errno 2] No such file or directory: '/dev/serial/by-id/usb-ZEPHYR_RAK5010_Zephyr_A79B173FF273CE6E-if00'

During handling of the above exception, another exception occurred:

Traceback (most recent call last):
  File "/__w/golioth-firmware-sdk/golioth-firmware-sdk/zephyr/scripts/pylib/pytest-twister-harness/src/twister_harness/device/hardware_adapter.py", line 141, in _connect_device
    self._serial_connection = serial.Serial(
                              ^^^^^^^^^^^^^^
  File "/usr/local/lib/python3.11/dist-packages/serial/serialutil.py", line 244, in __init__
    self.open()
  File "/usr/local/lib/python3.11/dist-packages/serial/serialposix.py", line 325, in open
    raise SerialException(msg.errno, "could not open port {}: {}".format(self._port, msg))
serial.serialutil.SerialException: [Errno 2] could not open port /dev/serial/by-id/usb-ZEPHYR_RAK5010_Zephyr_A79B173FF273CE6E-if00: [Errno 2] No such file or directory: '/dev/serial/by-id/usb-ZEPHYR_RAK5010_Zephyr_A79B173FF273CE6E-if00'
DEBUG    twister_harness.device.hardware_adapter:hardware_adapter.py:139 Opening serial connection for /dev/serial/by-id/usb-ZEPHYR_RAK5010_Zephyr_A79B173FF273CE6E-if00
ERROR    twister_harness.device.hardware_adapter:hardware_adapter.py:150 Cannot open connection: [Errno 2] could not open port /dev/serial/by-id/usb-ZEPHYR_RAK5010_Zephyr_A79B173FF273CE6E-if00: [Errno 2] No such file or directory: '/dev/serial/by-id/usb-ZEPHYR_RAK5010_Zephyr_A79B173FF273CE6E-if00'
Traceback (most recent call last):
  File "/usr/local/lib/python3.11/dist-packages/serial/serialposix.py", line 322, in open
    self.fd = os.open(self.portstr, os.O_RDWR | os.O_NOCTTY | os.O_NONBLOCK)
              ^^^^^^^^^^^^^^^^^^^^^^^^^^^^^^^^^^^^^^^^^^^^^^^^^^^^^^^^^^^^^^
FileNotFoundError: [Errno 2] No such file or directory: '/dev/serial/by-id/usb-ZEPHYR_RAK5010_Zephyr_A79B173FF273CE6E-if00'

During handling of the above exception, another exception occurred:

Traceback (most recent call last):
  File "/__w/golioth-firmware-sdk/golioth-firmware-sdk/zephyr/scripts/pylib/pytest-twister-harness/src/twister_harness/device/hardware_adapter.py", line 141, in _connect_device
    self._serial_connection = serial.Serial(
                              ^^^^^^^^^^^^^^
  File "/usr/local/lib/python3.11/dist-packages/serial/serialutil.py", line 244, in __init__
    self.open()
  File "/usr/local/lib/python3.11/dist-packages/serial/serialposix.py", line 325, in open
    raise SerialException(msg.errno, "could not open port {}: {}".format(self._port, msg))
serial.serialutil.SerialException: [Errno 2] could not open port /dev/serial/by-id/usb-ZEPHYR_RAK5010_Zephyr_A79B173FF273CE6E-if00: [Errno 2] No such file or directory: '/dev/serial/by-id/usb-ZEPHYR_RAK5010_Zephyr_A79B173FF273CE6E-if00'
DEBUG    twister_harness.device.hardware_adapter:hardware_adapter.py:139 Opening serial connection for /dev/serial/by-id/usb-ZEPHYR_RAK5010_Zephyr_A79B173FF273CE6E-if00
INFO     twister_harness.fixtures:fixtures.py:61 Wait for prompt
DEBUG    twister_harness.helpers.shell:shell.py:47 Got prompt
DEBUG    httpx:_config.py:82 load_ssl_context verify=True cert=None trust_env=True http2=False
DEBUG    httpx:_config.py:148 load_verify_locations cafile='/usr/local/lib/python3.11/dist-packages/certifi/cacert.pem'
DEBUG    httpcore.connection:_trace.py:85 connect_tcp.started host='api.golioth.io' port=443 local_address=None timeout=5.0 socket_options=None
DEBUG    httpcore.connection:_trace.py:85 connect_tcp.complete return_value=<httpcore._backends.trio.TrioStream object at 0xffffaf399810>
DEBUG    httpcore.connection:_trace.py:85 start_tls.started ssl_context=<ssl.SSLContext object at 0xffffaf5cee70> server_hostname='api.golioth.io' timeout=5.0
DEBUG    httpcore.connection:_trace.py:85 start_tls.complete return_value=<httpcore._backends.trio.TrioStream object at 0xffffaf39a8d0>
DEBUG    httpcore.http11:_trace.py:85 send_request_headers.started request=<Request [b'POST']>
DEBUG    httpcore.http11:_trace.py:85 send_request_headers.complete
DEBUG    httpcore.http11:_trace.py:85 send_request_body.started request=<Request [b'POST']>
DEBUG    httpcore.http11:_trace.py:85 send_request_body.complete
DEBUG    httpcore.http11:_trace.py:85 receive_response_headers.started request=<Request [b'POST']>
DEBUG    httpcore.http11:_trace.py:85 receive_response_headers.complete return_value=(b'HTTP/1.1', 200, b'OK', [(b'Content-Length', b'11'), (b'Content-Type', b'application/json'), (b'Date', b'Wed, 13 Nov 2024 23:29:26 GMT'), (b'Grpc-Metadata-Content-Type', b'application/grpc'), (b'Via', b'kong/2.5.2'), (b'X-Kong-Proxy-Latency', b'2'), (b'X-Kong-Upstream-Latency', b'7')])
INFO     httpx:_client.py:1786 HTTP Request: POST https://api.golioth.io/v1/projects/firmware_ci/devices/673536328590529831ce4d55/data/counter "HTTP/1.1 200 OK"
DEBUG    httpcore.http11:_trace.py:85 receive_response_body.started request=<Request [b'POST']>
DEBUG    httpcore.http11:_trace.py:85 receive_response_body.complete
DEBUG    httpcore.http11:_trace.py:85 response_closed.started
DEBUG    httpcore.http11:_trace.py:85 response_closed.complete
DEBUG    httpcore.connection:_trace.py:85 close.started
DEBUG    httpcore.connection:_trace.py:85 close.complete
DEBUG    httpx:_config.py:82 load_ssl_context verify=True cert=None trust_env=True http2=False
DEBUG    httpx:_config.py:148 load_verify_locations cafile='/usr/local/lib/python3.11/dist-packages/certifi/cacert.pem'
DEBUG    httpcore.connection:_trace.py:85 connect_tcp.started host='api.golioth.io' port=443 local_address=None timeout=5.0 socket_options=None
DEBUG    httpcore.connection:_trace.py:85 connect_tcp.complete return_value=<httpcore._backends.trio.TrioStream object at 0xffffaf367b50>
DEBUG    httpcore.connection:_trace.py:85 start_tls.started ssl_context=<ssl.SSLContext object at 0xffffaf4c5520> server_hostname='api.golioth.io' timeout=5.0
DEBUG    httpcore.connection:_trace.py:85 start_tls.complete return_value=<httpcore._backends.trio.TrioStream object at 0xffffaf39a710>
DEBUG    httpcore.http11:_trace.py:85 send_request_headers.started request=<Request [b'GET']>
DEBUG    httpcore.http11:_trace.py:85 send_request_headers.complete
DEBUG    httpcore.http11:_trace.py:85 send_request_body.started request=<Request [b'GET']>
DEBUG    httpcore.http11:_trace.py:85 send_request_body.complete
DEBUG    httpcore.http11:_trace.py:85 receive_response_headers.started request=<Request [b'GET']>
DEBUG    httpcore.http11:_trace.py:85 receive_response_headers.complete return_value=(b'HTTP/1.1', 200, b'OK', [(b'Content-Length', b'11'), (b'Content-Type', b'application/json'), (b'Date', b'Wed, 13 Nov 2024 23:29:26 GMT'), (b'Grpc-Metadata-Content-Type', b'application/grpc'), (b'Via', b'kong/2.5.2'), (b'X-Kong-Proxy-Latency', b'1'), (b'X-Kong-Upstream-Latency', b'10')])
INFO     httpx:_client.py:1786 HTTP Request: GET https://api.golioth.io/v1/projects/firmware_ci/devices/673536328590529831ce4d55/data/counter "HTTP/1.1 200 OK"
DEBUG    httpcore.http11:_trace.py:85 receive_response_body.started request=<Request [b'GET']>
DEBUG    httpcore.http11:_trace.py:85 receive_response_body.complete
DEBUG    httpcore.http11:_trace.py:85 response_closed.started
DEBUG    httpcore.http11:_trace.py:85 response_closed.complete
DEBUG    httpcore.connection:_trace.py:85 close.started
DEBUG    httpcore.connection:_trace.py:85 close.complete
DEBUG    httpx:_config.py:82 load_ssl_context verify=True cert=None trust_env=True http2=False
DEBUG    httpx:_config.py:148 load_verify_locations cafile='/usr/local/lib/python3.11/dist-packages/certifi/cacert.pem'
DEBUG    httpcore.connection:_trace.py:85 connect_tcp.started host='api.golioth.io' port=443 local_address=None timeout=5.0 socket_options=None
DEBUG    httpcore.connection:_trace.py:85 connect_tcp.complete return_value=<httpcore._backends.trio.TrioStream object at 0xffffaf359910>
DEBUG    httpcore.connection:_trace.py:85 start_tls.started ssl_context=<ssl.SSLContext object at 0xffffaf4c47a0> server_hostname='api.golioth.io' timeout=5.0
DEBUG    httpcore.connection:_trace.py:85 start_tls.complete return_value=<httpcore._backends.trio.TrioStream object at 0xffffaf39bb50>
DEBUG    httpcore.http11:_trace.py:85 send_request_headers.started request=<Request [b'GET']>
DEBUG    httpcore.http11:_trace.py:85 send_request_headers.complete
DEBUG    httpcore.http11:_trace.py:85 send_request_body.started request=<Request [b'GET']>
DEBUG    httpcore.http11:_trace.py:85 send_request_body.complete
DEBUG    httpcore.http11:_trace.py:85 receive_response_headers.started request=<Request [b'GET']>
DEBUG    httpcore.http11:_trace.py:85 receive_response_headers.complete return_value=(b'HTTP/1.1', 200, b'OK', [(b'Access-Control-Expose-Headers', b'Content-Range'), (b'Content-Length', b'203'), (b'Content-Range', b'credentials 0-1/1'), (b'Content-Type', b'application/json'), (b'Date', b'Wed, 13 Nov 2024 23:29:29 GMT'), (b'Grpc-Metadata-Access-Control-Expose-Headers', b'Content-Range'), (b'Grpc-Metadata-Content-Type', b'application/grpc'), (b'Via', b'kong/2.5.2'), (b'X-Kong-Proxy-Latency', b'0'), (b'X-Kong-Upstream-Latency', b'25')])
INFO     httpx:_client.py:1786 HTTP Request: GET https://api.golioth.io/v1/projects/firmware_ci/devices/673536328590529831ce4d55/credentials "HTTP/1.1 200 OK"
DEBUG    httpcore.http11:_trace.py:85 receive_response_body.started request=<Request [b'GET']>
DEBUG    httpcore.http11:_trace.py:85 receive_response_body.complete
DEBUG    httpcore.http11:_trace.py:85 response_closed.started
DEBUG    httpcore.http11:_trace.py:85 response_closed.complete
DEBUG    httpcore.connection:_trace.py:85 close.started
DEBUG    httpcore.connection:_trace.py:85 close.complete
DEBUG    twister_harness.device.device_adapter:device_adapter.py:148 #: [1;32muart:~$ [msettings set golioth/psk-id generated-oeLplomuGqHHkkkj@firmware_ci
DEBUG    twister_harness.device.device_adapter:device_adapter.py:148 #: Setting golioth/psk-id to generated-oeLplomuGqHHkkkj@firmware_ci
DEBUG    twister_harness.device.device_adapter:device_adapter.py:148 #: Setting golioth/psk-id saved as generated-oeLplomuGqHHkkkj@firmware_ci
DEBUG    twister_harness.device.device_adapter:device_adapter.py:148 #: [1;32muart:~$ [m
DEBUG    twister_harness.device.device_adapter:device_adapter.py:148 #: [1;32muart:~$ [msettings set golioth/psk generated-oeLplomuGqHHkkkj
DEBUG    twister_harness.device.device_adapter:device_adapter.py:148 #: Setting golioth/psk to generated-oeLplomuGqHHkkkj
DEBUG    twister_harness.device.device_adapter:device_adapter.py:148 #: Setting golioth/psk saved as generated-oeLplomuGqHHkkkj
DEBUG    twister_harness.device.device_adapter:device_adapter.py:148 #: [1;32muart:~$ [m
DEBUG    twister_harness.device.device_adapter:device_adapter.py:148 #: [1;32muart:~$ [msettings set wifi/ssid "***MIKES_ORANGE_PI_WIFI_SSID***"
DEBUG    twister_harness.device.device_adapter:device_adapter.py:148 #: Setting wifi/ssid to ***MIKES_ORANGE_PI_WIFI_SSID***
DEBUG    twister_harness.device.device_adapter:device_adapter.py:148 #: [1;31mFailed to set runtime setting: wifi/ssid:***MIKES_ORANGE_PI_WIFI_SSID***
DEBUG    twister_harness.device.device_adapter:device_adapter.py:148 #: [m[1;32muart:~$ [m
DEBUG    twister_harness.device.device_adapter:device_adapter.py:148 #: [1;32muart:~$ [msettings set wifi/psk "***MIKES_ORANGE_PI_WIFI_PSK***"
DEBUG    twister_harness.device.device_adapter:device_adapter.py:148 #: Setting wifi/psk to ***MIKES_ORANGE_PI_WIFI_PSK***
DEBUG    twister_harness.device.device_adapter:device_adapter.py:148 #: [1;31mFailed to set runtime setting: wifi/psk:***MIKES_ORANGE_PI_WIFI_PSK***
DEBUG    twister_harness.device.device_adapter:device_adapter.py:148 #: [m[1;32muart:~$ [m
DEBUG    twister_harness.device.device_adapter:device_adapter.py:148 #: [1;32muart:~$ [m[8D[J[00:00:00.413,208] [0m<inf> fs_nvs: 8 Sectors of 4096 bytes[0m
DEBUG    twister_harness.device.device_adapter:device_adapter.py:148 #: [1;32muart:~$ [m[8D[J[00:00:00.413,238] [0m<inf> fs_nvs: alloc wra: 0, f88[0m
DEBUG    twister_harness.device.device_adapter:device_adapter.py:148 #: [1;32muart:~$ [m[8D[J[00:00:00.413,238] [0m<inf> fs_nvs: data wra: 0, 134[0m
DEBUG    twister_harness.device.device_adapter:device_adapter.py:148 #: [1;32muart:~$ [m[8D[J[00:00:00.413,299] [0m<inf> golioth_settings_autoload: Loading settings[0m
DEBUG    twister_harness.device.device_adapter:device_adapter.py:148 #: [1;32muart:~$ [m[8D[J[00:00:00.413,665] [0m<dbg> lightdb_delete: main: Start LightDB delete sample[0m
DEBUG    twister_harness.device.device_adapter:device_adapter.py:148 #: [1;32muart:~$ [m[8D[J[00:00:00.413,665] [0m<inf> golioth_samples: Bringing up network interface[0m
DEBUG    twister_harness.device.device_adapter:device_adapter.py:148 #: [1;32muart:~$ [m[8D[J[00:00:00.413,726] [0m<inf> golioth_samples: Waiting to obtain IP address[0m
DEBUG    twister_harness.device.device_adapter:device_adapter.py:148 #: [1;32muart:~$ [m[8D[J[00:00:21.907,012] [1;33m<wrn> modem_chat: quectel_bg95_init_chat_script: timed out[0m
DEBUG    twister_harness.device.device_adapter:device_adapter.py:148 #: [1;32muart:~$ [m[8D[J[1;32muart:~$ [m[8D[J[00:00:37.169,738] [0m<inf> golioth_mbox: Mbox created, bufsize: 1320, num_items: 10, item_size: 120[0m
DEBUG    twister_harness.device.device_adapter:device_adapter.py:148 #: [1;32muart:~$ [m[8D[J[1;32muart:~$ [m[8D[J[00:00:38.946,685] [0m<inf> golioth_coap_client_zephyr: Golioth CoAP client connected[0m
DEBUG    twister_harness.device.device_adapter:device_adapter.py:148 #: [1;32muart:~$ [m[8D[J[00:00:38.946,716] [0m<dbg> lightdb_delete: main: Before request (async)[0m
DEBUG    twister_harness.device.device_adapter:device_adapter.py:148 #: [1;32muart:~$ [m[8D[J[00:00:38.946,838] [0m<dbg> lightdb_delete: main: After request (async)[0m
DEBUG    twister_harness.device.device_adapter:device_adapter.py:148 #: [1;32muart:~$ [m[8D[J[00:00:38.946,868] [0m<inf> lightdb_delete: Golioth client connected[0m
DEBUG    twister_harness.device.device_adapter:device_adapter.py:148 #: [1;32muart:~$ [m[8D[J[00:00:38.946,899] [0m<inf> golioth_coap_client_zephyr: Entering CoAP I/O loop[0m
DEBUG    twister_harness.device.device_adapter:device_adapter.py:148 #: [1;32muart:~$ [m[8D[J[00:00:39.305,603] [0m<dbg> lightdb_delete: counter_handler: Counter deleted successfully[0m
DEBUG    httpx:_config.py:82 load_ssl_context verify=True cert=None trust_env=True http2=False
DEBUG    httpx:_config.py:148 load_verify_locations cafile='/usr/local/lib/python3.11/dist-packages/certifi/cacert.pem'
DEBUG    httpcore.connection:_trace.py:85 connect_tcp.started host='api.golioth.io' port=443 local_address=None timeout=5.0 socket_options=None
DEBUG    httpcore.connection:_trace.py:85 connect_tcp.complete return_value=<httpcore._backends.trio.TrioStream object at 0xffffaf358d90>
DEBUG    httpcore.connection:_trace.py:85 start_tls.started ssl_context=<ssl.SSLContext object at 0xffffaf3950a0> server_hostname='api.golioth.io' timeout=5.0
DEBUG    httpcore.connection:_trace.py:85 start_tls.complete return_value=<httpcore._backends.trio.TrioStream object at 0xffffaf3aaf90>
DEBUG    httpcore.http11:_trace.py:85 send_request_headers.started request=<Request [b'GET']>
DEBUG    httpcore.http11:_trace.py:85 send_request_headers.complete
DEBUG    httpcore.http11:_trace.py:85 send_request_body.started request=<Request [b'GET']>
DEBUG    httpcore.http11:_trace.py:85 send_request_body.complete
DEBUG    httpcore.http11:_trace.py:85 receive_response_headers.started request=<Request [b'GET']>
DEBUG    httpcore.http11:_trace.py:85 receive_response_headers.complete return_value=(b'HTTP/1.1', 200, b'OK', [(b'Content-Length', b'13'), (b'Content-Type', b'application/json'), (b'Date', b'Wed, 13 Nov 2024 23:30:06 GMT'), (b'Grpc-Metadata-Content-Type', b'application/grpc'), (b'Via', b'kong/2.5.2'), (b'X-Kong-Proxy-Latency', b'11'), (b'X-Kong-Upstream-Latency', b'8')])
INFO     httpx:_client.py:1786 HTTP Request: GET https://api.golioth.io/v1/projects/firmware_ci/devices/673536328590529831ce4d55/data/counter "HTTP/1.1 200 OK"
DEBUG    httpcore.http11:_trace.py:85 receive_response_body.started request=<Request [b'GET']>
DEBUG    httpcore.http11:_trace.py:85 receive_response_body.complete
DEBUG    httpcore.http11:_trace.py:85 response_closed.started
DEBUG    httpcore.http11:_trace.py:85 response_closed.complete
DEBUG    httpcore.connection:_trace.py:85 close.started
DEBUG    httpcore.connection:_trace.py:85 close.complete
DEBUG    httpx:_config.py:82 load_ssl_context verify=True cert=None trust_env=True http2=False
DEBUG    httpx:_config.py:148 load_verify_locations cafile='/usr/local/lib/python3.11/dist-packages/certifi/cacert.pem'
DEBUG    httpcore.connection:_trace.py:85 connect_tcp.started host='api.golioth.io' port=443 local_address=None timeout=5.0 socket_options=None
DEBUG    httpcore.connection:_trace.py:85 connect_tcp.complete return_value=<httpcore._backends.trio.TrioStream object at 0xffffaf3ab790>
DEBUG    httpcore.connection:_trace.py:85 start_tls.started ssl_context=<ssl.SSLContext object at 0xffffaf395370> server_hostname='api.golioth.io' timeout=5.0
DEBUG    httpcore.connection:_trace.py:85 start_tls.complete return_value=<httpcore._backends.trio.TrioStream object at 0xffffaf3b9f50>
DEBUG    httpcore.http11:_trace.py:85 send_request_headers.started request=<Request [b'POST']>
DEBUG    httpcore.http11:_trace.py:85 send_request_headers.complete
DEBUG    httpcore.http11:_trace.py:85 send_request_body.started request=<Request [b'POST']>
DEBUG    httpcore.http11:_trace.py:85 send_request_body.complete
DEBUG    httpcore.http11:_trace.py:85 receive_response_headers.started request=<Request [b'POST']>
DEBUG    httpcore.http11:_trace.py:85 receive_response_headers.complete return_value=(b'HTTP/1.1', 200, b'OK', [(b'Content-Length', b'11'), (b'Content-Type', b'application/json'), (b'Date', b'Wed, 13 Nov 2024 23:30:06 GMT'), (b'Grpc-Metadata-Content-Type', b'application/grpc'), (b'Via', b'kong/2.5.2'), (b'X-Kong-Proxy-Latency', b'1'), (b'X-Kong-Upstream-Latency', b'7')])
INFO     httpx:_client.py:1786 HTTP Request: POST https://api.golioth.io/v1/projects/firmware_ci/devices/673536328590529831ce4d55/data/counter "HTTP/1.1 200 OK"
DEBUG    httpcore.http11:_trace.py:85 receive_response_body.started request=<Request [b'POST']>
DEBUG    httpcore.http11:_trace.py:85 receive_response_body.complete
DEBUG    httpcore.http11:_trace.py:85 response_closed.started
DEBUG    httpcore.http11:_trace.py:85 response_closed.complete
DEBUG    httpcore.connection:_trace.py:85 close.started
DEBUG    httpcore.connection:_trace.py:85 close.complete
DEBUG    httpx:_config.py:82 load_ssl_context verify=True cert=None trust_env=True http2=False
DEBUG    httpx:_config.py:148 load_verify_locations cafile='/usr/local/lib/python3.11/dist-packages/certifi/cacert.pem'
DEBUG    httpcore.connection:_trace.py:85 connect_tcp.started host='api.golioth.io' port=443 local_address=None timeout=5.0 socket_options=None
DEBUG    httpcore.connection:_trace.py:85 connect_tcp.complete return_value=<httpcore._backends.trio.TrioStream object at 0xffffaf3a9290>
DEBUG    httpcore.connection:_trace.py:85 start_tls.started ssl_context=<ssl.SSLContext object at 0xffffaf395ac0> server_hostname='api.golioth.io' timeout=5.0
DEBUG    httpcore.connection:_trace.py:85 start_tls.complete return_value=<httpcore._backends.trio.TrioStream object at 0xffffaf3c0d90>
DEBUG    httpcore.http11:_trace.py:85 send_request_headers.started request=<Request [b'GET']>
DEBUG    httpcore.http11:_trace.py:85 send_request_headers.complete
DEBUG    httpcore.http11:_trace.py:85 send_request_body.started request=<Request [b'GET']>
DEBUG    httpcore.http11:_trace.py:85 send_request_body.complete
DEBUG    httpcore.http11:_trace.py:85 receive_response_headers.started request=<Request [b'GET']>
DEBUG    httpcore.http11:_trace.py:85 receive_response_headers.complete return_value=(b'HTTP/1.1', 200, b'OK', [(b'Content-Length', b'11'), (b'Content-Type', b'application/json'), (b'Date', b'Wed, 13 Nov 2024 23:30:07 GMT'), (b'Grpc-Metadata-Content-Type', b'application/grpc'), (b'Via', b'kong/2.5.2'), (b'X-Kong-Proxy-Latency', b'1'), (b'X-Kong-Upstream-Latency', b'74')])
INFO     httpx:_client.py:1786 HTTP Request: GET https://api.golioth.io/v1/projects/firmware_ci/devices/673536328590529831ce4d55/data/counter "HTTP/1.1 200 OK"
DEBUG    httpcore.http11:_trace.py:85 receive_response_body.started request=<Request [b'GET']>
DEBUG    httpcore.http11:_trace.py:85 receive_response_body.complete
DEBUG    httpcore.http11:_trace.py:85 response_closed.started
DEBUG    httpcore.http11:_trace.py:85 response_closed.complete
DEBUG    httpcore.connection:_trace.py:85 close.started
DEBUG    httpcore.connection:_trace.py:85 close.complete
DEBUG    twister_harness.device.device_adapter:device_adapter.py:148 #: [1;32muart:~$ [m[8D[J[1;32muart:~$ [m[8D[J[00:00:43.946,899] [0m<dbg> lightdb_delete: main: Before request (sync)[0m
DEBUG    twister_harness.device.device_adapter:device_adapter.py:148 #: [1;32muart:~$ [m[8D[J[00:00:44.539,001] [0m<dbg> lightdb_delete: counter_delete_sync: Counter deleted successfully[0m
DEBUG    httpx:_config.py:82 load_ssl_context verify=True cert=None trust_env=True http2=False
DEBUG    httpx:_config.py:148 load_verify_locations cafile='/usr/local/lib/python3.11/dist-packages/certifi/cacert.pem'
DEBUG    httpcore.connection:_trace.py:85 connect_tcp.started host='api.golioth.io' port=443 local_address=None timeout=5.0 socket_options=None
DEBUG    httpcore.connection:_trace.py:85 connect_tcp.complete return_value=<httpcore._backends.trio.TrioStream object at 0xffffaf34eb50>
DEBUG    httpcore.connection:_trace.py:85 start_tls.started ssl_context=<ssl.SSLContext object at 0xffffaf4c47a0> server_hostname='api.golioth.io' timeout=5.0
DEBUG    httpcore.connection:_trace.py:85 start_tls.complete return_value=<httpcore._backends.trio.TrioStream object at 0xffffaf3bba10>
DEBUG    httpcore.http11:_trace.py:85 send_request_headers.started request=<Request [b'GET']>
DEBUG    httpcore.http11:_trace.py:85 send_request_headers.complete
DEBUG    httpcore.http11:_trace.py:85 send_request_body.started request=<Request [b'GET']>
DEBUG    httpcore.http11:_trace.py:85 send_request_body.complete
DEBUG    httpcore.http11:_trace.py:85 receive_response_headers.started request=<Request [b'GET']>
DEBUG    httpcore.http11:_trace.py:85 receive_response_headers.complete return_value=(b'HTTP/1.1', 200, b'OK', [(b'Content-Length', b'13'), (b'Content-Type', b'application/json'), (b'Date', b'Wed, 13 Nov 2024 23:30:11 GMT'), (b'Grpc-Metadata-Content-Type', b'application/grpc'), (b'Via', b'kong/2.5.2'), (b'X-Kong-Proxy-Latency', b'1'), (b'X-Kong-Upstream-Latency', b'7')])
INFO     httpx:_client.py:1786 HTTP Request: GET https://api.golioth.io/v1/projects/firmware_ci/devices/673536328590529831ce4d55/data/counter "HTTP/1.1 200 OK"
DEBUG    httpcore.http11:_trace.py:85 receive_response_body.started request=<Request [b'GET']>
DEBUG    httpcore.http11:_trace.py:85 receive_response_body.complete
DEBUG    httpcore.http11:_trace.py:85 response_closed.started
DEBUG    httpcore.http11:_trace.py:85 response_closed.complete
DEBUG    httpcore.connection:_trace.py:85 close.started
DEBUG    httpcore.connection:_trace.py:85 close.complete
DEBUG    twister_harness.device.hardware_adapter:hardware_adapter.py:186 Closed serial connection for /dev/serial/by-id/usb-ZEPHYR_RAK5010_Zephyr_A79B173FF273CE6E-if00
DEBUG    httpx:_config.py:82 load_ssl_context verify=True cert=None trust_env=True http2=False
DEBUG    httpx:_config.py:148 load_verify_locations cafile='/usr/local/lib/python3.11/dist-packages/certifi/cacert.pem'
DEBUG    httpcore.connection:_trace.py:85 connect_tcp.started host='api.golioth.io' port=443 local_address=None timeout=5.0 socket_options=None
DEBUG    httpcore.connection:_trace.py:85 connect_tcp.complete return_value=<httpcore._backends.trio.TrioStream object at 0xffffaf3b9a90>
DEBUG    httpcore.connection:_trace.py:85 start_tls.started ssl_context=<ssl.SSLContext object at 0xffffaf5cec30> server_hostname='api.golioth.io' timeout=5.0
DEBUG    httpcore.connection:_trace.py:85 start_tls.complete return_value=<httpcore._backends.trio.TrioStream object at 0xffffaf3c2210>
DEBUG    httpcore.http11:_trace.py:85 send_request_headers.started request=<Request [b'DELETE']>
DEBUG    httpcore.http11:_trace.py:85 send_request_headers.complete
DEBUG    httpcore.http11:_trace.py:85 send_request_body.started request=<Request [b'DELETE']>
DEBUG    httpcore.http11:_trace.py:85 send_request_body.complete
DEBUG    httpcore.http11:_trace.py:85 receive_response_headers.started request=<Request [b'DELETE']>
DEBUG    httpcore.http11:_trace.py:85 receive_response_headers.complete return_value=(b'HTTP/1.1', 200, b'OK', [(b'Content-Length', b'2'), (b'Content-Type', b'application/json'), (b'Date', b'Wed, 13 Nov 2024 23:30:12 GMT'), (b'Grpc-Metadata-Content-Type', b'application/grpc'), (b'Via', b'kong/2.5.2'), (b'X-Kong-Proxy-Latency', b'0'), (b'X-Kong-Upstream-Latency', b'27')])
INFO     httpx:_client.py:1786 HTTP Request: DELETE https://api.golioth.io/v1/projects/firmware_ci/devices/673536328590529831ce4d55 "HTTP/1.1 200 OK"
DEBUG    httpcore.http11:_trace.py:85 receive_response_body.started request=<Request [b'DELETE']>
DEBUG    httpcore.http11:_trace.py:85 receive_response_body.complete
DEBUG    httpcore.http11:_trace.py:85 response_closed.started
DEBUG    httpcore.http11:_trace.py:85 response_closed.complete
DEBUG    httpcore.connection:_trace.py:85 close.started
DEBUG    httpcore.connection:_trace.py:85 close.complete