DEBUG    twister_harness.device.factory:factory.py:37 Get device type "hardware"
DEBUG    httpx:_config.py:82 load_ssl_context verify=True cert=None trust_env=True http2=False
DEBUG    httpx:_config.py:148 load_verify_locations cafile='/usr/local/lib/python3.11/dist-packages/certifi/cacert.pem'
DEBUG    httpcore.connection:_trace.py:85 connect_tcp.started host='api.golioth.io' port=443 local_address=None timeout=5.0 socket_options=None
DEBUG    httpcore.connection:_trace.py:85 connect_tcp.complete return_value=<httpcore._backends.trio.TrioStream object at 0xffff7ce5f1d0>
DEBUG    httpcore.connection:_trace.py:85 start_tls.started ssl_context=<ssl.SSLContext object at 0xffff7cf73e30> server_hostname='api.golioth.io' timeout=5.0
DEBUG    httpcore.connection:_trace.py:85 start_tls.complete return_value=<httpcore._backends.trio.TrioStream object at 0xffff7ccb3fd0>
DEBUG    httpcore.http11:_trace.py:85 send_request_headers.started request=<Request [b'GET']>
DEBUG    httpcore.http11:_trace.py:85 send_request_headers.complete
DEBUG    httpcore.http11:_trace.py:85 send_request_body.started request=<Request [b'GET']>
DEBUG    httpcore.http11:_trace.py:85 send_request_body.complete
DEBUG    httpcore.http11:_trace.py:85 receive_response_headers.started request=<Request [b'GET']>
DEBUG    httpcore.http11:_trace.py:85 receive_response_headers.complete return_value=(b'HTTP/1.1', 200, b'OK', [(b'Access-Control-Expose-Headers', b'Content-Range'), (b'Content-Length', b'193'), (b'Content-Range', b'projects 0-1/1'), (b'Content-Type', b'application/json'), (b'Date', b'Mon, 30 Sep 2024 21:39:27 GMT'), (b'Grpc-Metadata-Access-Control-Expose-Headers', b'Content-Range'), (b'Grpc-Metadata-Content-Type', b'application/grpc'), (b'Via', b'kong/2.5.2'), (b'X-Kong-Proxy-Latency', b'1'), (b'X-Kong-Upstream-Latency', b'18')])
INFO     httpx:_client.py:1786 HTTP Request: GET https://api.golioth.io/v1/projects "HTTP/1.1 200 OK"
DEBUG    httpcore.http11:_trace.py:85 receive_response_body.started request=<Request [b'GET']>
DEBUG    httpcore.http11:_trace.py:85 receive_response_body.complete
DEBUG    httpcore.http11:_trace.py:85 response_closed.started
DEBUG    httpcore.http11:_trace.py:85 response_closed.complete
DEBUG    httpcore.connection:_trace.py:85 close.started
DEBUG    httpcore.connection:_trace.py:85 close.complete
DEBUG    httpx:_config.py:82 load_ssl_context verify=True cert=None trust_env=True http2=False
DEBUG    httpx:_config.py:148 load_verify_locations cafile='/usr/local/lib/python3.11/dist-packages/certifi/cacert.pem'
DEBUG    httpcore.connection:_trace.py:85 connect_tcp.started host='api.golioth.io' port=443 local_address=None timeout=5.0 socket_options=None
DEBUG    httpcore.connection:_trace.py:85 connect_tcp.complete return_value=<httpcore._backends.trio.TrioStream object at 0xffff7ce90d10>
DEBUG    httpcore.connection:_trace.py:85 start_tls.started ssl_context=<ssl.SSLContext object at 0xffff7ce79130> server_hostname='api.golioth.io' timeout=5.0
DEBUG    httpcore.connection:_trace.py:85 start_tls.complete return_value=<httpcore._backends.trio.TrioStream object at 0xffff7ccdf790>
DEBUG    httpcore.http11:_trace.py:85 send_request_headers.started request=<Request [b'POST']>
DEBUG    httpcore.http11:_trace.py:85 send_request_headers.complete
DEBUG    httpcore.http11:_trace.py:85 send_request_body.started request=<Request [b'POST']>
DEBUG    httpcore.http11:_trace.py:85 send_request_body.complete
DEBUG    httpcore.http11:_trace.py:85 receive_response_headers.started request=<Request [b'POST']>
DEBUG    httpcore.http11:_trace.py:85 receive_response_headers.complete return_value=(b'HTTP/1.1', 200, b'OK', [(b'Content-Length', b'849'), (b'Content-Type', b'application/json'), (b'Date', b'Mon, 30 Sep 2024 21:39:27 GMT'), (b'Grpc-Metadata-Content-Type', b'application/grpc'), (b'Via', b'kong/2.5.2'), (b'X-Kong-Proxy-Latency', b'3'), (b'X-Kong-Upstream-Latency', b'15')])
INFO     httpx:_client.py:1786 HTTP Request: POST https://api.golioth.io/v1/projects/firmware_ci/certificates "HTTP/1.1 200 OK"
DEBUG    httpcore.http11:_trace.py:85 receive_response_body.started request=<Request [b'POST']>
DEBUG    httpcore.http11:_trace.py:85 receive_response_body.complete
DEBUG    httpcore.http11:_trace.py:85 response_closed.started
DEBUG    httpcore.http11:_trace.py:85 response_closed.complete
DEBUG    httpcore.connection:_trace.py:85 close.started
DEBUG    httpcore.connection:_trace.py:85 close.complete
DEBUG    twister_harness.device.hardware_adapter:utils.py:37 Flashing command: /usr/local/bin/west flash --skip-rebuild --build-dir /__w/golioth-firmware-sdk/golioth-firmware-sdk/twister-out/rak5010_nrf52840/certificate_provisioning/sample.golioth.certificate_provisioning --runner blackmagicprobe -- --gdb=/usr/bin/gdb
DEBUG    twister_harness.device.hardware_adapter:hardware_adapter.py:131 Flashing finished
DEBUG    twister_harness.device.hardware_adapter:hardware_adapter.py:139 Opening serial connection for /dev/serial/by-id/usb-ZEPHYR_RAK5010_Zephyr_B1E5A88410C9C828-if00
ERROR    twister_harness.device.hardware_adapter:hardware_adapter.py:150 Cannot open connection: [Errno 2] could not open port /dev/serial/by-id/usb-ZEPHYR_RAK5010_Zephyr_B1E5A88410C9C828-if00: [Errno 2] No such file or directory: '/dev/serial/by-id/usb-ZEPHYR_RAK5010_Zephyr_B1E5A88410C9C828-if00'
Traceback (most recent call last):
  File "/usr/local/lib/python3.11/dist-packages/serial/serialposix.py", line 322, in open
    self.fd = os.open(self.portstr, os.O_RDWR | os.O_NOCTTY | os.O_NONBLOCK)
              ^^^^^^^^^^^^^^^^^^^^^^^^^^^^^^^^^^^^^^^^^^^^^^^^^^^^^^^^^^^^^^
FileNotFoundError: [Errno 2] No such file or directory: '/dev/serial/by-id/usb-ZEPHYR_RAK5010_Zephyr_B1E5A88410C9C828-if00'

During handling of the above exception, another exception occurred:

Traceback (most recent call last):
  File "/__w/golioth-firmware-sdk/golioth-firmware-sdk/zephyr/scripts/pylib/pytest-twister-harness/src/twister_harness/device/hardware_adapter.py", line 141, in _connect_device
    self._serial_connection = serial.Serial(
                              ^^^^^^^^^^^^^^
  File "/usr/local/lib/python3.11/dist-packages/serial/serialutil.py", line 244, in __init__
    self.open()
  File "/usr/local/lib/python3.11/dist-packages/serial/serialposix.py", line 325, in open
    raise SerialException(msg.errno, "could not open port {}: {}".format(self._port, msg))
serial.serialutil.SerialException: [Errno 2] could not open port /dev/serial/by-id/usb-ZEPHYR_RAK5010_Zephyr_B1E5A88410C9C828-if00: [Errno 2] No such file or directory: '/dev/serial/by-id/usb-ZEPHYR_RAK5010_Zephyr_B1E5A88410C9C828-if00'
DEBUG    twister_harness.device.hardware_adapter:hardware_adapter.py:139 Opening serial connection for /dev/serial/by-id/usb-ZEPHYR_RAK5010_Zephyr_B1E5A88410C9C828-if00
ERROR    twister_harness.device.hardware_adapter:hardware_adapter.py:150 Cannot open connection: [Errno 2] could not open port /dev/serial/by-id/usb-ZEPHYR_RAK5010_Zephyr_B1E5A88410C9C828-if00: [Errno 2] No such file or directory: '/dev/serial/by-id/usb-ZEPHYR_RAK5010_Zephyr_B1E5A88410C9C828-if00'
Traceback (most recent call last):
  File "/usr/local/lib/python3.11/dist-packages/serial/serialposix.py", line 322, in open
    self.fd = os.open(self.portstr, os.O_RDWR | os.O_NOCTTY | os.O_NONBLOCK)
              ^^^^^^^^^^^^^^^^^^^^^^^^^^^^^^^^^^^^^^^^^^^^^^^^^^^^^^^^^^^^^^
FileNotFoundError: [Errno 2] No such file or directory: '/dev/serial/by-id/usb-ZEPHYR_RAK5010_Zephyr_B1E5A88410C9C828-if00'

During handling of the above exception, another exception occurred:

Traceback (most recent call last):
  File "/__w/golioth-firmware-sdk/golioth-firmware-sdk/zephyr/scripts/pylib/pytest-twister-harness/src/twister_harness/device/hardware_adapter.py", line 141, in _connect_device
    self._serial_connection = serial.Serial(
                              ^^^^^^^^^^^^^^
  File "/usr/local/lib/python3.11/dist-packages/serial/serialutil.py", line 244, in __init__
    self.open()
  File "/usr/local/lib/python3.11/dist-packages/serial/serialposix.py", line 325, in open
    raise SerialException(msg.errno, "could not open port {}: {}".format(self._port, msg))
serial.serialutil.SerialException: [Errno 2] could not open port /dev/serial/by-id/usb-ZEPHYR_RAK5010_Zephyr_B1E5A88410C9C828-if00: [Errno 2] No such file or directory: '/dev/serial/by-id/usb-ZEPHYR_RAK5010_Zephyr_B1E5A88410C9C828-if00'
DEBUG    twister_harness.device.hardware_adapter:hardware_adapter.py:139 Opening serial connection for /dev/serial/by-id/usb-ZEPHYR_RAK5010_Zephyr_B1E5A88410C9C828-if00
ERROR    twister_harness.device.hardware_adapter:hardware_adapter.py:150 Cannot open connection: [Errno 2] could not open port /dev/serial/by-id/usb-ZEPHYR_RAK5010_Zephyr_B1E5A88410C9C828-if00: [Errno 2] No such file or directory: '/dev/serial/by-id/usb-ZEPHYR_RAK5010_Zephyr_B1E5A88410C9C828-if00'
Traceback (most recent call last):
  File "/usr/local/lib/python3.11/dist-packages/serial/serialposix.py", line 322, in open
    self.fd = os.open(self.portstr, os.O_RDWR | os.O_NOCTTY | os.O_NONBLOCK)
              ^^^^^^^^^^^^^^^^^^^^^^^^^^^^^^^^^^^^^^^^^^^^^^^^^^^^^^^^^^^^^^
FileNotFoundError: [Errno 2] No such file or directory: '/dev/serial/by-id/usb-ZEPHYR_RAK5010_Zephyr_B1E5A88410C9C828-if00'

During handling of the above exception, another exception occurred:

Traceback (most recent call last):
  File "/__w/golioth-firmware-sdk/golioth-firmware-sdk/zephyr/scripts/pylib/pytest-twister-harness/src/twister_harness/device/hardware_adapter.py", line 141, in _connect_device
    self._serial_connection = serial.Serial(
                              ^^^^^^^^^^^^^^
  File "/usr/local/lib/python3.11/dist-packages/serial/serialutil.py", line 244, in __init__
    self.open()
  File "/usr/local/lib/python3.11/dist-packages/serial/serialposix.py", line 325, in open
    raise SerialException(msg.errno, "could not open port {}: {}".format(self._port, msg))
serial.serialutil.SerialException: [Errno 2] could not open port /dev/serial/by-id/usb-ZEPHYR_RAK5010_Zephyr_B1E5A88410C9C828-if00: [Errno 2] No such file or directory: '/dev/serial/by-id/usb-ZEPHYR_RAK5010_Zephyr_B1E5A88410C9C828-if00'
DEBUG    twister_harness.device.hardware_adapter:hardware_adapter.py:139 Opening serial connection for /dev/serial/by-id/usb-ZEPHYR_RAK5010_Zephyr_B1E5A88410C9C828-if00
INFO     twister_harness.fixtures:fixtures.py:61 Wait for prompt
DEBUG    twister_harness.helpers.shell:shell.py:47 Got prompt
DEBUG    httpx:_config.py:82 load_ssl_context verify=True cert=None trust_env=True http2=False
DEBUG    httpx:_config.py:148 load_verify_locations cafile='/usr/local/lib/python3.11/dist-packages/certifi/cacert.pem'
DEBUG    httpcore.connection:_trace.py:85 connect_tcp.started host='api.golioth.io' port=443 local_address=None timeout=5.0 socket_options=None
DEBUG    httpcore.connection:_trace.py:85 connect_tcp.complete return_value=<httpcore._backends.trio.TrioStream object at 0xffff7ce43610>
DEBUG    httpcore.connection:_trace.py:85 start_tls.started ssl_context=<ssl.SSLContext object at 0xffff7d835ac0> server_hostname='api.golioth.io' timeout=5.0
DEBUG    httpcore.connection:_trace.py:85 start_tls.complete return_value=<httpcore._backends.trio.TrioStream object at 0xffff7cd3f790>
DEBUG    httpcore.http11:_trace.py:85 send_request_headers.started request=<Request [b'GET']>
DEBUG    httpcore.http11:_trace.py:85 send_request_headers.complete
DEBUG    httpcore.http11:_trace.py:85 send_request_body.started request=<Request [b'GET']>
DEBUG    httpcore.http11:_trace.py:85 send_request_body.complete
DEBUG    httpcore.http11:_trace.py:85 receive_response_headers.started request=<Request [b'GET']>
DEBUG    httpcore.http11:_trace.py:85 receive_response_headers.complete return_value=(b'HTTP/1.1', 200, b'OK', [(b'Access-Control-Expose-Headers', b'Content-Range'), (b'Content-Length', b'47'), (b'Content-Range', b'devices 0-0/0'), (b'Content-Type', b'application/json'), (b'Date', b'Mon, 30 Sep 2024 21:39:42 GMT'), (b'Grpc-Metadata-Access-Control-Expose-Headers', b'Content-Range'), (b'Grpc-Metadata-Content-Type', b'application/grpc'), (b'Via', b'kong/2.5.2'), (b'X-Kong-Proxy-Latency', b'0'), (b'X-Kong-Upstream-Latency', b'23')])
INFO     httpx:_client.py:1786 HTTP Request: GET https://api.golioth.io/v1/projects/firmware_ci/devices?deviceName=certificate-GaxtpJEUhiCQhZIT "HTTP/1.1 200 OK"
DEBUG    httpcore.http11:_trace.py:85 receive_response_body.started request=<Request [b'GET']>
DEBUG    httpcore.http11:_trace.py:85 receive_response_body.complete
DEBUG    httpcore.http11:_trace.py:85 response_closed.started
DEBUG    httpcore.http11:_trace.py:85 response_closed.complete
DEBUG    httpcore.connection:_trace.py:85 close.started
DEBUG    httpcore.connection:_trace.py:85 close.complete
DEBUG    twister_harness.device.device_adapter:device_adapter.py:148 #: [1;32muart:~$ [msettings set wifi/ssid "***MIKES_ORANGE_PI_WIFI_SSID***"
DEBUG    twister_harness.device.device_adapter:device_adapter.py:148 #: Setting wifi/ssid to ***MIKES_ORANGE_PI_WIFI_SSID***
DEBUG    twister_harness.device.device_adapter:device_adapter.py:148 #: [1;31mFailed to set runtime setting: wifi/ssid:***MIKES_ORANGE_PI_WIFI_SSID***
DEBUG    twister_harness.device.device_adapter:device_adapter.py:148 #: [m[1;32muart:~$ [m
DEBUG    twister_harness.device.device_adapter:device_adapter.py:148 #: [1;32muart:~$ [msettings set wifi/psk "***MIKES_ORANGE_PI_WIFI_PSK***"
DEBUG    twister_harness.device.device_adapter:device_adapter.py:148 #: Setting wifi/psk to ***MIKES_ORANGE_PI_WIFI_PSK***
DEBUG    twister_harness.device.device_adapter:device_adapter.py:148 #: [1;31mFailed to set runtime setting: wifi/psk:***MIKES_ORANGE_PI_WIFI_PSK***
DEBUG    twister_harness.device.device_adapter:device_adapter.py:148 #: [m[1;32muart:~$ [m
DEBUG    twister_harness.device.device_adapter:device_adapter.py:148 #: [1;32muart:~$ [m[8D[J*** Booting Zephyr OS build 36940db938a8 ***
DEBUG    twister_harness.device.device_adapter:device_adapter.py:148 #: [1;32muart:~$ [m[8D[J[00:00:00.462,463] [0m<inf> golioth_settings_autoload: Initializing settings subsystem[0m
DEBUG    twister_harness.device.device_adapter:device_adapter.py:148 #: [1;32muart:~$ [m[8D[J[00:00:00.462,554] [0m<inf> golioth_settings_autoload: Loading settings[0m
DEBUG    twister_harness.device.device_adapter:device_adapter.py:148 #: [1;32muart:~$ [m[8D[J[00:00:00.462,738] [1;31m<err> fs: file open error (-2)[0m
DEBUG    twister_harness.device.device_adapter:device_adapter.py:148 #: [1;32muart:~$ [m[8D[J[00:00:00.463,195] [0m<dbg> cert_provisioning: main: Start certificate provisioning sample[0m
DEBUG    twister_harness.device.device_adapter:device_adapter.py:148 #: [1;32muart:~$ [m[8D[J[00:00:00.463,195] [0m<inf> golioth_samples: Bringing up network interface[0m
DEBUG    twister_harness.device.device_adapter:device_adapter.py:148 #: [1;32muart:~$ [m[8D[J[00:00:00.463,256] [0m<inf> golioth_samples: Waiting to obtain IP address[0m
DEBUG    twister_harness.device.device_adapter:device_adapter.py:148 #: [1;32muart:~$ [m[8D[J[00:00:21.791,595] [1;33m<wrn> modem_chat: quectel_bg95_init_chat_script: timed out[0m
DEBUG    twister_harness.device.device_adapter:device_adapter.py:148 #: [1;32muart:~$ [m[8D[J[1;32muart:~$ [m[8D[J[00:00:37.417,144] [1;33m<wrn> cert_provisioning: Could not stat /lfs1/credentials/client_cert.der, err: -2[0m
DEBUG    twister_harness.device.device_adapter:device_adapter.py:148 #: [1;32muart:~$ [m[8D[J[1;32muart:~$ [mfs mkdir /lfs1/credentials
DEBUG    twister_harness.device.device_adapter:device_adapter.py:148 #: [1;32muart:~$ [m
DEBUG    twister_harness.device.device_adapter:device_adapter.py:148 #: [1;32muart:~$ [mlog halt
DEBUG    twister_harness.device.device_adapter:device_adapter.py:148 #: [1;32muart:~$ [m
INFO     test_sample:test_sample.py:23 mcumgr crt stdout: 302
365
Done

INFO     test_sample:test_sample.py:23 mcumgr key stdout: 121
Done

DEBUG    twister_harness.device.device_adapter:device_adapter.py:148 #: [1;32muart:~$ [mlog go
DEBUG    twister_harness.device.device_adapter:device_adapter.py:148 #: [1;32muart:~$ [m
DEBUG    twister_harness.device.device_adapter:device_adapter.py:148 #: [1;32muart:~$ [m[8D[J[00:00:42.419,189] [0m<inf> cert_provisioning: Read 365 bytes from /lfs1/credentials/client_cert.der[0m
DEBUG    twister_harness.device.device_adapter:device_adapter.py:148 #: [1;32muart:~$ [m[8D[J[00:00:42.420,898] [0m<inf> cert_provisioning: Read 121 bytes from /lfs1/credentials/private_key.der[0m
DEBUG    twister_harness.device.device_adapter:device_adapter.py:148 #: [1;32muart:~$ [m[8D[J[00:00:42.421,417] [0m<inf> golioth_mbox: Mbox created, bufsize: 1232, num_items: 10, item_size: 112[0m
DEBUG    twister_harness.device.device_adapter:device_adapter.py:148 #: [1;32muart:~$ [m[8D[J[1;32muart:~$ [m[8D[J[1;31m--- 3 messages dropped ---
DEBUG    twister_harness.device.device_adapter:device_adapter.py:148 #: [m[00:00:45.900,146] [1;33m<wrn> modem_ppp: Failed to alloc buffer[0m
DEBUG    twister_harness.device.device_adapter:device_adapter.py:148 #: [1;32muart:~$ [m[8D[J[00:00:46.183,471] [1;31m<err> net_pkt: Data buffer (127) allocation failed.[0m
DEBUG    twister_harness.device.device_adapter:device_adapter.py:148 #: [1;32muart:~$ [m[8D[J[00:00:46.183,471] [1;33m<wrn> modem_ppp: Failed to alloc buffer[0m
DEBUG    twister_harness.device.device_adapter:device_adapter.py:148 #: [1;32muart:~$ [m[8D[J[00:00:47.500,030] [1;33m<wrn> modem_ppp: Dropped frame, no net_pkt available[0m
DEBUG    twister_harness.device.device_adapter:device_adapter.py:148 #: [1;32muart:~$ [m[8D[J[1;31m--- 1 messages dropped ---
DEBUG    twister_harness.device.device_adapter:device_adapter.py:148 #: [m[00:00:47.775,970] [1;33m<wrn> modem_ppp: Dropped frame, no net_pkt available[0m
DEBUG    twister_harness.device.device_adapter:device_adapter.py:148 #: [1;32muart:~$ [m[8D[J[00:00:47.916,870] [1;33m<wrn> modem_ppp: Dropped frame, no net_pkt available[0m
DEBUG    twister_harness.device.device_adapter:device_adapter.py:148 #: [1;32muart:~$ [m[8D[J[00:00:48.046,081] [1;33m<wrn> modem_ppp: Dropped frame, no net_pkt available[0m
DEBUG    twister_harness.device.device_adapter:device_adapter.py:148 #: [1;32muart:~$ [m[8D[J[00:00:48.319,244] [1;33m<wrn> modem_ppp: Dropped frame, no net_pkt available[0m
DEBUG    twister_harness.device.device_adapter:device_adapter.py:148 #: [1;32muart:~$ [m[8D[J[00:00:48.559,082] [1;33m<wrn> modem_ppp: Dropped frame, no net_pkt available[0m
DEBUG    twister_harness.device.device_adapter:device_adapter.py:148 #: [1;32muart:~$ [m[8D[J[00:00:48.823,455] [1;33m<wrn> modem_ppp: Dropped frame, no net_pkt available[0m
DEBUG    twister_harness.device.device_adapter:device_adapter.py:148 #: [1;32muart:~$ [m[8D[J[00:00:49.085,540] [1;33m<wrn> modem_ppp: Dropped frame, no net_pkt available[0m
DEBUG    twister_harness.device.device_adapter:device_adapter.py:148 #: [1;32muart:~$ [m[8D[J[00:00:49.559,417] [1;33m<wrn> modem_ppp: Dropped frame, no net_pkt available[0m
DEBUG    twister_harness.device.device_adapter:device_adapter.py:148 #: [1;32muart:~$ [m[8D[J[00:00:49.883,728] [1;33m<wrn> modem_ppp: Dropped frame, no net_pkt available[0m
DEBUG    twister_harness.device.device_adapter:device_adapter.py:148 #: [1;32muart:~$ [m[8D[J[00:00:50.206,787] [1;33m<wrn> modem_ppp: Dropped frame, no net_pkt available[0m
DEBUG    twister_harness.device.device_adapter:device_adapter.py:148 #: [1;32muart:~$ [m[8D[J[00:00:51.100,982] [1;33m<wrn> modem_ppp: Dropped frame, no net_pkt available[0m
DEBUG    twister_harness.device.device_adapter:device_adapter.py:148 #: [1;32muart:~$ [m[8D[J[00:00:51.448,272] [1;33m<wrn> modem_ppp: Dropped frame, no net_pkt available[0m
DEBUG    twister_harness.device.device_adapter:device_adapter.py:148 #: [1;32muart:~$ [m[8D[J[00:00:51.688,323] [1;33m<wrn> modem_ppp: Dropped frame, no net_pkt available[0m
DEBUG    twister_harness.device.device_adapter:device_adapter.py:148 #: [1;32muart:~$ [m[8D[J[00:00:51.829,223] [1;33m<wrn> modem_ppp: Dropped frame, no net_pkt available[0m
DEBUG    twister_harness.device.device_adapter:device_adapter.py:148 #: [1;32muart:~$ [m[8D[J[00:00:51.966,522] [1;33m<wrn> modem_ppp: Dropped frame, no net_pkt available[0m
DEBUG    twister_harness.device.device_adapter:device_adapter.py:148 #: [1;32muart:~$ [m[8D[J[00:00:52.204,559] [1;33m<wrn> modem_ppp: Dropped frame, no net_pkt available[0m
DEBUG    twister_harness.device.device_adapter:device_adapter.py:148 #: [1;32muart:~$ [m[8D[J[00:00:52.946,929] [1;33m<wrn> modem_ppp: Dropped frame, no net_pkt available[0m
DEBUG    twister_harness.device.device_adapter:device_adapter.py:148 #: [1;32muart:~$ [m[8D[J[00:00:53.188,842] [1;33m<wrn> modem_ppp: Dropped frame, no net_pkt available[0m
DEBUG    twister_harness.device.device_adapter:device_adapter.py:148 #: [1;32muart:~$ [m[8D[J[00:00:53.568,786] [1;33m<wrn> modem_ppp: Dropped frame, no net_pkt available[0m
DEBUG    twister_harness.device.device_adapter:device_adapter.py:148 #: [1;32muart:~$ [m[8D[J[00:00:53.781,036] [1;33m<wrn> modem_ppp: Dropped frame, no net_pkt available[0m
DEBUG    twister_harness.device.device_adapter:device_adapter.py:148 #: [1;32muart:~$ [m[8D[J[00:00:54.016,143] [1;33m<wrn> modem_ppp: Dropped frame, no net_pkt available[0m
DEBUG    twister_harness.device.device_adapter:device_adapter.py:148 #: [1;32muart:~$ [m[8D[J[00:00:56.132,598] [1;33m<wrn> modem_ppp: Dropped frame, no net_pkt available[0m
DEBUG    twister_harness.device.device_adapter:device_adapter.py:148 #: [1;32muart:~$ [m[8D[J[00:00:56.334,930] [1;33m<wrn> modem_ppp: Dropped frame, no net_pkt available[0m
DEBUG    twister_harness.device.device_adapter:device_adapter.py:148 #: [1;32muart:~$ [m[8D[J[00:00:56.496,063] [1;33m<wrn> modem_ppp: Dropped frame, no net_pkt available[0m
DEBUG    twister_harness.device.device_adapter:device_adapter.py:148 #: [1;32muart:~$ [m[8D[J[00:00:56.636,962] [1;33m<wrn> modem_ppp: Dropped frame, no net_pkt available[0m
DEBUG    twister_harness.device.device_adapter:device_adapter.py:148 #: [1;32muart:~$ [m[8D[J[00:00:56.848,999] [1;33m<wrn> modem_ppp: Dropped frame, no net_pkt available[0m
DEBUG    twister_harness.device.device_adapter:device_adapter.py:148 #: [1;32muart:~$ [m[8D[J[00:00:57.010,040] [1;33m<wrn> modem_ppp: Dropped frame, no net_pkt available[0m
DEBUG    twister_harness.device.device_adapter:device_adapter.py:148 #: [1;32muart:~$ [m[8D[J[00:00:57.166,107] [1;33m<wrn> modem_ppp: Dropped frame, no net_pkt available[0m
DEBUG    twister_harness.device.device_adapter:device_adapter.py:148 #: [1;32muart:~$ [m[8D[J[00:00:57.390,228] [1;33m<wrn> modem_ppp: Dropped frame, no net_pkt available[0m
DEBUG    twister_harness.device.device_adapter:device_adapter.py:148 #: [1;32muart:~$ [m[8D[J[00:00:57.583,099] [1;33m<wrn> modem_ppp: Dropped frame, no net_pkt available[0m
DEBUG    twister_harness.device.device_adapter:device_adapter.py:148 #: [1;32muart:~$ [m[8D[J[00:00:57.865,386] [1;33m<wrn> modem_ppp: Dropped frame, no net_pkt available[0m
DEBUG    twister_harness.device.device_adapter:device_adapter.py:148 #: [1;32muart:~$ [m[8D[J[00:00:58.128,662] [1;33m<wrn> modem_ppp: Dropped frame, no net_pkt available[0m
DEBUG    twister_harness.device.device_adapter:device_adapter.py:148 #: [1;32muart:~$ [m[8D[J[00:00:58.566,375] [1;33m<wrn> modem_ppp: Dropped frame, no net_pkt available[0m
DEBUG    twister_harness.device.device_adapter:device_adapter.py:148 #: [1;32muart:~$ [m[8D[J[00:00:58.830,749] [1;33m<wrn> modem_ppp: Dropped frame, no net_pkt available[0m
DEBUG    twister_harness.device.device_adapter:device_adapter.py:148 #: [1;32muart:~$ [m[8D[J[00:00:59.042,724] [1;33m<wrn> modem_ppp: Dropped frame, no net_pkt available[0m
DEBUG    twister_harness.device.device_adapter:device_adapter.py:148 #: [1;32muart:~$ [m[8D[J[00:00:59.962,677] [1;33m<wrn> modem_ppp: Dropped frame, no net_pkt available[0m
DEBUG    twister_harness.device.device_adapter:device_adapter.py:148 #: [1;32muart:~$ [m[8D[J[00:01:00.278,900] [1;33m<wrn> modem_ppp: Dropped frame, no net_pkt available[0m
DEBUG    twister_harness.device.device_adapter:device_adapter.py:148 #: [1;32muart:~$ [m[8D[J[00:01:00.544,097] [1;33m<wrn> modem_ppp: Dropped frame, no net_pkt available[0m
DEBUG    twister_harness.device.device_adapter:device_adapter.py:148 #: [1;32muart:~$ [m[8D[J[00:01:00.684,936] [1;33m<wrn> modem_ppp: Dropped frame, no net_pkt available[0m
DEBUG    twister_harness.device.device_adapter:device_adapter.py:148 #: [1;32muart:~$ [m[8D[J[00:01:00.866,241] [1;33m<wrn> modem_ppp: Dropped frame, no net_pkt available[0m
DEBUG    twister_harness.device.device_adapter:device_adapter.py:148 #: [1;32muart:~$ [m[8D[J[00:01:01.136,322] [1;33m<wrn> modem_ppp: Dropped frame, no net_pkt available[0m
DEBUG    twister_harness.device.device_adapter:device_adapter.py:148 #: [1;32muart:~$ [m[8D[J[00:01:01.570,312] [1;33m<wrn> modem_ppp: Dropped frame, no net_pkt available[0m
DEBUG    twister_harness.device.device_adapter:device_adapter.py:148 #: [1;32muart:~$ [m[8D[J[00:01:01.824,493] [1;33m<wrn> modem_ppp: Dropped frame, no net_pkt available[0m
DEBUG    twister_harness.device.device_adapter:device_adapter.py:148 #: [1;32muart:~$ [m[8D[J[00:01:02.016,540] [1;33m<wrn> modem_ppp: Dropped frame, no net_pkt available[0m
DEBUG    twister_harness.device.device_adapter:device_adapter.py:148 #: [1;32muart:~$ [m[8D[J[00:01:02.576,538] [1;33m<wrn> modem_ppp: Dropped frame, no net_pkt available[0m
DEBUG    twister_harness.device.device_adapter:device_adapter.py:148 #: [1;32muart:~$ [m[8D[J[00:01:05.185,607] [1;33m<wrn> modem_ppp: Dropped frame, no net_pkt available[0m
DEBUG    twister_harness.device.device_adapter:device_adapter.py:148 #: [1;32muart:~$ [m[8D[J[1;32muart:~$ [m[8D[J[1;32muart:~$ [m[8D[J[00:01:05.812,377] [1;33m<wrn> modem_cmux: DLCI 1 receive buffer overrun (dropped 18 out of 119 bytes)[0m
DEBUG    twister_harness.device.device_adapter:device_adapter.py:148 #: [1;32muart:~$ [m[8D[J[00:01:05.831,756] [1;33m<wrn> modem_cmux: DLCI 1 receive buffer overrun (dropped 5 out of 43 bytes)[0m
DEBUG    twister_harness.device.device_adapter:device_adapter.py:148 #: [1;32muart:~$ [m[8D[J[00:01:06.452,087] [0m<inf> golioth_coap_client_zephyr: Golioth CoAP client connected[0m
DEBUG    twister_harness.device.device_adapter:device_adapter.py:148 #: [1;32muart:~$ [m[8D[J[00:01:06.452,331] [0m<inf> cert_provisioning: Sending hello! 0[0m
DEBUG    twister_harness.device.device_adapter:device_adapter.py:148 #: [1;32muart:~$ [m[8D[J[00:01:06.452,392] [0m<inf> cert_provisioning: Golioth client connected[0m
DEBUG    twister_harness.device.device_adapter:device_adapter.py:148 #: [1;32muart:~$ [m[8D[J[00:01:06.452,392] [0m<inf> golioth_coap_client_zephyr: Entering CoAP I/O loop[0m
DEBUG    twister_harness.device.device_adapter:device_adapter.py:148 #: [1;32muart:~$ [m[8D[J[1;32muart:~$ [m[8D[J[00:01:11.452,392] [0m<inf> cert_provisioning: Sending hello! 1[0m
DEBUG    twister_harness.device.device_adapter:device_adapter.py:148 #: [1;32muart:~$ [m[8D[J[1;32muart:~$ [m[8D[J[00:01:16.452,484] [0m<inf> cert_provisioning: Sending hello! 2[0m
DEBUG    httpx:_config.py:82 load_ssl_context verify=True cert=None trust_env=True http2=False
DEBUG    httpx:_config.py:148 load_verify_locations cafile='/usr/local/lib/python3.11/dist-packages/certifi/cacert.pem'
DEBUG    httpcore.connection:_trace.py:85 connect_tcp.started host='api.golioth.io' port=443 local_address=None timeout=5.0 socket_options=None
DEBUG    httpcore.connection:_trace.py:85 connect_tcp.complete return_value=<httpcore._backends.trio.TrioStream object at 0xffff7cd4aa90>
DEBUG    httpcore.connection:_trace.py:85 start_tls.started ssl_context=<ssl.SSLContext object at 0xffff7d835ac0> server_hostname='api.golioth.io' timeout=5.0
DEBUG    httpcore.connection:_trace.py:85 start_tls.complete return_value=<httpcore._backends.trio.TrioStream object at 0xffff7cd52ed0>
DEBUG    httpcore.http11:_trace.py:85 send_request_headers.started request=<Request [b'GET']>
DEBUG    httpcore.http11:_trace.py:85 send_request_headers.complete
DEBUG    httpcore.http11:_trace.py:85 send_request_body.started request=<Request [b'GET']>
DEBUG    httpcore.http11:_trace.py:85 send_request_body.complete
DEBUG    httpcore.http11:_trace.py:85 receive_response_headers.started request=<Request [b'GET']>
DEBUG    httpcore.http11:_trace.py:85 receive_response_headers.complete return_value=(b'HTTP/1.1', 200, b'OK', [(b'Access-Control-Expose-Headers', b'Content-Range'), (b'Content-Length', b'584'), (b'Content-Range', b'devices 0-1/1'), (b'Content-Type', b'application/json'), (b'Date', b'Mon, 30 Sep 2024 21:40:59 GMT'), (b'Grpc-Metadata-Access-Control-Expose-Headers', b'Content-Range'), (b'Grpc-Metadata-Content-Type', b'application/grpc'), (b'Via', b'kong/2.5.2'), (b'X-Kong-Proxy-Latency', b'12'), (b'X-Kong-Upstream-Latency', b'20')])
INFO     httpx:_client.py:1786 HTTP Request: GET https://api.golioth.io/v1/projects/firmware_ci/devices?deviceName=certificate-GaxtpJEUhiCQhZIT "HTTP/1.1 200 OK"
DEBUG    httpcore.http11:_trace.py:85 receive_response_body.started request=<Request [b'GET']>
DEBUG    httpcore.http11:_trace.py:85 receive_response_body.complete
DEBUG    httpcore.http11:_trace.py:85 response_closed.started
DEBUG    httpcore.http11:_trace.py:85 response_closed.complete
DEBUG    httpcore.connection:_trace.py:85 close.started
DEBUG    httpcore.connection:_trace.py:85 close.complete
DEBUG    twister_harness.device.hardware_adapter:hardware_adapter.py:186 Closed serial connection for /dev/serial/by-id/usb-ZEPHYR_RAK5010_Zephyr_B1E5A88410C9C828-if00
DEBUG    httpx:_config.py:82 load_ssl_context verify=True cert=None trust_env=True http2=False
DEBUG    httpx:_config.py:148 load_verify_locations cafile='/usr/local/lib/python3.11/dist-packages/certifi/cacert.pem'
DEBUG    httpcore.connection:_trace.py:85 connect_tcp.started host='api.golioth.io' port=443 local_address=None timeout=5.0 socket_options=None
DEBUG    httpcore.connection:_trace.py:85 connect_tcp.complete return_value=<httpcore._backends.trio.TrioStream object at 0xffff7cd53b10>
DEBUG    httpcore.connection:_trace.py:85 start_tls.started ssl_context=<ssl.SSLContext object at 0xffff7ce79400> server_hostname='api.golioth.io' timeout=5.0
DEBUG    httpcore.connection:_trace.py:85 start_tls.complete return_value=<httpcore._backends.trio.TrioStream object at 0xffff7cd65ad0>
DEBUG    httpcore.http11:_trace.py:85 send_request_headers.started request=<Request [b'DELETE']>
DEBUG    httpcore.http11:_trace.py:85 send_request_headers.complete
DEBUG    httpcore.http11:_trace.py:85 send_request_body.started request=<Request [b'DELETE']>
DEBUG    httpcore.http11:_trace.py:85 send_request_body.complete
DEBUG    httpcore.http11:_trace.py:85 receive_response_headers.started request=<Request [b'DELETE']>
DEBUG    httpcore.http11:_trace.py:85 receive_response_headers.complete return_value=(b'HTTP/1.1', 200, b'OK', [(b'Content-Length', b'2'), (b'Content-Type', b'application/json'), (b'Date', b'Mon, 30 Sep 2024 21:40:59 GMT'), (b'Grpc-Metadata-Content-Type', b'application/grpc'), (b'Via', b'kong/2.5.2'), (b'X-Kong-Proxy-Latency', b'0'), (b'X-Kong-Upstream-Latency', b'13')])
INFO     httpx:_client.py:1786 HTTP Request: DELETE https://api.golioth.io/v1/projects/firmware_ci/certificates/66fb1a8f0e704510295cabb5 "HTTP/1.1 200 OK"
DEBUG    httpcore.http11:_trace.py:85 receive_response_body.started request=<Request [b'DELETE']>
DEBUG    httpcore.http11:_trace.py:85 receive_response_body.complete
DEBUG    httpcore.http11:_trace.py:85 response_closed.started
DEBUG    httpcore.http11:_trace.py:85 response_closed.complete
DEBUG    httpcore.connection:_trace.py:85 close.started
DEBUG    httpcore.connection:_trace.py:85 close.complete
DEBUG    httpx:_config.py:82 load_ssl_context verify=True cert=None trust_env=True http2=False
DEBUG    httpx:_config.py:148 load_verify_locations cafile='/usr/local/lib/python3.11/dist-packages/certifi/cacert.pem'
DEBUG    httpcore.connection:_trace.py:85 connect_tcp.started host='api.golioth.io' port=443 local_address=None timeout=5.0 socket_options=None
DEBUG    httpcore.connection:_trace.py:85 connect_tcp.complete return_value=<httpcore._backends.trio.TrioStream object at 0xffff7ccb2610>
DEBUG    httpcore.connection:_trace.py:85 start_tls.started ssl_context=<ssl.SSLContext object at 0xffff7cf72f00> server_hostname='api.golioth.io' timeout=5.0
DEBUG    httpcore.connection:_trace.py:85 start_tls.complete return_value=<httpcore._backends.trio.TrioStream object at 0xffff7cd67a10>
DEBUG    httpcore.http11:_trace.py:85 send_request_headers.started request=<Request [b'GET']>
DEBUG    httpcore.http11:_trace.py:85 send_request_headers.complete
DEBUG    httpcore.http11:_trace.py:85 send_request_body.started request=<Request [b'GET']>
DEBUG    httpcore.http11:_trace.py:85 send_request_body.complete
DEBUG    httpcore.http11:_trace.py:85 receive_response_headers.started request=<Request [b'GET']>
DEBUG    httpcore.http11:_trace.py:85 receive_response_headers.complete return_value=(b'HTTP/1.1', 200, b'OK', [(b'Access-Control-Expose-Headers', b'Content-Range'), (b'Content-Length', b'584'), (b'Content-Range', b'devices 0-1/1'), (b'Content-Type', b'application/json'), (b'Date', b'Mon, 30 Sep 2024 21:41:00 GMT'), (b'Grpc-Metadata-Access-Control-Expose-Headers', b'Content-Range'), (b'Grpc-Metadata-Content-Type', b'application/grpc'), (b'Via', b'kong/2.5.2'), (b'X-Kong-Proxy-Latency', b'0'), (b'X-Kong-Upstream-Latency', b'24')])
INFO     httpx:_client.py:1786 HTTP Request: GET https://api.golioth.io/v1/projects/firmware_ci/devices?deviceName=certificate-GaxtpJEUhiCQhZIT "HTTP/1.1 200 OK"
DEBUG    httpcore.http11:_trace.py:85 receive_response_body.started request=<Request [b'GET']>
DEBUG    httpcore.http11:_trace.py:85 receive_response_body.complete
DEBUG    httpcore.http11:_trace.py:85 response_closed.started
DEBUG    httpcore.http11:_trace.py:85 response_closed.complete
DEBUG    httpcore.connection:_trace.py:85 close.started
DEBUG    httpcore.connection:_trace.py:85 close.complete
DEBUG    httpx:_config.py:82 load_ssl_context verify=True cert=None trust_env=True http2=False
DEBUG    httpx:_config.py:148 load_verify_locations cafile='/usr/local/lib/python3.11/dist-packages/certifi/cacert.pem'
DEBUG    httpcore.connection:_trace.py:85 connect_tcp.started host='api.golioth.io' port=443 local_address=None timeout=5.0 socket_options=None
DEBUG    httpcore.connection:_trace.py:85 connect_tcp.complete return_value=<httpcore._backends.trio.TrioStream object at 0xffff7ce637d0>
DEBUG    httpcore.connection:_trace.py:85 start_tls.started ssl_context=<ssl.SSLContext object at 0xffff7cd34cb0> server_hostname='api.golioth.io' timeout=5.0
DEBUG    httpcore.connection:_trace.py:85 start_tls.complete return_value=<httpcore._backends.trio.TrioStream object at 0xffff7cd67890>
DEBUG    httpcore.http11:_trace.py:85 send_request_headers.started request=<Request [b'DELETE']>
DEBUG    httpcore.http11:_trace.py:85 send_request_headers.complete
DEBUG    httpcore.http11:_trace.py:85 send_request_body.started request=<Request [b'DELETE']>
DEBUG    httpcore.http11:_trace.py:85 send_request_body.complete
DEBUG    httpcore.http11:_trace.py:85 receive_response_headers.started request=<Request [b'DELETE']>
DEBUG    httpcore.http11:_trace.py:85 receive_response_headers.complete return_value=(b'HTTP/1.1', 200, b'OK', [(b'Content-Length', b'2'), (b'Content-Type', b'application/json'), (b'Date', b'Mon, 30 Sep 2024 21:41:00 GMT'), (b'Grpc-Metadata-Content-Type', b'application/grpc'), (b'Via', b'kong/2.5.2'), (b'X-Kong-Proxy-Latency', b'0'), (b'X-Kong-Upstream-Latency', b'18')])
INFO     httpx:_client.py:1786 HTTP Request: DELETE https://api.golioth.io/v1/projects/firmware_ci/devices/66fb1ade0e704510295cabc3 "HTTP/1.1 200 OK"
DEBUG    httpcore.http11:_trace.py:85 receive_response_body.started request=<Request [b'DELETE']>
DEBUG    httpcore.http11:_trace.py:85 receive_response_body.complete
DEBUG    httpcore.http11:_trace.py:85 response_closed.started
DEBUG    httpcore.http11:_trace.py:85 response_closed.complete
DEBUG    httpcore.connection:_trace.py:85 close.started
DEBUG    httpcore.connection:_trace.py:85 close.complete